Workbook

Sheet FATORES
A2: VENDEDOR
A3: ESSENCIAIS | G3: MÓVEL | M3: SEGURO
D4: A | E4: B | G4: COMISSÃO | I4: 0 | J4: 0.79 | K4: 0.01 | M4: COMISSÃO | O4: 0 | P4: 0.79 | Q4: 0.01
D5: <50 | E5: <50 | I5: 0.8 | J5: 0.89 | K5: 0.05 | O5: 0.8 | P5: 0.89 | Q5: 0.03
A6: COMISSÃO | B6: 0 | C6: 0.7999 | D6: 0.005 | E6: 0.002 | I6: 0.9 | J6: 1000 | K6: 0.08 | O6: 0.9 | P6: 1000 | Q6: 0.05
B7: 0.8 | C7: 0.8999 | D7: 0.01 | E7: 0.004 | G7: PREMIAÇÃO ALTO DESEMPENHO | H7: INDIVIDUAL | I7: 1 | J7: 1.49 | K7: 0.15 | M7: PREMIAÇÃO ALTO DESEMPENHO | N7: INDIVIDUAL | O7: 1 | P7: 1.49 | Q7: 0.2
B8: 0.9 | C8: 10000 | D8: 0.015 | E8: 0.01 | I8: 1.5 | J8: 1000 | K8: 0.2 | O8: 1.5 | P8: 1000 | Q8: 0.25
A9: PREMIO ALTA PERFORMANCE | B9: 1 | C9: 1.4999 | D9: 0.04 | E9: 0.015 | H9: LOJA | I9: 1 | J9: 1000 | K9: 0.1 | N9: LOJA | O9: 1 | P9: 1000 | Q9: 0.1
B10: 1.5 | C10: 10 | D10: 0.05 | E10: 0.02
A11: PREMIO LOJA | B11: 1 | C11: 10 | D11: 0.015 | E11: 0.01 | G11: FIXA | M11: SVA
G12: COMISSÃO | I12: 0 | J12: 0.79 | K12: 0.01 | M12: COMISSÃO | O12: VENDEU GANHOU | Q12: 0.01
A13: ELETRONICOS | I13: 0.8 | J13: 0.89 | K13: 0.05
D14: A | E14: B | I14: 0.9 | J14: 1000 | K14: 0.08
D15: >15 | E15: <15 | G15: PREMIAÇÃO ALTO DESEMPENHO | H15: INDIVIDUAL | I15: 1 | J15: 1.49 | K15: 0.15 | M15: PREMIAÇÃO ALTO DESEMPENHO | N15: INDIVIDUAL | O15: 1 | P15: 100000 | Q15: 0.01
A16: COMISSÃO | B16: 0 | C16: 0.7999 | D16: 0.001 | E16: 0.0005 | I16: 1.5 | J16: 1000 | K16: 0.2
B17: 0.8 | C17: 0.8999 | D17: 0.002 | E17: 0.001 | H17: LOJA | I17: 1 | J17: 1000 | K17: 0.15 | N17: LOJA | O17: 1 | P17: 100000 | Q17: 0.01
B18: 0.9 | C18: 10000 | D18: 0.003 | E18: 0.0015
A19: PREMIO ALTA PERFORMANCE | B19: 1 | C19: 1.4999 | D19: 0.012 | E19: 0.006
B20: 1.5 | C20: 10 | D20: 0.014 | E20: 0.007
A21: PREMIO LOJA | B21: 1 | C21: 10 | D21: 0.005 | E21: 0.0025
A23: Smartphone
A25: COMISSÃO | B25: 0 | C25: 0.8999 | D25: 0.0005
B26: 0.9 | C26: 10000 | D26: 0.0015
A27: PREMIO ALTA PERFORMANCE | B27: 1 | C27: 10000 | D27: 0.002
A28: PREMIO LOJA | B28: 1 | C28: 10 | D28: 0.0025
A30: GERENTE
A31: ESSENCIAIS | G31: MÓVEL | M31: SEGURO
D32: A | E32: B | G32: COMISSÃO | I32: 0 | J32: 0.79 | K32: 0.005 | M32: COMISSÃO | O32: 0 | P32: 0.79 | Q32: 0.005
D33: <50 | E33: <50 | I33: 0.8 | J33: 0.89 | K33: 0.02 | O33: 0.8 | P33: 0.89 | Q33: 0.02
A34: COMISSÃO | B34: 0 | C34: 0.7999 | D34: 0.0005 | E34: 0.00025 | I34: 0.9 | J34: 1000 | K34: 0.04 | O34: 0.9 | P34: 1000 | Q34: 0.04
B35: 0.8 | C35: 0.8999 | D35: 0.001 | E35: 0.0005 | G35: PREMIAÇÃO ALTO DESEMPENHO | H35: INDIVIDUAL | I35: 1 | J35: 1.49 | K35: 0.08 | M35: PREMIAÇÃO ALTO DESEMPENHO | N35: INDIVIDUAL | O35: 1 | P35: 1.49 | Q35: 0.1
B36: 0.9 | C36: 10000 | D36: 0.0015 | E36: 0.00075 | I36: 1.5 | J36: 1000 | K36: 0.13 | O36: 1.5 | P36: 1000 | Q36: 0.15
A37: PREMIO ALTA PERFORMANCE | B37: 1 | C37: 1.4999 | D37: 0.006 | E37: 0.003 | H37: CARTEIRA | I37: 1 | J37: 1000 | K37: 0.03 | N37: CARTEIRA | O37: 1 | P37: 1000 | Q37: 0.03
B38: 1.5 | C38: 10 | D38: 0.025 | E38: 0.01
A39: PREMIO CARTEIRA | B39: 1 | C39: 10 | D39: 0.008 | E39: 0.004 | G39: FIXA | M39: SVA
G40: COMISSÃO | I40: 0 | J40: 0.79 | K40: 0.005 | M40: COMISSÃO | O40: VENDEU GANHOU | Q40: 0.005
A41: ELETRONICOS | I41: 0.8 | J41: 0.89 | K41: 0.02
D42: A | E42: B | I42: 0.9 | J42: 1000 | K42: 0.04
D43: >15 | E43: <15 | G43: PREMIAÇÃO ALTO DESEMPENHO | H43: INDIVIDUAL | I43: 1 | J43: 1.49 | K43: 0.1 | M43: PREMIAÇÃO ALTO DESEMPENHO | N43: INDIVIDUAL | O43: 1 | P43: 100000 | Q43: 0.005
A44: COMISSÃO | B44: 0 | C44: 0.7999 | D44: =D16/2 -> 0.0005 | E44: =E16/2 -> 0.00025 | I44: 1.5 | J44: 1000 | K44: 0.15
...

Sheet REALIZADO
A1: CONSULTOR | B1: PDV | C1: AT_MOVEL | D1: META_MOVEL | E1: F_M_MOVEL | F1: AT_FIXA | G1: META_FIXA | H1: F_M_FIXA | I1: AT_SMARTPHONE | J1: META_SMARTPHONE | K1: F_M_SMARTPHONE | L1: AT_ACESSORIOS_A | M1: AT_ACESSORIOS_B | N1: META_ACESSORIO | O1: F_M_ACESSORIOS | P1: AT_ESSENCIAIS_A | Q1: AT_ESSENCIAIS_B | R1: META_ESSENCIAIS | S1: F_M_ESSENCIAIS | T1: AT_SEGUROS | U1: META_SEGUROS | V1: F_M_SEGUROS | W1: AT_SVA | X1: META_SVA | Y1: F_M_SVA
A2: EVELYN MAVYE SILVEIRA | B2: ANCHIETA | C2: 44 | D2: 2200 | E2: 2156 | F2: 0 | G2: 0 | H2: 0 | I2: 2999 | J2: 38666.667 | K2: 35667.667 | L2: 0 | M2: 0 | N2: 4650 | O2: 4650 | P2: 129 | Q2: 79 | R2: 2283.3333 | S2: 2075.3333 | T2: 0 | U2: 275 | V2: 275 | W2: 20.9 | X2: 283.3333 | Y2: 262.4333
A3: GABRIEL PINHEIRO BORGES | B3: ANCHIETA | C3: 118 | D3: 2200 | E3: 2082 | F3: 0 | G3: 0 | H3: 0 | I3: 3098 | J3: 38666.667 | K3: 35568.667 | L3: 0 | M3: 0 | N3: 4650 | O3: 4650 | P3: 158 | Q3: 99 | R3: 2283.3333 | S3: 2026.3333 | T3: 0 | U3: 275 | V3: 275 | W3: 20.9 | X3: 283.3333 | Y3: 262.4333
A4: MILENA SILVA MARTINS | B4: ANCHIETA | C4: 315.01 | D4: 2200 | E4: 1884.99 | F4: 0 | G4: 0 | H4: 0 | I4: 2747 | J4: 38666.667 | K4: 35919.667 | L4: 0 | M4: 199 | N4: 4650 | O4: 4451 | P4: 356 | Q4: 198 | R4: 2283.3333 | S4: 1729.3333 | T4: 33.8 | U4: 275 | V4: 241.2 | W4: 77.6 | X4: 283.3333 | Y4: 205.7333
A5: ANA CAROLINA XAVIER GONÇALVES | B5: ANCHIETA | C5: 0 | D5: 0 | E5: 0 | F5: 0 | G5: 0 | H5: 0 | I5: 0 | J5: 0 | K5: 0 | L5: 0 | M5: 0 | N5: 0 | O5: 0 | P5: 0 | Q5: 0 | R5: 0 | S5: 0 | T5: 0 | U5: 0 | V5: 0 | W5: 0 | X5: 0 | Y5: 0
A6: ALISSON PAULO SILVA | B6: BOM JESUS DO ITABAPOANA | C6: 480 | D6: 4333.3333 | E6: 3853.3333 | F6: 0 | G6: 0 | H6: 0 | I6: 7297 | J6: 30000 | K6: 22703 | L6: 0 | M6: 4137 | N6: 3566.6667 | O6: -570.3333 | P6: 802 | Q6: 455 | R6: 2850 | S6: 1593 | T6: 51.8 | U6: 333.3333 | V6: 281.5333 | W6: 45 | X6: 283.3333 | Y6: 238.3333
A7: GIAN BATISTA BRANCO | B7: BOM JESUS DO ITABAPOANA | C7: 444.99 | D7: 4333.3333 | E7: 3888.3433 | F7: 0 | G7: 0 | H7: 0 | I7: 5048 | J7: 30000 | K7: 24952 | L7: 0 | M7: 1738 | N7: 3566.6667 | O7: 1828.6667 | P7: 178 | Q7: 208 | R7: 2850 | S7: 2464 | T7: 33.8 | U7: 333.3333 | V7: 299.5333 | W7: 25.9 | X7: 283.3333 | Y7: 257.4333
A8: SHIRLEY SILVA MOREIRA | B8: BOM JESUS DO ITABAPOANA | C8: 445 | D8: 4333.3333 | E8: 3888.3333 | F8: 0 | G8: 0 | H8: 0 | I8: 11098 | J8: 30000 | K8: 18902 | L8: 0 | M8: 0 | N8: 3566.6667 | O8: 3566.6667 | P8: 89 | Q8: 505 | R8: 2850 | S8: 2256 | T8: 0 | U8: 333.3333 | V8: 333.3333 | W8: 0 | X8: 283.3333 | Y8: 283.3333
A9: JANERSON VICTOR GONÇALVES AZEVEDO | B9: BOM JESUS DO ITABAPOANA | C9: 0 | D9: 0 | E9: 0 | F9: 0 | G9: 0 | H9: 0 | I9: 0 | J9: 0 | K9: 0 | L9: 0 | M9: 0 | N9: 0 | O9: 0 | P9: 0 | Q9: 0 | R9: 0 | S9: 0 | T9: 0 | U9: 0 | V9: 0 | W9: 0 | X9: 0 | Y9: 0
A10: ALICE COSTALONGA COLLI | B10: CENTRO VILA VELHA | C10: 418.99 | D10: 2200 | E10: 1781.01 | F10: 20.01 | G10: 1275 | H10: 1254.99 | I10: 0 | J10: 33750 | K10: 33750 | L10: 0 | M10: 0 | N10: 4450 | O10: 4450 | P10: 0 | Q10: 0 | R10: 1700 | S10: 1700 | T10: 0 | U10: 195 | V10: 195 | W10: 137.7 | X10: 200 | Y10: 62.3
A11: TAHINA PAHINS COELHO | B11: CENTRO VILA VELHA | C11: 187.99 | D11: 2200 | E11: 2012.01 | F11: 0 | G11: 1275 | H11: 1275 | I11: 0 | J11: 33750 | K11: 33750 | L11: 0 | M11: 0 | N11: 4450 | O11: 4450 | P11: 0 | Q11: 0 | R11: 1700 | S11: 1700 | T11: 69.9 | U11: 195 | V11: 125.1 | W11: 0 | X11: 200 | Y11: 200
A12: GUSTAVO SANTOS MONTE MOR | B12: CENTRO VILA VELHA | C12: 0 | D12: 0 | E12: 0 | F12: 0 | G12: 0 | H12: 0 | I12: 0 | J12: 0 | K12: 0 | L12: 0 | M12: 0 | N12: 0 | O12: 0 | P12: 0 | Q12: 0 | R12: 0 | S12: 0 | T12: 0 | U12: 0 | V12: 0 | W12: 0 | X12: 0 | Y12: 0
A13: BARBARA BORGES OLIVEIRA | B13: CENTRO VIX | C13: 309 | D13: 2066.6667 | E13: 1757.6667 | F13: 0 | G13: 1266.6667 | H13: 1266.6667 | I13: 3528 | J13: 23000 | K13: 19472 | L13: 209 | M13: 818 | N13: 2966.6667 | O13: 1939.6667 | P13: 138 | Q13: 0 | R13: 1666.6667 | S13: 1528.6667 | T13: 0 | U13: 230 | V13: 230 | W13: 0 | X13: 200 | Y13: 200
... A107: CARLOS EDUARDO DOS REIS SILVA | B107: SERRA SEDE | C107: 126 | D107: 0 | E107: -126 | F107: 0 | G107: 0 | H107: 0 | I107: 0 | J107: 0 | K107: 0 | L107: 0 | M107: 0 | N107: 0 | O107: 0 | P107: 0 | Q107: 0 | R107: 0 | S107: 0 | T107: 0 | U107: 0 | V107: 0 | W107: 0 | X107: 0 | Y107: 0

Sheet PROJEÇÃO
A1: CONSULTOR | B1: PDV | C1: PROJ_MOVEL | D1: PROJ_FIXA | E1: PROJ_BL | F1: PROJ_APARELHO | G1: PROJ_ESSENCIAIS | H1: PROJ_ACESSORIOS | I1: PROJ_SEGURO | J1: PROJ_SVA | K1: PROJ_PÓS | L1: PROJ_CONTROLE | M1: PROJ_MOVEL_B2B | N1: PROJ_FIXA_B2B | O1: PROJ_ELETRO_A | P1: PROJ_ELETRO_B | Q1: PROJ_ESSEN_A | R1: PROJ_ESSEN_B | S1: PROJ_BL% | T1: COORDENAÇÃO
A2: EVELYN MAVYE SILVEIRA | B2: ANCHIETA | C2: 2063.98 | D2: 0 | E2: 0 | F2: 24429 | G2: 2310 | H2: 2016 | I2: 281.3 | J2: 303.09 | K2: 0 | L2: 0 | M2: 0 | N2: 0 | O2: 0 | P2: 2016 | Q2: 1139 | R2: 1171 | S2: 0 | T2: ARIEL
A3: GABRIEL PINHEIRO BORGES | B3: ANCHIETA | C3: 1128.97 | D3: 0 | E3: 0 | F3: 12152 | G3: 2369 | H3: 3625 | I3: 213.4 | J3: 217.49 | K3: 0 | L3: 0 | M3: 0 | N3: 0 | O3: 0 | P3: 3625 | Q3: 741 | R3: 1628 | S3: 0 | T3: ARIEL
A4: MILENA SILVA MARTINS | B4: ANCHIETA | C4: 2282.23 | D4: 0 | E4: 0 | F4: 29989 | G4: 2984 | H4: 5411 | I4: 291.7 | J4: 297.88 | K4: 0 | L4: 0 | M4: 0 | N4: 0 | O4: 0 | P4: 5411 | Q4: 1495 | R4: 1489 | S4: 0 | T4: ARIEL
A5: ALISSON PAULO SILVA | B5: BOM JESUS DO ITABAPOANA | C5: 4690.94 | D5: 0 | E5: 0 | F5: 32589 | G5: 3239 | H5: 8183 | I5: 397.6 | J5: 329.56 | K5: 0 | L5: 0 | M5: 0 | N5: 0 | O5: 0 | P5: 8183 | Q5: 1881 | R5: 1358 | S5: 0 | T5: ARIEL
A6: GIAN BATISTA BRANCO | B6: BOM JESUS DO ITABAPOANA | C6: 4259.99 | D6: 0 | E6: 0 | F6: 29234 | G6: 3305 | H6: 4612 | I6: 254.6 | J6: 282.18 | K6: 0 | L6: 0 | M6: 0 | N6: 0 | O6: 199 | P6: 4413 | Q6: 1781 | R6: 1524 | S6: 0 | T6: ARIEL
A7: SHIRLEY SILVA MOREIRA | B7: BOM JESUS DO ITABAPOANA | C7: 4235.53 | D7: 0 | E7: 0 | F7: 30870 | G7: 3041 | H7: 3767 | I7: 358.2 | J7: 252.55 | K7: 0 | L7: 0 | M7: 0 | N7: 0 | O7: 0 | P7: 3767 | Q7: 742 | R7: 2299 | S7: 0 | T7: ARIEL
A8: ALICE COSTALONGA COLLI | B8: CENTRO VILA VELHA | C8: 3269.24 | D8: 1164 | E8: 10 | F8: 24723 | G8: 2104 | H8: 5339 | I8: 321.6 | J8: 317.5 | K8: 0 | L8: 0 | M8: 0 | N8: 0 | O8: 78 | P8: 5261 | Q8: 881 | R8: 1223 | S8: 0.71428571 | T8: LUIZ
A9: TAHINA PAHINS COELHO | B9: CENTRO VILA VELHA | C9: 2245.95 | D9: 1334.99 | E9: 10 | F9: 38673 | G9: 1931 | H9: 4388.6 | I9: 156.7 | J9: 209.7 | K9: 0 | L9: 0 | M9: 0 | N9: 0 | O9: 199 | P9: 4189.6 | Q9: 930 | R9: 1001 | S9: 0.71428571 | T9: LUIZ
A10: BARBARA BORGES OLIVEIRA | B10: CENTRO VIX | C10: 1696 | D10: 1314.9 | E10: 11 | F10: 16353 | G10: 1642 | H10: 2963 | I10: 121.7 | J10: 249.29 | K10: 0 | L10: 0 | M10: 0 | N10: 0 | O10: 209 | P10: 2754 | Q10: 543 | R10: 1099 | S10: 0.78571429 | T10: LUIZ
A11: SAFYRA GOMES QUINTILIANO | B11: CENTRO VIX | C11: 441.01 | D11: 290 | E11: 3 | F11: 1549 | G11: 69 | H11: 0 | I11: 104.8 | J11: 20.9 | K11: 0 | L11: 0 | M11: 0 | N11: 0 | O11: 0 | P11: 0 | Q11: 69 | R11: 0 | S11: 0.21428571 | T11: LUIZ
A12: RODRIGO ARAUJO BRAU | B12: CENTRO VIX | C12: 1757 | D12: 1479.99 | E12: 14 | F12: 38590 | G12: 2389 | H12: 2527 | I12: 239.4 | J12: 184.4 | K12: 0 | L12: 0 | M12: 0 | N12: 0 | O12: 0 | P12: 2527 | Q12: 1209 | R12: 1180 | S12: 1 | T12: LUIZ
A13: BIANCA SALES SILVA | B13: GLÓRIA | C13: 1741.5 | D13: 450 | E13: 5 | F13: 7245 | G13: 1042.55 | H13: 3216 | I13: 121.6 | J13: 50.8 | K13: 0 | L13: 0 | M13: 0 | N13: 0 | O13: 358 | P13: 2858 | Q13: 845.55 | R13: 197 | S13: 0.29166667 | T13: LUIZ
... A107: CARLOS EDUARDO DOS REIS SILVA | B107: SERRA SEDE | C107: 451 | D107: 525 | E107: 4 | F107: 0 | G107: 0 | H107: 0 | I107: 0 | J107: 59.9 | K107: 0 | L107: 0 | M107: 0 | N107: 0 | O107: 0 | P107: 0 | Q107: 0 | R107: 0 | S107: 0 | T107: THAYANDRA

Sheet CAPA
B2: SELECIONE A LOJA
B6: ANCHIETA | E6: CENTRO VV | H6: ITACIBA
B8: ICONHA | E8: CENTRO VIX | H8: JACARAIPE
B10: PIUMA | E10: GLÓRIA | H10: LARANJEIRAS
B12: BOM JESUS | E12: JARDIM CAMBURI | H12: MARCILIO DE NORONHA
B14: MIRACEMA | E14: MASTERPLACE | H14: MONTSERRAT
B16: QUISSAMA | E16: NORTE SUL | H16: PORTO CANOA
B18: SAO FIDELIS | H18: SERRA SEDE
B20: ST PADUA

Sheet ANCHIETA
B2: SIMULADOR CONSULTOR
B6: HUNTER | J6: CONSULTOR | M6: PDV | P6: COORDENADOR | V6: 0 | W6: 2 | X6: 3
B7: MOVEL | C7: FIXA | D7: SMARTPHONE | E7: ELETRONICOS | F7: ESSESCIAIS | G7: SEGUROS | H7: SVA | J7: GABRIEL PINHEIRO BORGES | M7: ANCHIETA | P7: ARIEL
B8: 0 | C8: 0 | D8: 0 | E8: 0 | F8: 0 | G8: 0 | H8: 0
B11: PROJEÇÃO
B12: INDIVIDUAL | K12: PDV
B13: PILAR | C13: REAL CN | F13: % - COMISSÃO | G13: % - PREMIAÇÃO ALTO DESEMP. INDIV. | H13: R$ - COMISSÃO | I13: R$ - PREMIAÇÃO ALTO DESEMP. INDIV. | J13: R$ - COMISSÃO + PREMIAÇÃO INDIV. | K13: REAL PDV | N13: % - PREMIAÇÃO ALTO DESEMPENHO PDV | O13: R$ - PREMIAÇÃO ALTO DESEMPENHO PDV | P13: R$ - COMISSÃO + PREMIAÇÕES | Q13: HUNTER 2 | R13: HUNTER 3 | S13: 6/7 PPILARES | T13: GANHO TOTAL
C14: META | D14: ATINGIMENTO | K14: META | L14: ATINGIMENTO
B15: MÓVEL | C15: =_xlfn.XLOOKUP($J$7,REALIZADO[CONSULTOR],REALIZADO[META_MOVEL]) -> 2200 | D15: =_xlfn.XLOOKUP($J$7,PROJEÇÃO[CONSULTOR],PROJEÇÃO[PROJ_MOVEL]) -> 1128.97 | E15: =IFERROR(D15/C15,0) -> 0.51316818 | F15: =VLOOKUP($E$15,FATORES!$I$4:$K$6,3) -> 0.01 | G15: =IFERROR(VLOOKUP($E$15,FATORES!$I$7:$K$8,3),0) -> 0 | H15: =D15*F15 -> 11.2897 | I15: =IF($P$7="ARIEL", IF(AND($E$15>=69.5%, AND($E$17>=69.5%, $E$18>=69.5%, $E$18>=69.5%, $E$20>=69.5%, $E$20>=69.5%, $E$22>=69.5%, $E$23>=69.5%)), D15*G15, 0), IF(AND($E$15>=69.5%, $E$16>=69.5%, $E$17>=69.5%, $E$18>=69.5%, $E$18>=69.5%, $E$20>=69.5%, $E$20>=69.5%, $E$22>=69.5%, $E$23>=69.5%), D15*G15, 0) ) -> 0 | J15: =H15+I15 -> 11.2897 | K15: =SUMIFS(REALIZADO[META_MOVEL],REALIZADO[PDV],ANCHIETA!$M$7) -> 6600 | L15: =SUMIFS(PROJEÇÃO[PROJ_MOVEL],PROJEÇÃO[PDV],ANCHIETA!$M$7) -> 5475.18 | M15: =IFERROR(L15/K15,0) -> 0.82957273 | N15: =IF($M$15>=FATORES!$I$9,FATORES!$K$9,0) -> 0 | O15: =IF(E15>=100%, IF($P$7="ARIEL", IF(AND($E$15>=69.5%,$E$17>=69.5%,$E$18>=69.5%,$E$20>=69.5%,$E$22>=69.5%,$E$23>=69.5%), D15*N15, 0 ), IF(AND($E$15>=69.5%,$E$16>=69.5%,$E$17>=69.5%,$E$18>=69.5%,$E$20>=69.5%,$E$22>=69.5%,$E$23>=69.5%), D15*N15, 0 ) ), 0) -> 0 | P15: =J15+O15 -> 11.2897 | Q15: =IF($B$8=2,P15*0.05,0) -> 0 | R15: =IF($B$8=3,P15*0.15,0) -> 0 | S15: 0.1 | T15: =SUM(P24:S24) -> 50.8821
B16: FIXA | C16: =_xlfn.XLOOKUP($J$7,REALIZADO[CONSULTOR],REALIZADO[META_FIXA]) -> 0 | D16: =_xlfn.XLOOKUP($J$7,PROJEÇÃO[CONSULTOR],PROJEÇÃO[PROJ_FIXA]) -> 0 | E16: =IFERROR(D16/C16,0) -> 0 | F16: =VLOOKUP($E$16,FATORES!$I$12:$K$14,3) -> 0.01 | G16: =IFERROR(VLOOKUP($E$16,FATORES!$I$15:$K$16,3),0) -> 0 | H16: =D16*F16 -> 0 | I16: =IF($P$7="ARIEL", IF(AND($E$15>=69.5%, AND($E$17>=69.5%, $E$18>=69.5%, $E$18>=69.5%, $E$20>=69.5%, $E$20>=69.5%, $E$22>=69.5%, $E$23>=69.5%)), D16*G16, 0), IF(AND($E$15>=69.5%, $E$16>=69.5%, $E$17>=69.5%, $E$18>=69.5%, $E$18>=69.5%, $E$20>=69.5%, $E$20>=69.5%, $E$22>=69.5%, $E$23>=69.5%), D16*G16, 0) ) -> 0 | J16: =H16+I16 -> 0 | K16: =SUMIFS(REALIZADO[META_FIXA],REALIZADO[PDV],ANCHIETA!$M$7) -> 0 | L16: =SUMIFS(PROJEÇÃO[PROJ_FIXA],PROJEÇÃO[PDV],ANCHIETA!$M$7) -> 0 | M16: =IFERROR(L16/K16,0) -> 0 | N16: =IF($M$17>=FATORES!$I$17,FATORES!$K$17,0) -> 0 | O16: =IF(E16>=100%, IF($P$7="ARIEL", IF(AND($E$15>=69.5%,$E$17>=69.5%,$E$18>=69.5%,$E$20>=69.5%,$E$22>=69.5%,$E$23>=69.5%), D16*N16, 0 ), IF(AND($E$15>=69.5%,$E$16>=69.5%,$E$17>=69.5%,$E$18>=69.5%,$E$20>=69.5%,$E$22>=69.5%,$E$23>=69.5%), D16*N16, 0 ) ), 0) -> 0 | P16: =J16+O16 -> 0 | Q16: =IF($C$8=2,P16*0.05,0) -> 0 | R16: =IF($C$8=3,P16*0.15,0) -> 0
B17: SMARTPHONES | C17: =_xlfn.XLOOKUP($J$7,REALIZADO[CONSULTOR],REALIZADO[META_SMARTPHONE]) -> 38666.667 | D17: =_xlfn.XLOOKUP($J$7,PROJEÇÃO[CONSULTOR],PROJEÇÃO[PROJ_APARELHO]) -> 12152 | E17: =IFERROR(D17/C17,0) -> 0.31427586 | F17: =VLOOKUP($E$17,FATORES!$B$25:$D$26,3) -> 0.0005 | G17: =IFERROR(VLOOKUP($E$17,FATORES!$B$27:$D$27,3),0) -> 0 | H17: =D17*F17 -> 6.076 | I17: =IF($P$7="ARIEL", IF(AND($E$15>=69.5%, AND($E$17>=69.5%, $E$18>=69.5%, $E$18>=69.5%, $E$20>=69.5%, $E$20>=69.5%, $E$22>=69.5%, $E$23>=69.5%)), D17*G17, 0), IF(AND($E$15>=69.5%, $E$16>=69.5%, $E$17>=69.5%, $E$18>=69.5%, $E$18>=69.5%, $E$20>=69.5%, $E$20>=69.5%, $E$22>=69.5%, $E$23>=69.5%), D17*G17, 0) ) -> 0 | J17: =H17+I17 -> 6.076 | K17: =SUMIFS(REALIZADO[META_SMARTPHONE],REALIZADO[PDV],ANCHIETA!$M$7) -> 116000 | L17: =SUMIFS(PROJEÇÃO[PROJ_APARELHO],PROJEÇÃO[PDV],ANCHIETA!$M$7) -> 66570 | M17: =IFERROR(L17/K17,0) -> 0.57387931 | N17: =IF($M$17>=FATORES!$B$28,FATORES!$D$28,0) -> 0 | O17: =IF(E17>=100%, IF($P$7="ARIEL", IF(AND($E$15>=69.5%,$E$17>=69.5%,$E$18>=69.5%,$E$20>=69.5%,$E$22>=69.5%,$E$23>=69.5%), D17*N17, 0 ), IF(AND($E$15>=69.5%,$E$16>=69.5%,$E$17>=69.5%,$E$18>=69.5%,$E$20>=69.5%,$E$22>=69.5%,$E$23>=69.5%), D17*N17, 0 ) ), 0) -> 0 | P17: =J17+O17 -> 6.076 | Q17: =IF($D$8=2,P17*0.05,0) -> 0 | R17: =IF($D$8=3,P17*0.15,0) -> 0
B18: ELETRONICOS - A | C18: =_xlfn.XLOOKUP($J$7,REALIZADO[CONSULTOR],REALIZADO[META_ACESSORIO]) -> 4650 | D18: =_xlfn.XLOOKUP($J$7,PROJEÇÃO[CONSULTOR],PROJEÇÃO[PROJ_ELETRO_A]) -> 0 | E18: =IFERROR((D18+D19)/C18,0) -> 0.77956989 | F18: =VLOOKUP($E$18,FATORES!$B$16:$E$18,3) -> 0.001 | G18: =IFERROR(VLOOKUP($E$18,FATORES!$B$19:$E$20,3),0) -> 0 | H18: =D18*F18 -> 0 | I18: =IF($P$7="ARIEL", IF(AND($E$15>=69.5%, AND($E$17>=69.5%, $E$18>=69.5%, $E$18>=69.5%, $E$20>=69.5%, $E$20>=69.5%, $E$22>=69.5%, $E$23>=69.5%)), D18*G18, 0), IF(AND($E$15>=69.5%, $E$16>=69.5%, $E$17>=69.5%, $E$18>=69.5%, $E$18>=69.5%, $E$20>=69.5%, $E$20>=69.5%, $E$22>=69.5%, $E$23>=69.5%), D18*G18, 0) ) -> 0 | J18: =H18+I18 -> 0 | K18: =SUMIFS(REALIZADO[META_ACESSORIO],REALIZADO[PDV],ANCHIETA!$M$7) -> 13950 | L18: =SUMIFS(PROJEÇÃO[PROJ_ELETRO_A],PROJEÇÃO[PDV],ANCHIETA!$M$7) -> 0 | M18: =IFERROR((L18+L19)/K18,0) -> 0.79225806 | N18: =IF($M$18>=FATORES!$B$21,FATORES!$D$21,0) -> 0 | O18: =IF(E18>=100%, IF($P$7="ARIEL", IF(AND($E$15>=69.5%,$E$17>=69.5%,$E$18>=69.5%,$E$20>=69.5%,$E$22>=69.5%,$E$23>=69.5%), D18*N18, 0 ), IF(AND($E$15>=69.5%,$E$16>=69.5%,$E$17>=69.5%,$E$18>=69.5%,$E$20>=69.5%,$E$22>=69.5%,$E$23>=69.5%), D18*N18, 0 ) ), 0) -> 0 | P18: =J18+O18 -> 0 | Q18: =IF($E$8=2,P18*0.05,0) -> 0 | R18: =IF($E$8=3,P18*0.15,0) -> 0
B19: ELETRONICOS - B | D19: =_xlfn.XLOOKUP($J$7,PROJEÇÃO[CONSULTOR],PROJEÇÃO[PROJ_ELETRO_B]) -> 3625 | F19: =VLOOKUP($E$18,FATORES!$B$16:$E$18,4) -> 0.0005 | G19: =IFERROR(VLOOKUP($E$18,FATORES!$B$19:$E$20,4),0) -> 0 | H19: =D19*F19 -> 1.8125 | I19: =IF($P$7="ARIEL", IF(AND($E$15>=69.5%, AND($E$17>=69.5%, $E$18>=69.5%, $E$18>=69.5%, $E$20>=69.5%, $E$20>=69.5%, $E$22>=69.5%, $E$23>=69.5%)), D19*G19, 0), IF(AND($E$15>=69.5%, $E$16>=69.5%, $E$17>=69.5%, $E$18>=69.5%, $E$18>=69.5%, $E$20>=69.5%, $E$20>=69.5%, $E$22>=69.5%, $E$23>=69.5%), D19*G19, 0) ) -> 0 | J19: =H19+I19 -> 1.8125 | L19: =SUMIFS(PROJEÇÃO[PROJ_ELETRO_B],PROJEÇÃO[PDV],ANCHIETA!$M$7) -> 11052 | N19: =IF($M$18>=FATORES!$B$21,FATORES!$E$21,0) -> 0 | O19: =IF(E19>=100%, IF($P$7="ARIEL", IF(AND($E$15>=69.5%,$E$17>=69.5%,$E$18>=69.5%,$E$20>=69.5%,$E$22>=69.5%,$E$23>=69.5%), D19*N19, 0 ), IF(AND($E$15>=69.5%,$E$16>=69.5%,$E$17>=69.5%,$E$18>=69.5%,$E$20>=69.5%,$E$22>=69.5%,$E$23>=69.5%), D19*N19, 0 ) ), 0) -> 0 | P19: =J19+O19 -> 1.8125 | Q19: =IF($E$8=2,P19*0.05,0) -> 0 | R19: =IF($E$8=3,P19*0.15,0) -> 0
B20: ESSENCIAIS - A | C20: =_xlfn.XLOOKUP($J$7,REALIZADO[CONSULTOR],REALIZADO[META_ESSENCIAIS]) -> 2283.3333 | D20: =_xlfn.XLOOKUP($J$7,PROJEÇÃO[CONSULTOR],PROJEÇÃO[PROJ_ESSEN_A]) -> 741 | E20: =IFERROR((D20+D21)/C20,0) -> 1.0375183 | F20: =VLOOKUP($E$20,FATORES!$B$6:$E$8,3) -> 0.015 | G20: =IFERROR(VLOOKUP($E$20,FATORES!$B$9:$E$10,3),0) -> 0.04 | H20: =D20*F20 -> 11.115 | I20: =IF($P$7="ARIEL", IF(AND($E$15>=69.5%, AND($E$17>=69.5%, $E$18>=69.5%, $E$18>=69.5%, $E$20>=69.5%, $E$20>=69.5%, $E$22>=69.5%, $E$23>=69.5%)), D20*G20, 0), IF(AND($E$15>=69.5%, $E$16>=69.5%, $E$17>=69.5%, $E$18>=69.5%, $E$18>=69.5%, $E$20>=69.5%, $E$20>=69.5%, $E$22>=69.5%, $E$23>=69.5%), D20*G20, 0) ) -> 0 | J20: =H20+I20 -> 11.115 | K20: =SUMIFS(REALIZADO[META_ESSENCIAIS],REALIZADO[PDV],ANCHIETA!$M$7) -> 6849.9999 | L20: =SUMIFS(PROJEÇÃO[PROJ_ESSEN_A],PROJEÇÃO[PDV],ANCHIETA!$M$7) -> 3375 | M20: =IFERROR((L20+L21)/K20,0) -> 1.1186861 | N20: =IF($M$20>=FATORES!$B$11,FATORES!$D$11,0) -> 0.015 | O20: =IF(E20>=100%, IF($P$7="ARIEL", IF(AND($E$15>=69.5%,$E$17>=69.5%,$E$18>=69.5%,$E$20>=69.5%,$E$22>=69.5%,$E$23>=69.5%), D20*N20, 0 ), IF(AND($E$15>=69.5%,$E$16>=69.5%,$E$17>=69.5%,$E$18>=69.5%,$E$20>=69.5%,$E$22>=69.5%,$E$23>=69.5%), D20*N20, 0 ) ), 0) -> 0 | P20: =J20+O20 -> 11.115 | Q20: =IF($F$8=2,P20*0.05,0) -> 0 | R20: =IF($F$8=3,P20*0.15,0) -> 0
B21: ESSENCIAIS - B | D21: =_xlfn.XLOOKUP($J$7,PROJEÇÃO[CONSULTOR],PROJEÇÃO[PROJ_ESSEN_B]) -> 1628 | F21: =VLOOKUP($E$20,FATORES!$B$6:$E$8,4) -> 0.01 | G21: =IFERROR(VLOOKUP($E$20,FATORES!$B$9:$E$10,4),0) -> 0.015 | H21: =D21*F21 -> 16.28 | I21: =IF($P$7="ARIEL", IF(AND($E$15>=69.5%, AND($E$17>=69.5%, $E$18>=69.5%, $E$18>=69.5%, $E$20>=69.5%, $E$20>=69.5%, $E$22>=69.5%, $E$23>=69.5%)), D21*G21, 0), IF(AND($E$15>=69.5%, $E$16>=69.5%, $E$17>=69.5%, $E$18>=69.5%, $E$18>=69.5%, $E$20>=69.5%, $E$20>=69.5%, $E$22>=69.5%, $E$23>=69.5%), D21*G21, 0) ) -> 0 | J21: =H21+I21 -> 16.28 | L21: =SUMIFS(PROJEÇÃO[PROJ_ESSEN_B],PROJEÇÃO[PDV],ANCHIETA!$M$7) -> 4288 | N21: =IF($M$20>=FATORES!$B$11,FATORES!$E$11,0) -> 0.01 | O21: =IF(E21>=100%, IF($P$7="ARIEL", IF(AND($E$15>=69.5%,$E$17>=69.5%,$E$18>=69.5%,$E$20>=69.5%,$E$22>=69.5%,$E$23>=69.5%), D21*N21, 0 ), IF(AND($E$15>=69.5%,$E$16>=69.5%,$E$17>=69.5%,$E$18>=69.5%,$E$20>=69.5%,$E$22>=69.5%,$E$23>=69.5%), D21*N21, 0 ) ), 0) -> 0 | P21: =J21+O21 -> 16.28 | Q21: =IF($F$8=2,P21*0.05,0) -> 0 | R21: =IF($F$8=3,P21*0.15,0) -> 0
B22: SEGUROS | C22: =_xlfn.XLOOKUP($J$7,REALIZADO[CONSULTOR],REALIZADO[META_SEGUROS]) -> 275 | D22: =_xlfn.XLOOKUP($J$7,PROJEÇÃO[CONSULTOR],PROJEÇÃO[PROJ_SEGURO]) -> 213.4 | E22: =IFERROR(D22/C22,0) -> 0.776 | F22: =VLOOKUP($E$22,FATORES!$O$4:$Q$6,3) -> 0.01 | G22: =IFERROR(VLOOKUP($E$22,FATORES!$O$7:$Q$8,3),0) -> 0 | H22: =D22*F22 -> 2.134 | I22: =IF($P$7="ARIEL", IF(AND($E$15>=69.5%, AND($E$17>=69.5%, $E$18>=69.5%, $E$18>=69.5%, $E$20>=69.5%, $E$20>=69.5%, $E$22>=69.5%, $E$23>=69.5%)), D22*G22, 0), IF(AND($E$15>=69.5%, $E$16>=69.5%, $E$17>=69.5%, $E$18>=69.5%, $E$18>=69.5%, $E$20>=69.5%, $E$20>=69.5%, $E$22>=69.5%, $E$23>=69.5%), D22*G22, 0) ) -> 0 | J22: =H22+I22 -> 2.134 | K22: =SUMIFS(REALIZADO[META_SEGUROS],REALIZADO[PDV],ANCHIETA!$M$7) -> 825 | L22: =SUMIFS(PROJEÇÃO[PROJ_SEGURO],PROJEÇÃO[PDV],ANCHIETA!$M$7) -> 786.4 | M22: =IFERROR(L22/K22,0) -> 0.95321212 | N22: =IF($M$22>=FATORES!$O$9,FATORES!$Q$9,0) -> 0 | O22: =IF(E22>=100%, IF($P$7="ARIEL", IF(AND($E$15>=69.5%,$E$17>=69.5%,$E$18>=69.5%,$E$20>=69.5%,$E$22>=69.5%,$E$23>=69.5%), D22*N22, 0 ), IF(AND($E$15>=69.5%,$E$16>=69.5%,$E$17>=69.5%,$E$18>=69.5%,$E$20>=69.5%,$E$22>=69.5%,$E$23>=69.5%), D22*N22, 0 ) ), 0) -> 0 | P22: =J22+O22 -> 2.134 | Q22: =IF($G$8=2,P22*0.05,0) -> 0 | R22: =IF($G$8=3,P22*0.15,0) -> 0
B23: SVA | C23: =_xlfn.XLOOKUP($J$7,REALIZADO[CONSULTOR],REALIZADO[META_SVA]) -> 283.3333 | D23: =_xlfn.XLOOKUP($J$7,PROJEÇÃO[CONSULTOR],PROJEÇÃO[PROJ_SVA]) -> 217.49 | E23: =IFERROR(D23/C23,0) -> 0.76761186 | F23: =IF(E23>=0,FATORES!$Q$12) -> 0.01 | G23: =IFERROR(VLOOKUP($E$23,FATORES!$O$15:$Q$16,3),0) -> 0 | H23: =D23*F23 -> 2.1749 | I23: =IF($P$7="ARIEL", IF(AND($E$15>=69.5%, AND($E$17>=69.5%, $E$18>=69.5%, $E$18>=69.5%, $E$20>=69.5%, $E$20>=69.5%, $E$22>=69.5%, $E$23>=69.5%)), D23*G23, 0), IF(AND($E$15>=69.5%, $E$16>=69.5%, $E$17>=69.5%, $E$18>=69.5%, $E$18>=69.5%, $E$20>=69.5%, $E$20>=69.5%, $E$22>=69.5%, $E$23>=69.5%), D23*G23, 0) ) -> 0 | J23: =H23+I23 -> 2.1749 | K23: =SUMIFS(REALIZADO[META_SVA],REALIZADO[PDV],ANCHIETA!$M$7) -> 849.9999 | L23: =SUMIFS(PROJEÇÃO[PROJ_SVA],PROJEÇÃO[PDV],ANCHIETA!$M$7) -> 818.46 | M23: =IFERROR(L23/K23,0) -> 0.96289423 | N23: =IF($M$23>=FATORES!$O$17,FATORES!$Q$17,0) -> 0 | O23: =IF(E23>=100%, IF($P$7="ARIEL", IF(AND($E$15>=69.5%,$E$17>=69.5%,$E$18>=69.5%,$E$20>=69.5%,$E$22>=69.5%,$E$23>=69.5%), D23*N23, 0 ), IF(AND($E$15>=69.5%,$E$16>=69.5%,$E$17>=69.5%,$E$18>=69.5%,$E$20>=69.5%,$E$22>=69.5%,$E$23>=69.5%), D23*N23, 0 ) ), 0) -> 0 | P23: =J23+O23 -> 2.1749 | Q23: =IF($H$8=2,P23*0.05,0) -> 0 | R23: =IF($H$8=3,P23*0.15,0) -> 0
P24: =SUM(P15:P23) -> 50.8821 | Q24: =SUM(Q15:Q23) -> 0 | R24: =SUM(R15:R23) -> 0 | S24: =IF($P$7="ARIEL",IF(MIN(E15,E17,E18,E19,E20,E22,E23)>=100%,SUM(P24:R24)*S15,""),IF(MIN(E15:E23)>=100%,SUM(P24:R24)*S15,""))
B26: REALIZADO
B27: INDIVIDUAL | K27: PDV
B28: PILAR | C28: REAL CN | F28: % - COMISSÃO | G28: % - PREMIAÇÃO ALTO DESEMP. INDIV. | H28: R$ - COMISSÃO | I28: R$ - PREMIAÇÃO ALTO DESEMP. INDIV. | J28: R$ - COMISSÃO + PREMIAÇÃO INDIV. | K28: REAL PDV | N28: % - PREMIAÇÃO ALTO DESEMPENHO PDV | O28: R$ - PREMIAÇÃO ALTO DESEMPENHO PDV | P28: R$ - COMISSÃO + PREMIAÇÕES | Q28: HUNTER 2 | R28: HUNTER 3 | S28: 6/7 PPILARES | T28: GANHO TOTAL
C29: META | D29: ATINGIMENTO | K29: META | L29: ATINGIMENTO
B30: MÓVEL | C30: =_xlfn.XLOOKUP($J$7,REALIZADO[CONSULTOR],REALIZADO[META_MOVEL]) -> 2200 | D30: =_xlfn.XLOOKUP($J$7,REALIZADO[CONSULTOR],REALIZADO[AT_MOVEL]) -> 118 | E30: =IFERROR(D30/C30,0) -> 0.053636364 | F30: =VLOOKUP($E$30,FATORES!$I$4:$K$6,3) -> 0.01 | G30: =IFERROR(VLOOKUP($E$30,FATORES!$I$7:$K$8,3),0) -> 0 | H30: =D30*F30 -> 1.18 | I30: =IF($P$7="ARIEL", IF(AND($E$30>=69.5%, AND($E$32>=69.5%, $E$33>=69.5%, $E$33>=69.5%, $E$35>=69.5%, $E$35>=69.5%, $E$37>=69.5%, $E$38>=69.5%)), D30*G30, 0), IF(AND($E$30>=69.5%, $E$31>=69.5%, $E$32>=69.5%, $E$33>=69.5%, $E$33>=69.5%, $E$35>=69.5%, $E$35>=69.5%, $E$37>=69.5%, $E$38>=69.5%), D30*G30, 0) ) -> 0 | J30: =H30+I30 -> 1.18 | K30: =SUMIFS(REALIZADO[META_MOVEL],REALIZADO[PDV],ANCHIETA!$M$7) -> 6600 | L30: =SUMIFS(REALIZADO[AT_MOVEL],REALIZADO[PDV],ANCHIETA!$M$7) -> 477.01 | M30: =IFERROR(L30/K30,0) -> 0.072274242 | N30: =IF($M$30>=FATORES!$I$9,FATORES!$K$9,0) -> 0 | O30: =IF(E30>=100%, IF($P$7="ARIEL", IF(AND($E$30>=69.5%,$E$32>=69.5%,$E$33>=69.5%,$E$35>=69.5%,$E$37>=69.5%,$E$38>=69.5%), D30*N30, 0), IF(AND($E$30>=69.5%,$E$31>=69.5%,$E$32>=69.5%,$E$33>=69.5%,$E$35>=69.5%,$E$37>=69.5%,$E$38>=69.5%), D30*N30, 0) ),0) -> 0 | P30: =J30+O30 -> 1.18 | Q30: =IF($B$8=2,P30*0.05,0) -> 0 | R30: =IF($B$8=3,P30*0.15,0) -> 0 | S30: 0.1 | T30: =SUM(P39:S39) -> 3.926
B31: FIXA | C31: =_xlfn.XLOOKUP($J$7,REALIZADO[CONSULTOR],REALIZADO[META_FIXA]) -> 0 | D31: =_xlfn.XLOOKUP($J$7,REALIZADO[CONSULTOR],REALIZADO[AT_FIXA]) -> 0 | E31: =IFERROR(D31/C31,0) -> 0 | F31: =VLOOKUP($E$31,FATORES!$I$12:$K$14,3) -> 0.01 | G31: =IFERROR(VLOOKUP($E$31,FATORES!$I$15:$K$16,3),0) -> 0 | H31: =D31*F31 -> 0 | I31: =IF($P$7="ARIEL", IF(AND($E$30>=69.5%, AND($E$32>=69.5%, $E$33>=69.5%, $E$33>=69.5%, $E$35>=69.5%, $E$35>=69.5%, $E$37>=69.5%, $E$38>=69.5%)), D31*G31, 0), IF(AND($E$30>=69.5%, $E$31>=69.5%, $E$32>=69.5%, $E$33>=69.5%, $E$33>=69.5%, $E$35>=69.5%, $E$35>=69.5%, $E$37>=69.5%, $E$38>=69.5%), D31*G31, 0) ) -> 0 | J31: =H31+I31 -> 0 | K31: =SUMIFS(REALIZADO[META_FIXA],REALIZADO[PDV],ANCHIETA!$M$7) -> 0 | L31: =SUMIFS(REALIZADO[AT_FIXA],REALIZADO[PDV],ANCHIETA!$M$7) -> 0 | M31: =IFERROR(L31/K31,0) -> 0 | N31: =IF($M$31>=FATORES!$I$17,FATORES!$K$17,0) -> 0 | O31: =IF(E31>=100%, IF($P$7="ARIEL", IF(AND($E$30>=69.5%,$E$32>=69.5%,$E$33>=69.5%,$E$35>=69.5%,$E$37>=69.5%,$E$38>=69.5%), D31*N31, 0), IF(AND($E$30>=69.5%,$E$31>=69.5%,$E$32>=69.5%,$E$33>=69.5%,$E$35>=69.5%,$E$37>=69.5%,$E$38>=69.5%), D31*N31, 0) ),0) -> 0 | P31: =J31+O31 -> 0 | Q31: =IF($C$8=2,P31*0.05,0) -> 0 | R31: =IF($C$8=3,P31*0.15,0) -> 0
B32: SMARTPHONES | C32: =_xlfn.XLOOKUP($J$7,REALIZADO[CONSULTOR],REALIZADO[META_SMARTPHONE]) -> 38666.667 | D32: =_xlfn.XLOOKUP($J$7,REALIZADO[CONSULTOR],REALIZADO[AT_SMARTPHONE]) -> 3098 | E32: =IFERROR(D32/C32,0) -> 0.08012069 | F32: =VLOOKUP($E$32,FATORES!$B$25:$D$26,3) -> 0.0005 | G32: =IFERROR(VLOOKUP($E$32,FATORES!$B$27:$D$27,3),0) -> 0 | H32: =D32*F32 -> 1.549 | I32: =IF($P$7="ARIEL", IF(AND($E$30>=69.5%, AND($E$32>=69.5%, $E$33>=69.5%, $E$33>=69.5%, $E$35>=69.5%, $E$35>=69.5%, $E$37>=69.5%, $E$38>=69.5%)), D32*G32, 0), IF(AND($E$30>=69.5%, $E$31>=69.5%, $E$32>=69.5%, $E$33>=69.5%, $E$33>=69.5%, $E$35>=69.5%, $E$35>=69.5%, $E$37>=69.5%, $E$38>=69.5%), D32*G32, 0) ) -> 0 | J32: =H32+I32 -> 1.549 | K32: =SUMIFS(REALIZADO[META_SMARTPHONE],REALIZADO[PDV],ANCHIETA!$M$7) -> 116000 | L32: =SUMIFS(REALIZADO[AT_SMARTPHONE],REALIZADO[PDV],ANCHIETA!$M$7) -> 8844 | M32: =IFERROR(L32/K32,0) -> 0.076241379 | N32: =IF($M$32>=FATORES!$B$28,FATORES!$D$28,0) -> 0 | O32: =IF(E32>=100%, IF($P$7="ARIEL", IF(AND($E$30>=69.5%,$E$32>=69.5%,$E$33>=69.5%,$E$35>=69.5%,$E$37>=69.5%,$E$38>=69.5%), D32*N32, 0), IF(AND($E$30>=69.5%,$E$31>=69.5%,$E$32>=69.5%,$E$33>=69.5%,$E$35>=69.5%,$E$37>=69.5%,$E$38>=69.5%), D32*N32, 0) ),0) -> 0 | P32: =J32+O32 -> 1.549 | Q32: =IF($D$8=2,P32*0.05,0) -> 0 | R32: =IF($D$8=3,P32*0.15,0) -> 0
B33: ELETRONICOS - A | C33: =_xlfn.XLOOKUP($J$7,REALIZADO[CONSULTOR],REALIZADO[META_ACESSORIO]) -> 4650 | D33: =_xlfn.XLOOKUP($J$7,REALIZADO[CONSULTOR],REALIZADO[AT_ACESSORIOS_A]) -> 0 | E33: =IFERROR((D33+D34)/C33,0) -> 0 | F33: =VLOOKUP($E$33,FATORES!$B$16:$E$18,3) -> 0.001 | G33: =IFERROR(VLOOKUP($E$33,FATORES!$B$19:$E$20,3),0) -> 0 | H33: =D33*F33 -> 0 | I33: =IF($P$7="ARIEL", IF(AND($E$30>=69.5%, AND($E$32>=69.5%, $E$33>=69.5%, $E$33>=69.5%, $E$35>=69.5%, $E$35>=69.5%, $E$37>=69.5%, $E$38>=69.5%)), D33*G33, 0), IF(AND($E$30>=69.5%, $E$31>=69.5%, $E$32>=69.5%, $E$33>=69.5%, $E$33>=69.5%, $E$35>=69.5%, $E$35>=69.5%, $E$37>=69.5%, $E$38>=69.5%), D33*G33, 0) ) -> 0 | J33: =H33+I33 -> 0 | K33: =SUMIFS(REALIZADO[META_ACESSORIO],REALIZADO[PDV],ANCHIETA!$M$7) -> 13950 | L33: =SUMIFS(REALIZADO[AT_ACESSORIOS_A],REALIZADO[PDV],ANCHIETA!$M$7) -> 0 | M33: =IFERROR((L33+L34)/K33,0) -> 0.014265233 | N33: =IF($M$33>=FATORES!$B$21,FATORES!$D$21,0) -> 0 | O33: =IF(E33>=100%, IF($P$7="ARIEL", IF(AND($E$30>=69.5%,$E$32>=69.5%,$E$33>=69.5%,$E$35>=69.5%,$E$37>=69.5%,$E$38>=69.5%), D33*N33, 0), IF(AND($E$30>=69.5%,$E$31>=69.5%,$E$32>=69.5%,$E$33>=69.5%,$E$35>=69.5%,$E$37>=69.5%,$E$38>=69.5%), D33*N33, 0) ),0) -> 0 | P33: =J33+O33 -> 0 | Q33: =IF($E$8=2,P33*0.05,0) -> 0 | R33: =IF($E$8=3,P33*0.15,0) -> 0
B34: ELETRONICOS - B | D34: =_xlfn.XLOOKUP($J$7,REALIZADO[CONSULTOR],REALIZADO[AT_ACESSORIOS_B]) -> 0 | F34: =VLOOKUP($E$33,FATORES!$B$16:$E$18,4) -> 0.0005 | G34: =IFERROR(VLOOKUP($E$33,FATORES!$B$19:$E$20,4),0) -> 0 | H34: =D34*F34 -> 0 | I34: =IF($P$7="ARIEL", IF(AND($E$30>=69.5%, AND($E$32>=69.5%, $E$33>=69.5%, $E$33>=69.5%, $E$35>=69.5%, $E$35>=69.5%, $E$37>=69.5%, $E$38>=69.5%)), D34*G34, 0), IF(AND($E$30>=69.5%, $E$31>=69.5%, $E$32>=69.5%, $E$33>=69.5%, $E$33>=69.5%, $E$35>=69.5%, $E$35>=69.5%, $E$37>=69.5%, $E$38>=69.5%), D34*G34, 0) ) -> 0 | J34: =H34+I34 -> 0 | L34: =SUMIFS(REALIZADO[AT_ACESSORIOS_B],REALIZADO[PDV],ANCHIETA!$M$7) -> 199 | N34: =IF($M$33>=FATORES!$B$21,FATORES!$E$21,0) -> 0 | O34: =IF(E34>=100%, IF($P$7="ARIEL", IF(AND($E$30>=69.5%,$E$32>=69.5%,$E$33>=69.5%,$E$35>=69.5%,$E$37>=69.5%,$E$38>=69.5%), D34*N34, 0), IF(AND($E$30>=69.5%,$E$31>=69.5%,$E$32>=69.5%,$E$33>=69.5%,$E$35>=69.5%,$E$37>=69.5%,$E$38>=69.5%), D34*N34, 0) ),0) -> 0 | P34: =J34+O34 -> 0 | Q34: =IF($E$8=2,P34*0.05,0) -> 0 | R34: =IF($E$8=3,P34*0.15,0) -> 0
B35: ESSENCIAIS - A | C35: =_xlfn.XLOOKUP($J$7,REALIZADO[CONSULTOR],REALIZADO[META_ESSENCIAIS]) -> 2283.3333 | D35: =_xlfn.XLOOKUP($J$7,REALIZADO[CONSULTOR],REALIZADO[AT_ESSENCIAIS_A]) -> 158 | E35: =IFERROR((D35+D36)/C35,0) -> 0.11255475 | F35: =VLOOKUP($E$35,FATORES!$B$6:$E$8,3) -> 0.005 | G35: =IFERROR(VLOOKUP($E$35,FATORES!$B$9:$E$10,3),0) -> 0 | H35: =D35*F35 -> 0.79 | I35: =IF($P$7="ARIEL", IF(AND($E$30>=69.5%, AND($E$32>=69.5%, $E$33>=69.5%, $E$33>=69.5%, $E$35>=69.5%, $E$35>=69.5%, $E$37>=69.5%, $E$38>=69.5%)), D35*G35, 0), IF(AND($E$30>=69.5%, $E$31>=69.5%, $E$32>=69.5%, $E$33>=69.5%, $E$33>=69.5%, $E$35>=69.5%, $E$35>=69.5%, $E$37>=69.5%, $E$38>=69.5%), D35*G35, 0) ) -> 0 | J35: =H35+I35 -> 0.79 | K35: =SUMIFS(REALIZADO[META_ESSENCIAIS],REALIZADO[PDV],ANCHIETA!$M$7) -> 6849.9999 | L35: =SUMIFS(REALIZADO[AT_ESSENCIAIS_A],REALIZADO[PDV],ANCHIETA!$M$7) -> 643 | M35: =IFERROR((L35+L36)/K35,0) -> 0.14875913 | N35: =IF($M$35>=FATORES!$B$11,FATORES!$D$11,0) -> 0 | O35: =IF(E35>=100%, IF($P$7="ARIEL", IF(AND($E$30>=69.5%,$E$32>=69.5%,$E$33>=69.5%,$E$35>=69.5%,$E$37>=69.5%,$E$38>=69.5%), D35*N35, 0), IF(AND($E$30>=69.5%,$E$31>=69.5%,$E$32>=69.5%,$E$33>=69.5%,$E$35>=69.5%,$E$37>=69.5%,$E$38>=69.5%), D35*N35, 0) ),0) -> 0 | P35: =J35+O35 -> 0.79 | Q35: =IF($F$8=2,P35*0.05,0) -> 0 | R35: =IF($F$8=3,P35*0.15,0) -> 0
B36: ESSENCIAIS - B | D36: =_xlfn.XLOOKUP($J$7,REALIZADO[CONSULTOR],REALIZADO[AT_ESSENCIAIS_B]) -> 99 | F36: =VLOOKUP($E$35,FATORES!$B$6:$E$8,4) -> 0.002 | G36: =IFERROR(VLOOKUP($E$35,FATORES!$B$9:$E$10,4),0) -> 0 | H36: =D36*F36 -> 0.198 | I36: =IF($P$7="ARIEL", IF(AND($E$30>=69.5%, AND($E$32>=69.5%, $E$33>=69.5%, $E$33>=69.5%, $E$35>=69.5%, $E$35>=69.5%, $E$37>=69.5%, $E$38>=69.5%)), D36*G36, 0), IF(AND($E$30>=69.5%, $E$31>=69.5%, $E$32>=69.5%, $E$33>=69.5%, $E$33>=69.5%, $E$35>=69.5%, $E$35>=69.5%, $E$37>=69.5%, $E$38>=69.5%), D36*G36, 0) ) -> 0 | J36: =H36+I36 -> 0.198 | L36: =SUMIFS(REALIZADO[AT_ESSENCIAIS_B],REALIZADO[PDV],ANCHIETA!$M$7) -> 376 | N36: =IF($M$35>=FATORES!$B$11,FATORES!$E$11,0) -> 0 | O36: =IF(E36>=100%, IF($P$7="ARIEL", IF(AND($E$30>=69.5%,$E$32>=69.5%,$E$33>=69.5%,$E$35>=69.5%,$E$37>=69.5%,$E$38>=69.5%), D36*N36, 0), IF(AND($E$30>=69.5%,$E$31>=69.5%,$E$32>=69.5%,$E$33>=69.5%,$E$35>=69.5%,$E$37>=69.5%,$E$38>=69.5%), D36*N36, 0) ),0) -> 0 | P36: =J36+O36 -> 0.198 | Q36: =IF($F$8=2,P36*0.05,0) -> 0 | R36: =IF($F$8=3,P36*0.15,0) -> 0
B37: SEGUROS | C37: =_xlfn.XLOOKUP($J$7,REALIZADO[CONSULTOR],REALIZADO[META_SEGUROS]) -> 275 | D37: =_xlfn.XLOOKUP($J$7,REALIZADO[CONSULTOR],REALIZADO[AT_SEGUROS]) -> 0 | E37: =IFERROR(D37/C37,0) -> 0 | F37: =VLOOKUP($E$37,FATORES!$O$4:$Q$6,3) -> 0.01 | G37: =IFERROR(VLOOKUP($E$37,FATORES!$O$7:$Q$8,3),0) -> 0 | H37: =D37*F37 -> 0 | I37: =IF($P$7="ARIEL", IF(AND($E$30>=69.5%, AND($E$32>=69.5%, $E$33>=69.5%, $E$33>=69.5%, $E$35>=69.5%, $E$35>=69.5%, $E$37>=69.5%, $E$38>=69.5%)), D37*G37, 0), IF(AND($E$30>=69.5%, $E$31>=69.5%, $E$32>=69.5%, $E$33>=69.5%, $E$33>=69.5%, $E$35>=69.5%, $E$35>=69.5%, $E$37>=69.5%, $E$38>=69.5%), D37*G37, 0) ) -> 0 | J37: =H37+I37 -> 0 | K37: =SUMIFS(REALIZADO[META_SEGUROS],REALIZADO[PDV],ANCHIETA!$M$7) -> 825 | L37: =SUMIFS(REALIZADO[AT_SEGUROS],REALIZADO[PDV],ANCHIETA!$M$7) -> 33.8 | M37: =IFERROR(L37/K37,0) -> 0.040969697 | N37: =IF($M$37>=FATORES!$O$9,FATORES!$Q$9,0) -> 0 | O37: =IF(E37>=100%, IF($P$7="ARIEL", IF(AND($E$30>=69.5%,$E$32>=69.5%,$E$33>=69.5%,$E$35>=69.5%,$E$37>=69.5%,$E$38>=69.5%), D37*N37, 0), IF(AND($E$30>=69.5%,$E$31>=69.5%,$E$32>=69.5%,$E$33>=69.5%,$E$35>=69.5%,$E$37>=69.5%,$E$38>=69.5%), D37*N37, 0) ),0) -> 0 | P37: =J37+O37 -> 0 | Q37: =IF($G$8=2,P37*0.05,0) -> 0 | R37: =IF($G$8=3,P37*0.15,0) -> 0
B38: SVA | C38: =_xlfn.XLOOKUP($J$7,REALIZADO[CONSULTOR],REALIZADO[META_SVA]) -> 283.3333 | D38: =_xlfn.XLOOKUP($J$7,REALIZADO[CONSULTOR],REALIZADO[AT_SVA]) -> 20.9 | E38: =IFERROR(D38/C38,0) -> 0.073764715 | F38: =IF(E38>=0,FATORES!$Q$12) -> 0.01 | G38: =IFERROR(VLOOKUP($E$38,FATORES!$O$15:$Q$16,3),0) -> 0 | H38: =D38*F38 -> 0.209 | I38: =IF($P$7="ARIEL", IF(AND($E$30>=69.5%, AND($E$32>=69.5%, $E$33>=69.5%, $E$33>=69.5%, $E$35>=69.5%, $E$35>=69.5%, $E$37>=69.5%, $E$38>=69.5%)), D38*G38, 0), IF(AND($E$30>=69.5%, $E$31>=69.5%, $E$32>=69.5%, $E$33>=69.5%, $E$33>=69.5%, $E$35>=69.5%, $E$35>=69.5%, $E$37>=69.5%, $E$38>=69.5%), D38*G38, 0) ) -> 0 | J38: =H38+I38 -> 0.209 | K38: =SUMIFS(REALIZADO[META_SVA],REALIZADO[PDV],ANCHIETA!$M$7) -> 849.9999 | L38: =SUMIFS(REALIZADO[AT_SVA],REALIZADO[PDV],ANCHIETA!$M$7) -> 119.4 | M38: =IFERROR(L38/K38,0) -> 0.1404706 | N38: =IF($M$38>=FATORES!$O$17,FATORES!$Q$17,0) -> 0 | O38: =IF(E38>=100%, IF($P$7="ARIEL", IF(AND($E$30>=69.5%,$E$32>=69.5%,$E$33>=69.5%,$E$35>=69.5%,$E$37>=69.5%,$E$38>=69.5%), D38*N38, 0), IF(AND($E$30>=69.5%,$E$31>=69.5%,$E$32>=69.5%,$E$33>=69.5%,$E$35>=69.5%,$E$37>=69.5%,$E$38>=69.5%), D38*N38, 0) ),0) -> 0 | P38: =J38+O38 -> 0.209 | Q38: =IF($H$8=2,P38*0.05,0) -> 0 | R38: =IF($H$8=3,P38*0.15,0) -> 0
P39: =SUM(P30:P38) -> 3.926 | Q39: =SUM(Q30:Q38) -> 0 | R39: =SUM(R30:R38) -> 0 | S39: =IF($P$7="ARIEL",IF(MIN(E30,E32,E33,E34,E35,E37,E38)>=100%,SUM(P39:R39)*S30,""),IF(MIN(E30:E38)>=100%,SUM(P39:R39)*S30,""))
B41: SIMULADOR
B42: INDIVIDUAL | K42: PDV
B43: PILAR | C43: REAL CN | F43: % - COMISSÃO | G43: % - PREMIAÇÃO ALTO DESEMP. INDIV. | H43: R$ - COMISSÃO | I43: R$ - PREMIAÇÃO ALTO DESEMP. INDIV. | J43: R$ - COMISSÃO + PREMIAÇÃO INDIV. | K43: REAL PDV | N43: % - PREMIAÇÃO ALTO DESEMPENHO PDV | O43: R$ - PREMIAÇÃO ALTO DESEMPENHO PDV | P43: R$ - COMISSÃO + PREMIAÇÕES | Q43: HUNTER 2 | R43: HUNTER 3 | S43: 6/7 PPILARES | T43: GANHO TOTAL
C44: META | D44: ATINGIMENTO | K44: META | L44: ATINGIMENTO
B45: MÓVEL | C45: 5000 | D45: 7500 | E45: =IFERROR(D45/C45,0) -> 1.5 | F45: =VLOOKUP($E$45,FATORES!$I$4:$K$6,3) -> 0.08 | G45: =IFERROR(VLOOKUP($E$45,FATORES!$I$7:$K$8,3),0) -> 0.2 | H45: =D45*F45 -> 600 | I45: =IF($P$7="ARIEL", IF(AND($E$45>=69.5%, AND($E$47>=69.5%, $E$48>=69.5%, $E$48>=69.5%, $E$50>=69.5%, $E$50>=69.5%, $E$52>=69.5%, $E$53>=69.5%)), D45*G45, 0), IF(AND($E$45>=69.5%, $E$46>=69.5%, $E$47>=69.5%, $E$48>=69.5%, $E$48>=69.5%, $E$50>=69.5%, $E$50>=69.5%, $E$52>=69.5%, $E$53>=69.5%), D45*G45, 0) ) -> 1500 | J45: =H45+I45 -> 2100 | K45: =SUMIFS(REALIZADO[META_MOVEL],REALIZADO[PDV],ANCHIETA!$M$7) -> 6600 | L45: 7842.21 | M45: =IFERROR(L45/K45,0) -> 1.1882136 | N45: =IF($M$45>=FATORES!$I$9,FATORES!$K$9,0) -> 0.1 | O45: =IF(E45>=100%, IF($P$7="ARIEL", IF(AND($E$45>=69.5%, AND($E$47>=69.5%, $E$48>=69.5%, $E$48>=69.5%, $E$50>=69.5%, $E$50>=69.5%, $E$52>=69.5%, $E$53>=69.5%)), D45*N45, 0), IF(AND($E$45>=69.5%, $E$46>=69.5%, $E$47>=69.5%, $E$48>=69.5%, $E$48>=69.5%, $E$50>=69.5%, $E$50>=69.5%, $E$52>=69.5%, $E$53>=69.5%), D45*N45, 0) ),0) -> 750 | P45: =J45+O45 -> 2850 | Q45: =IF($B$8=2,P45*0.05,0) -> 0 | R45: =IF($B$8=3,P45*0.15,0) -> 0 | S45: 0.1 | T45: =SUM($P$54:$S$54) -> 3404.2029
B46: FIXA | C46: =_xlfn.XLOOKUP($J$7,REALIZADO[CONSULTOR],REALIZADO[META_FIXA]) -> 0 | E46: =IFERROR(D46/C46,0) -> 0 | F46: =VLOOKUP($E$46,FATORES!$I$12:$K$14,3) -> 0.01 | G46: =IFERROR(VLOOKUP($E$46,FATORES!$I$15:$K$16,3),0) -> 0 | H46: =D46*F46 -> 0 | I46: =IF($P$7="ARIEL", IF(AND($E$45>=69.5%, AND($E$47>=69.5%, $E$48>=69.5%, $E$48>=69.5%, $E$50>=69.5%, $E$50>=69.5%, $E$52>=69.5%, $E$53>=69.5%)), D46*G46, 0), IF(AND($E$45>=69.5%, $E$46>=69.5%, $E$47>=69.5%, $E$48>=69.5%, $E$48>=69.5%, $E$50>=69.5%, $E$50>=69.5%, $E$52>=69.5%, $E$53>=69.5%), D46*G46, 0) ) -> 0 | J46: =H46+I46 -> 0 | K46: =SUMIFS(REALIZADO[META_FIXA],REALIZADO[PDV],ANCHIETA!$M$7) -> 0 | L46: 100 | M46: =IFERROR(L46/K46,0) -> 0 | N46: =IF($M$46>=FATORES!$I$17,FATORES!$K$17,0) -> 0 | O46: =IF(E46>=100%, IF($P$7="ARIEL", IF(AND($E$45>=69.5%, AND($E$47>=69.5%, $E$48>=69.5%, $E$48>=69.5%, $E$50>=69.5%, $E$50>=69.5%, $E$52>=69.5%, $E$53>=69.5%)), D46*N46, 0), IF(AND($E$45>=69.5%, $E$46>=69.5%, $E$47>=69.5%, $E$48>=69.5%, $E$48>=69.5%, $E$50>=69.5%, $E$50>=69.5%, $E$52>=69.5%, $E$53>=69.5%), D46*N46, 0) ),0) -> 0 | P46: =J46+O46 -> 0 | Q46: =IF($C$8=2,P46*0.05,0) -> 0 | R46: =IF($C$8=3,P46*0.15,0) -> 0
B47: SMARTPHONES | C47: =_xlfn.XLOOKUP($J$7,REALIZADO[CONSULTOR],REALIZADO[META_SMARTPHONE]) -> 38666.667 | D47: 46937 | E47: =IFERROR(D47/C47,0) -> 1.2138879 | F47: =VLOOKUP($E$47,FATORES!$B$25:$D$26,3) -> 0.0015 | G47: =IFERROR(VLOOKUP($E$47,FATORES!$B$27:$D$27,3),0) -> 0.002 | H47: =D47*F47 -> 70.4055 | I47: =IF($P$7="ARIEL", IF(AND($E$45>=69.5%, AND($E$47>=69.5%, $E$48>=69.5%, $E$48>=69.5%, $E$50>=69.5%, $E$50>=69.5%, $E$52>=69.5%, $E$53>=69.5%)), D47*G47, 0), IF(AND($E$45>=69.5%, $E$46>=69.5%, $E$47>=69.5%, $E$48>=69.5%, $E$48>=69.5%, $E$50>=69.5%, $E$50>=69.5%, $E$52>=69.5%, $E$53>=69.5%), D47*G47, 0) ) -> 93.874 | J47: =H47+I47 -> 164.2795 | K47: =SUMIFS(REALIZADO[META_SMARTPHONE],REALIZADO[PDV],ANCHIETA!$M$7) -> 116000 | L47: 156456 | M47: =IFERROR(L47/K47,0) -> 1.3487586 | N47: =IF($M$47>=FATORES!$B$28,FATORES!$D$28,0) -> 0.0025 | O47: =IF(E47>=100%, IF($P$7="ARIEL", IF(AND($E$45>=69.5%, AND($E$47>=69.5%, $E$48>=69.5%, $E$48>=69.5%, $E$50>=69.5%, $E$50>=69.5%, $E$52>=69.5%, $E$53>=69.5%)), D47*N47, 0), IF(AND($E$45>=69.5%, $E$46>=69.5%, $E$47>=69.5%, $E$48>=69.5%, $E$48>=69.5%, $E$50>=69.5%, $E$50>=69.5%, $E$52>=69.5%, $E$53>=69.5%), D47*N47, 0) ),0) -> 117.3425 | P47: =J47+O47 -> 281.622 | Q47: =IF($D$8=2,P47*0.05,0) -> 0 | R47: =IF($D$8=3,P47*0.15,0) -> 0
B48: ELETRONICOS - A | C48: =_xlfn.XLOOKUP($J$7,REALIZADO[CONSULTOR],REALIZADO[META_ACESSORIO]) -> 4650 | E48: =IFERROR((D48+D49)/C48,0) -> 1.4737634 | F48: =VLOOKUP($E$48,FATORES!$B$16:$E$18,3) -> 0.003 | G48: =IFERROR(VLOOKUP($E$48,FATORES!$B$19:$E$20,3),0) -> 0.012 | H48: =D48*F48 -> 0 | I48: =IF($P$7="ARIEL", IF(AND($E$45>=69.5%, AND($E$47>=69.5%, $E$48>=69.5%, $E$48>=69.5%, $E$50>=69.5%, $E$50>=69.5%, $E$52>=69.5%, $E$53>=69.5%)), D48*G48, 0), IF(AND($E$45>=69.5%, $E$46>=69.5%, $E$47>=69.5%, $E$48>=69.5%, $E$48>=69.5%, $E$50>=69.5%, $E$50>=69.5%, $E$52>=69.5%, $E$53>=69.5%), D48*G48, 0) ) -> 0 | J48: =H48+I48 -> 0 | K48: =SUMIFS(REALIZADO[META_ACESSORIO],REALIZADO[PDV],ANCHIETA!$M$7) -> 13950 | L48: =SUMIFS(REALIZADO[AT_ACESSORIOS_A],REALIZADO[PDV],ANCHIETA!$M$7) -> 0 | M48: =IFERROR((L48+L49)/K48,0) -> 1.295914 | N48: =IF($M$48>=FATORES!$B$21,FATORES!$D$21,0) -> 0.005 | O48: =IF(E48>=100%, IF($P$7="ARIEL", IF(AND($E$45>=69.5%, AND($E$47>=69.5%, $E$48>=69.5%, $E$48>=69.5%, $E$50>=69.5%, $E$50>=69.5%, $E$52>=69.5%, $E$53>=69.5%)), D48*N48, 0), IF(AND($E$45>=69.5%, $E$46>=69.5%, $E$47>=69.5%, $E$48>=69.5%, $E$48>=69.5%, $E$50>=69.5%, $E$50>=69.5%, $E$52>=69.5%, $E$53>=69.5%), D48*N48, 0) ),0) -> 0 | P48: =J48+O48 -> 0 | Q48: =IF($E$8=2,P48*0.05,0) -> 0 | R48: =IF($E$8=3,P48*0.15,0) -> 0
...

Sheet CENTRO VIX
B2: SIMULADOR CONSULTOR
B6: HUNTER | J6: CONSULTOR | M6: PDV | P6: COORDENADOR | V6: 0 | W6: 2 | X6: 3
B7: MOVEL | C7: FIXA | D7: SMARTPHONE | E7: ELETRONICOS | F7: ESSESCIAIS | G7: SEGUROS | H7: SVA | J7: BARBARA BORGES OLIVEIRA | M7: CENTRO VIX | P7: IGOR
B8: 0 | C8: 0 | D8: 0 | E8: 0 | F8: 0 | G8: 0 | H8: 0
B11: PROJEÇÃO
B12: INDIVIDUAL | K12: PDV
B13: PILAR | C13: REAL CN | F13: % - COMISSÃO | G13: % - PREMIAÇÃO ALTO DESEMP. INDIV. | H13: R$ - COMISSÃO | I13: R$ - PREMIAÇÃO ALTO DESEMP. INDIV. | J13: R$ - COMISSÃO + PREMIAÇÃO INDIV. | K13: REAL PDV | N13: % - PREMIAÇÃO ALTO DESEMPENHO PDV | O13: R$ - PREMIAÇÃO ALTO DESEMPENHO PDV | P13: R$ - COMISSÃO + PREMIAÇÕES | Q13: HUNTER 2 | R13: HUNTER 3 | S13: 6/7 PPILARES | T13: GANHO TOTAL
C14: META | D14: ATINGIMENTO | K14: META | L14: ATINGIMENTO
B15: MÓVEL | C15: =_xlfn.XLOOKUP($J$7,REALIZADO[CONSULTOR],REALIZADO[META_MOVEL]) -> 2066.6667 | D15: =_xlfn.XLOOKUP($J$7,PROJEÇÃO[CONSULTOR],PROJEÇÃO[PROJ_MOVEL]) -> 1696 | E15: =IFERROR(D15/C15,0) -> 0.82064515 | F15: =VLOOKUP($E$15,FATORES!$I$4:$K$6,3) -> 0.05 | G15: =IFERROR(VLOOKUP($E$15,FATORES!$I$7:$K$8,3),0) -> 0 | H15: =D15*F15 -> 84.8 | I15: =IF($P$7="ARIEL", IF(AND($E$15>=69.5%, AND($E$17>=69.5%, $E$18>=69.5%, $E$18>=69.5%, $E$20>=69.5%, $E$20>=69.5%, $E$22>=69.5%, $E$23>=69.5%)), D15*G15, 0), IF(AND($E$15>=69.5%, $E$16>=69.5%, $E$17>=69.5%, $E$18>=69.5%, $E$18>=69.5%, $E$20>=69.5%, $E$20>=69.5%, $E$22>=69.5%, $E$23>=69.5%), D15*G15, 0) ) -> 0 | J15: =H15+I15 -> 84.8 | K15: =SUMIFS(REALIZADO[META_MOVEL],REALIZADO[PDV],'CENTRO VIX'!$M$7) -> 6200.0001 | L15: =SUMIFS(PROJEÇÃO[PROJ_MOVEL],PROJEÇÃO[PDV],'CENTRO VIX'!$M$7) -> 3894.01 | M15: =IFERROR(L15/K15,0) -> 0.62806612 | N15: =IF($M$15>=FATORES!$I$9,FATORES!$K$9,0) -> 0 | O15: =IF(E15>=100%, IF($P$7="ARIEL", IF(AND($E$15>=69.5%,$E$17>=69.5%,$E$18>=69.5%,$E$20>=69.5%,$E$22>=69.5%,$E$23>=69.5%), D15*N15, 0 ), IF(AND($E$15>=69.5%,$E$16>=69.5%,$E$17>=69.5%,$E$18>=69.5%,$E$20>=69.5%,$E$22>=69.5%,$E$23>=69.5%), D15*N15, 0 ) ), 0) -> 0 | P15: =J15+O15 -> 84.8 | Q15: =IF($B$8=2,P15*0.05,0) -> 0 | R15: =IF($B$8=3,P15*0.15,0) -> 0 | S15: 0.1 | T15: =SUM(P24:S24) -> 225.7714
B16: FIXA | C16: =_xlfn.XLOOKUP($J$7,REALIZADO[CONSULTOR],REALIZADO[META_FIXA]) -> 1266.6667 | D16: =_xlfn.XLOOKUP($J$7,PROJEÇÃO[CONSULTOR],PROJEÇÃO[PROJ_FIXA]) -> 1314.9 | E16: =IFERROR(D16/C16,0) -> 1.0380789 | F16: =VLOOKUP($E$16,FATORES!$I$12:$K$14,3) -> 0.08 | G16: =IFERROR(VLOOKUP($E$16,FATORES!$I$15:$K$16,3),0) -> 0.15 | H16: =D16*F16 -> 105.192 | I16: =IF($P$7="ARIEL", IF(AND($E$15>=69.5%, AND($E$17>=69.5%, $E$18>=69.5%, $E$18>=69.5%, $E$20>=69.5%, $E$20>=69.5%, $E$22>=69.5%, $E$23>=69.5%)), D16*G16, 0), IF(AND($E$15>=69.5%, $E$16>=69.5%, $E$17>=69.5%, $E$18>=69.5%, $E$18>=69.5%, $E$20>=69.5%, $E$20>=69.5%, $E$22>=69.5%, $E$23>=69.5%), D16*G16, 0) ) -> 0 | J16: =H16+I16 -> 105.192 | K16: =SUMIFS(REALIZADO[META_FIXA],REALIZADO[PDV],'CENTRO VIX'!$M$7) -> 3800.0001 | L16: =SUMIFS(PROJEÇÃO[PROJ_FIXA],PROJEÇÃO[PDV],'CENTRO VIX'!$M$7) -> 3084.89 | M16: =IFERROR(L16/K16,0) -> 0.81181314 | N16: =IF($M$17>=FATORES!$I$17,FATORES!$K$17,0) -> 0 | O16: =IF(E16>=100%, IF($P$7="ARIEL", IF(AND($E$15>=69.5%,$E$17>=69.5%,$E$18>=69.5%,$E$20>=69.5%,$E$22>=69.5%,$E$23>=69.5%), D16*N16, 0 ), IF(AND($E$15>=69.5%,$E$16>=69.5%,$E$17>=69.5%,$E$18>=69.5%,$E$20>=69.5%,$E$22>=69.5%,$E$23>=69.5%), D16*N16, 0 ) ), 0) -> 0 | P16: =J16+O16 -> 105.192 | Q16: =IF($C$8=2,P16*0.05,0) -> 0 | R16: =IF($C$8=3,P16*0.15,0) -> 0
B17: SMARTPHONES | C17: =_xlfn.XLOOKUP($J$7,REALIZADO[CONSULTOR],REALIZADO[META_SMARTPHONE]) -> 23000 | D17: =_xlfn.XLOOKUP($J$7,PROJEÇÃO[CONSULTOR],PROJEÇÃO[PROJ_APARELHO]) -> 16353 | E17: =IFERROR(D17/C17,0) -> 0.711 | F17: =VLOOKUP($E$17,FATORES!$B$25:$D$26,3) -> 0.0005 | G17: =IFERROR(VLOOKUP($E$17,FATORES!$B$27:$D$27,3),0) -> 0 | H17: =D17*F17 -> 8.1765 | I17: =IF($P$7="ARIEL", IF(AND($E$15>=69.5%, AND($E$17>=69.5%, $E$18>=69.5%, $E$18>=69.5%, $E$20>=69.5%, $E$20>=69.5%, $E$22>=69.5%, $E$23>=69.5%)), D17*G17, 0), IF(AND($E$15>=69.5%, $E$16>=69.5%, $E$17>=69.5%, $E$18>=69.5%, $E$18>=69.5%, $E$20>=69.5%, $E$20>=69.5%, $E$22>=69.5%, $E$23>=69.5%), D17*G17, 0) ) -> 0 | J17: =H17+I17 -> 8.1765 | K17: =SUMIFS(REALIZADO[META_SMARTPHONE],REALIZADO[PDV],'CENTRO VIX'!$M$7) -> 69000 | L17: =SUMIFS(PROJEÇÃO[PROJ_APARELHO],PROJEÇÃO[PDV],'CENTRO VIX'!$M$7) -> 56492 | M17: =IFERROR(L17/K17,0) -> 0.81872464 | N17: =IF($M$17>=FATORES!$B$28,FATORES!$D$28,0) -> 0 | O17: =IF(E17>=100%, IF($P$7="ARIEL", IF(AND($E$15>=69.5%,$E$17>=69.5%,$E$18>=69.5%,$E$20>=69.5%,$E$22>=69.5%,$E$23>=69.5%), D17*N17, 0 ), IF(AND($E$15>=69.5%,$E$16>=69.5%,$E$17>=69.5%,$E$18>=69.5%,$E$20>=69.5%,$E$22>=69.5%,$E$23>=69.5%), D17*N17, 0 ) ), 0) -> 0 | P17: =J17+O17 -> 8.1765 | Q17: =IF($D$8=2,P17*0.05,0) -> 0 | R17: =IF($D$8=3,P17*0.15,0) -> 0
B18: ELETRONICOS - A | C18: =_xlfn.XLOOKUP($J$7,REALIZADO[CONSULTOR],REALIZADO[META_ACESSORIO]) -> 2966.6667 | D18: =_xlfn.XLOOKUP($J$7,PROJEÇÃO[CONSULTOR],PROJEÇÃO[PROJ_ELETRO_A]) -> 209 | E18: =IFERROR((D18+D19)/C18,0) -> 0.99876403 | F18: =VLOOKUP($E$18,FATORES!$B$16:$E$18,3) -> 0.003 | G18: =IFERROR(VLOOKUP($E$18,FATORES!$B$19:$E$20,3),0) -> 0 | H18: =D18*F18 -> 0.627 | I18: =IF($P$7="ARIEL", IF(AND($E$15>=69.5%, AND($E$17>=69.5%, $E$18>=69.5%, $E$18>=69.5%, $E$20>=69.5%, $E$20>=69.5%, $E$22>=69.5%, $E$23>=69.5%)), D18*G18, 0), IF(AND($E$15>=69.5%, $E$16>=69.5%, $E$17>=69.5%, $E$18>=69.5%, $E$18>=69.5%, $E$20>=69.5%, $E$20>=69.5%, $E$22>=69.5%, $E$23>=69.5%), D18*G18, 0) ) -> 0 | J18: =H18+I18 -> 0.627 | K18: =SUMIFS(REALIZADO[META_ACESSORIO],REALIZADO[PDV],'CENTRO VIX'!$M$7) -> 8900.0001 | L18: =SUMIFS(PROJEÇÃO[PROJ_ELETRO_A],PROJEÇÃO[PDV],'CENTRO VIX'!$M$7) -> 209 | M18: =IFERROR((L18+L19)/K18,0) -> 0.61685393 | N18: =IF($M$18>=FATORES!$B$21,FATORES!$D$21,0) -> 0 | O18: =IF(E18>=100%, IF($P$7="ARIEL", IF(AND($E$15>=69.5%,$E$17>=69.5%,$E$18>=69.5%,$E$20>=69.5%,$E$22>=69.5%,$E$23>=69.5%), D18*N18, 0 ), IF(AND($E$15>=69.5%,$E$16>=69.5%,$E$17>=69.5%,$E$18>=69.5%,$E$20>=69.5%,$E$22>=69.5%,$E$23>=69.5%), D18*N18, 0 ) ), 0) -> 0 | P18: =J18+O18 -> 0.627 | Q18: =IF($E$8=2,P18*0.05,0) -> 0 | R18: =IF($E$8=3,P18*0.15,0) -> 0
B19: ELETRONICOS - B | D19: =_xlfn.XLOOKUP($J$7,PROJEÇÃO[CONSULTOR],PROJEÇÃO[PROJ_ELETRO_B]) -> 2754 | F19: =VLOOKUP($E$18,FATORES!$B$16:$E$18,4) -> 0.0015 | G19: =IFERROR(VLOOKUP($E$18,FATORES!$B$19:$E$20,4),0) -> 0 | H19: =D19*F19 -> 4.131 | I19: =IF($P$7="ARIEL", IF(AND($E$15>=69.5%, AND($E$17>=69.5%, $E$18>=69.5%, $E$18>=69.5%, $E$20>=69.5%, $E$20>=69.5%, $E$22>=69.5%, $E$23>=69.5%)), D19*G19, 0), IF(AND($E$15>=69.5%, $E$16>=69.5%, $E$17>=69.5%, $E$18>=69.5%, $E$18>=69.5%, $E$20>=69.5%, $E$20>=69.5%, $E$22>=69.5%, $E$23>=69.5%), D19*G19, 0) ) -> 0 | J19: =H19+I19 -> 4.131 | L19: =SUMIFS(PROJEÇÃO[PROJ_ELETRO_B],PROJEÇÃO[PDV],'CENTRO VIX'!$M$7) -> 5281 | N19: =IF($M$18>=FATORES!$B$21,FATORES!$E$21,0) -> 0 | O19: =IF(E19>=100%, IF($P$7="ARIEL", IF(AND($E$15>=69.5%,$E$17>=69.5%,$E$18>=69.5%,$E$20>=69.5%,$E$22>=69.5%,$E$23>=69.5%), D19*N19, 0 ), IF(AND($E$15>=69.5%,$E$16>=69.5%,$E$17>=69.5%,$E$18>=69.5%,$E$20>=69.5%,$E$22>=69.5%,$E$23>=69.5%), D19*N19, 0 ) ), 0) -> 0 | P19: =J19+O19 -> 4.131 | Q19: =IF($E$8=2,P19*0.05,0) -> 0 | R19: =IF($E$8=3,P19*0.15,0) -> 0
B20: ESSENCIAIS - A | C20: =_xlfn.XLOOKUP($J$7,REALIZADO[CONSULTOR],REALIZADO[META_ESSENCIAIS]) -> 1666.6667 | D20: =_xlfn.XLOOKUP($J$7,PROJEÇÃO[CONSULTOR],PROJEÇÃO[PROJ_ESSEN_A]) -> 543 | E20: =IFERROR((D20+D21)/C20,0) -> 0.98519998 | F20: =VLOOKUP($E$20,FATORES!$B$6:$E$8,3) -> 0.015 | G20: =IFERROR(VLOOKUP($E$20,FATORES!$B$9:$E$10,3),0) -> 0 | H20: =D20*F20 -> 8.145 | I20: =IF($P$7="ARIEL", IF(AND($E$15>=69.5%, AND($E$17>=69.5%, $E$18>=69.5%, $E$18>=69.5%, $E$20>=69.5%, $E$20>=69.5%, $E$22>=69.5%, $E$23>=69.5%)), D20*G20, 0), IF(AND($E$15>=69.5%, $E$16>=69.5%, $E$17>=69.5%, $E$18>=69.5%, $E$18>=69.5%, $E$20>=69.5%, $E$20>=69.5%, $E$22>=69.5%, $E$23>=69.5%), D20*G20, 0) ) -> 0 | J20: =H20+I20 -> 8.145 | K20: =SUMIFS(REALIZADO[META_ESSENCIAIS],REALIZADO[PDV],'CENTRO VIX'!$M$7) -> 5000.0001 | L20: =SUMIFS(PROJEÇÃO[PROJ_ESSEN_A],PROJEÇÃO[PDV],'CENTRO VIX'!$M$7) -> 1821 | M20: =IFERROR((L20+L21)/K20,0) -> 0.81999998 | N20: =IF($M$20>=FATORES!$B$11,FATORES!$D$11,0) -> 0 | O20: =IF(E20>=100%, IF($P$7="ARIEL", IF(AND($E$15>=69.5%,$E$17>=69.5%,$E$18>=69.5%,$E$20>=69.5%,$E$22>=69.5%,$E$23>=69.5%), D20*N20, 0 ), IF(AND($E$15>=69.5%,$E$16>=69.5%,$E$17>=69.5%,$E$18>=69.5%,$E$20>=69.5%,$E$22>=69.5%,$E$23>=69.5%), D20*N20, 0 ) ), 0) -> 0 | P20: =J20+O20 -> 8.145 | Q20: =IF($F$8=2,P20*0.05,0) -> 0 | R20: =IF($F$8=3,P20*0.15,0) -> 0
B21: ESSENCIAIS - B | D21: =_xlfn.XLOOKUP($J$7,PROJEÇÃO[CONSULTOR],PROJEÇÃO[PROJ_ESSEN_B]) -> 1099 | F21: =VLOOKUP($E$20,FATORES!$B$6:$E$8,4) -> 0.01 | G21: =IFERROR(VLOOKUP($E$20,FATORES!$B$9:$E$10,4),0) -> 0 | H21: =D21*F21 -> 10.99 | I21: =IF($P$7="ARIEL", IF(AND($E$15>=69.5%, AND($E$17>=69.5%, $E$18>=69.5%, $E$18>=69.5%, $E$20>=69.5%, $E$20>=69.5%, $E$22>=69.5%, $E$23>=69.5%)), D21*G21, 0), IF(AND($E$15>=69.5%, $E$16>=69.5%, $E$17>=69.5%, $E$18>=69.5%, $E$18>=69.5%, $E$20>=69.5%, $E$20>=69.5%, $E$22>=69.5%, $E$23>=69.5%), D21*G21, 0) ) -> 0 | J21: =H21+I21 -> 10.99 | L21: =SUMIFS(PROJEÇÃO[PROJ_ESSEN_B],PROJEÇÃO[PDV],'CENTRO VIX'!$M$7) -> 2279 | N21: =IF($M$20>=FATORES!$B$11,FATORES!$E$11,0) -> 0 | O21: =IF(E21>=100%, IF($P$7="ARIEL", IF(AND($E$15>=69.5%,$E$17>=69.5%,$E$18>=69.5%,$E$20>=69.5%,$E$22>=69.5%,$E$23>=69.5%), D21*N21, 0 ), IF(AND($E$15>=69.5%,$E$16>=69.5%,$E$17>=69.5%,$E$18>=69.5%,$E$20>=69.5%,$E$22>=69.5%,$E$23>=69.5%), D21*N21, 0 ) ), 0) -> 0 | P21: =J21+O21 -> 10.99 | Q21: =IF($F$8=2,P21*0.05,0) -> 0 | R21: =IF($F$8=3,P21*0.15,0) -> 0
B22: SEGUROS | C22: =_xlfn.XLOOKUP($J$7,REALIZADO[CONSULTOR],REALIZADO[META_SEGUROS]) -> 230 | D22: =_xlfn.XLOOKUP($J$7,PROJEÇÃO[CONSULTOR],PROJEÇÃO[PROJ_SEGURO]) -> 121.7 | E22: =IFERROR(D22/C22,0) -> 0.52913043 | F22: =VLOOKUP($E$22,FATORES!$O$4:$Q$6,3) -> 0.01 | G22: =IFERROR(VLOOKUP($E$22,FATORES!$O$7:$Q$8,3),0) -> 0 | H22: =D22*F22 -> 1.217 | I22: =IF($P$7="ARIEL", IF(AND($E$15>=69.5%, AND($E$17>=69.5%, $E$18>=69.5%, $E$18>=69.5%, $E$20>=69.5%, $E$20>=69.5%, $E$22>=69.5%, $E$23>=69.5%)), D22*G22, 0), IF(AND($E$15>=69.5%, $E$16>=69.5%, $E$17>=69.5%, $E$18>=69.5%, $E$18>=69.5%, $E$20>=69.5%, $E$20>=69.5%, $E$22>=69.5%, $E$23>=69.5%), D22*G22, 0) ) -> 0 | J22: =H22+I22 -> 1.217 | K22: =SUMIFS(REALIZADO[META_SEGUROS],REALIZADO[PDV],'CENTRO VIX'!$M$7) -> 690 | L22: =SUMIFS(PROJEÇÃO[PROJ_SEGURO],PROJEÇÃO[PDV],'CENTRO VIX'!$M$7) -> 465.9 | M22: =IFERROR(L22/K22,0) -> 0.67521739 | N22: =IF($M$22>=FATORES!$O$9,FATORES!$Q$9,0) -> 0 | O22: =IF(E22>=100%, IF($P$7="ARIEL", IF(AND($E$15>=69.5%,$E$17>=69.5%,$E$18>=69.5%,$E$20>=69.5%,$E$22>=69.5%,$E$23>=69.5%), D22*N22, 0 ), IF(AND($E$15>=69.5%,$E$16>=69.5%,$E$17>=69.5%,$E$18>=69.5%,$E$20>=69.5%,$E$22>=69.5%,$E$23>=69.5%), D22*N22, 0 ) ), 0) -> 0 | P22: =J22+O22 -> 1.217 | Q22: =IF($G$8=2,P22*0.05,0) -> 0 | R22: =IF($G$8=3,P22*0.15,0) -> 0
B23: SVA | C23: =_xlfn.XLOOKUP($J$7,REALIZADO[CONSULTOR],REALIZADO[META_SVA]) -> 200 | D23: =_xlfn.XLOOKUP($J$7,PROJEÇÃO[CONSULTOR],PROJEÇÃO[PROJ_SVA]) -> 249.29 | E23: =IFERROR(D23/C23,0) -> 1.24645 | F23: =IF(E23>=0,FATORES!$Q$12) -> 0.01 | G23: =IFERROR(VLOOKUP($E$23,FATORES!$O$15:$Q$16,3),0) -> 0.01 | H23: =D23*F23 -> 2.4929 | I23: =IF($P$7="ARIEL", IF(AND($E$15>=69.5%, AND($E$17>=69.5%, $E$18>=69.5%, $E$18>=69.5%, $E$20>=69.5%, $E$20>=69.5%, $E$22>=69.5%, $E$23>=69.5%)), D23*G23, 0), IF(AND($E$15>=69.5%, $E$16>=69.5%, $E$17>=69.5%, $E$18>=69.5%, $E$18>=69.5%, $E$20>=69.5%, $E$20>=69.5%, $E$22>=69.5%, $E$23>=69.5%), D23*G23, 0) ) -> 0 | J23: =H23+I23 -> 2.4929 | K23: =SUMIFS(REALIZADO[META_SVA],REALIZADO[PDV],'CENTRO VIX'!$M$7) -> 600 | L23: =SUMIFS(PROJEÇÃO[PROJ_SVA],PROJEÇÃO[PDV],'CENTRO VIX'!$M$7) -> 454.59 | M23: =IFERROR(L23/K23,0) -> 0.75765 | N23: =IF($M$23>=FATORES!$O$17,FATORES!$Q$17,0) -> 0 | O23: =IF(E23>=100%, IF($P$7="ARIEL", IF(AND($E$15>=69.5%,$E$17>=69.5%,$E$18>=69.5%,$E$20>=69.5%,$E$22>=69.5%,$E$23>=69.5%), D23*N23, 0 ), IF(AND($E$15>=69.5%,$E$16>=69.5%,$E$17>=69.5%,$E$18>=69.5%,$E$20>=69.5%,$E$22>=69.5%,$E$23>=69.5%), D23*N23, 0 ) ), 0) -> 0 | P23: =J23+O23 -> 2.4929 | Q23: =IF($H$8=2,P23*0.05,0) -> 0 | R23: =IF($H$8=3,P23*0.15,0) -> 0
P24: =SUM(P15:P23) -> 225.7714 | Q24: =SUM(Q15:Q23) -> 0 | R24: =SUM(R15:R23) -> 0 | S24: =IF($P$7="ARIEL",IF(MIN(E15,E17,E18,E19,E20,E22,E23)>=100%,SUM(P24:R24)*S15,""),IF(MIN(E15:E23)>=100%,SUM(P24:R24)*S15,""))
B26: REALIZADO
B27: INDIVIDUAL | K27: PDV
B28: PILAR | C28: REAL CN | F28: % - COMISSÃO | G28: % - PREMIAÇÃO ALTO DESEMP. INDIV. | H28: R$ - COMISSÃO | I28: R$ - PREMIAÇÃO ALTO DESEMP. INDIV. | J28: R$ - COMISSÃO + PREMIAÇÃO INDIV. | K28: REAL PDV | N28: % - PREMIAÇÃO ALTO DESEMPENHO PDV | O28: R$ - PREMIAÇÃO ALTO DESEMPENHO PDV | P28: R$ - COMISSÃO + PREMIAÇÕES | Q28: HUNTER 2 | R28: HUNTER 3 | S28: 6/7 PPILARES | T28: GANHO TOTAL
C29: META | D29: ATINGIMENTO | K29: META | L29: ATINGIMENTO
B30: MÓVEL | C30: =_xlfn.XLOOKUP($J$7,REALIZADO[CONSULTOR],REALIZADO[META_MOVEL]) -> 2066.6667 | D30: =_xlfn.XLOOKUP($J$7,REALIZADO[CONSULTOR],REALIZADO[AT_MOVEL]) -> 309 | E30: =IFERROR(D30/C30,0) -> 0.14951613 | F30: =VLOOKUP($E$30,FATORES!$I$4:$K$6,3) -> 0.01 | G30: =IFERROR(VLOOKUP($E$30,FATORES!$I$7:$K$8,3),0) -> 0 | H30: =D30*F30 -> 3.09 | I30: =IF($P$7="ARIEL", IF(AND($E$30>=69.5%, AND($E$32>=69.5%, $E$33>=69.5%, $E$33>=69.5%, $E$35>=69.5%, $E$35>=69.5%, $E$37>=69.5%, $E$38>=69.5%)), D30*G30, 0), IF(AND($E$30>=69.5%, $E$31>=69.5%, $E$32>=69.5%, $E$33>=69.5%, $E$33>=69.5%, $E$35>=69.5%, $E$35>=69.5%, $E$37>=69.5%, $E$38>=69.5%), D30*G30, 0) ) -> 0 | J30: =H30+I30 -> 3.09 | K30: =SUMIFS(REALIZADO[META_MOVEL],REALIZADO[PDV],'CENTRO VIX'!$M$7) -> 6200.0001 | L30: =SUMIFS(REALIZADO[AT_MOVEL],REALIZADO[PDV],'CENTRO VIX'!$M$7) -> 527 | M30: =IFERROR(L30/K30,0) -> 0.084999999 | N30: =IF($M$30>=FATORES!$I$9,FATORES!$K$9,0) -> 0 | O30: =IF(E30>=100%, IF($P$7="ARIEL", IF(AND($E$30>=69.5%,$E$32>=69.5%,$E$33>=69.5%,$E$35>=69.5%,$E$37>=69.5%,$E$38>=69.5%), D30*N30, 0), IF(AND($E$30>=69.5%,$E$31>=69.5%,$E$32>=69.5%,$E$33>=69.5%,$E$35>=69.5%,$E$37>=69.5%,$E$38>=69.5%), D30*N30, 0) ),0) -> 0 | P30: =J30+O30 -> 3.09 | Q30: =IF($B$8=2,P30*0.05,0) -> 0 | R30: =IF($B$8=3,P30*0.15,0) -> 0 | S30: 0.1 | T30: =SUM(P39:S39) -> 6.162
B31: FIXA | C31: =_xlfn.XLOOKUP($J$7,REALIZADO[CONSULTOR],REALIZADO[META_FIXA]) -> 1266.6667 | D31: =_xlfn.XLOOKUP($J$7,REALIZADO[CONSULTOR],REALIZADO[AT_FIXA]) -> 0 | E31: =IFERROR(D31/C31,0) -> 0 | F31: =VLOOKUP($E$31,FATORES!$I$12:$K$14,3) -> 0.01 | G31: =IFERROR(VLOOKUP($E$31,FATORES!$I$15:$K$16,3),0) -> 0 | H31: =D31*F31 -> 0 | I31: =IF($P$7="ARIEL", IF(AND($E$30>=69.5%, AND($E$32>=69.5%, $E$33>=69.5%, $E$33>=69.5%, $E$35>=69.5%, $E$35>=69.5%, $E$37>=69.5%, $E$38>=69.5%)), D31*G31, 0), IF(AND($E$30>=69.5%, $E$31>=69.5%, $E$32>=69.5%, $E$33>=69.5%, $E$33>=69.5%, $E$35>=69.5%, $E$35>=69.5%, $E$37>=69.5%, $E$38>=69.5%), D31*G31, 0) ) -> 0 | J31: =H31+I31 -> 0 | K31: =SUMIFS(REALIZADO[META_FIXA],REALIZADO[PDV],'CENTRO VIX'!$M$7) -> 3800.0001 | L31: =SUMIFS(REALIZADO[AT_FIXA],REALIZADO[PDV],'CENTRO VIX'!$M$7) -> 85 | M31: =IFERROR(L31/K31,0) -> 0.02236842 | N31: =IF($M$31>=FATORES!$I$17,FATORES!$K$17,0) -> 0 | O31: =IF(E31>=100%, IF($P$7="ARIEL", IF(AND($E$30>=69.5%,$E$32>=69.5%,$E$33>=69.5%,$E$35>=69.5%,$E$37>=69.5%,$E$38>=69.5%), D31*N31, 0), IF(AND($E$30>=69.5%,$E$31>=69.5%,$E$32>=69.5%,$E$33>=69.5%,$E$35>=69.5%,$E$37>=69.5%,$E$38>=69.5%), D31*N31, 0) ),0) -> 0 | P31: =J31+O31 -> 0 | Q31: =IF($C$8=2,P31*0.05,0) -> 0 | R31: =IF($C$8=3,P31*0.15,0) -> 0
B32: SMARTPHONES | C32: =_xlfn.XLOOKUP($J$7,REALIZADO[CONSULTOR],REALIZADO[META_SMARTPHONE]) -> 23000 | D32: =_xlfn.XLOOKUP($J$7,REALIZADO[CONSULTOR],REALIZADO[AT_SMARTPHONE]) -> 3528 | E32: =IFERROR(D32/C32,0) -> 0.1533913 | F32: =VLOOKUP($E$32,FATORES!$B$25:$D$26,3) -> 0.0005 | G32: =IFERROR(VLOOKUP($E$32,FATORES!$B$27:$D$27,3),0) -> 0 | H32: =D32*F32 -> 1.764 | I32: =IF($P$7="ARIEL", IF(AND($E$30>=69.5%, AND($E$32>=69.5%, $E$33>=69.5%, $E$33>=69.5%, $E$35>=69.5%, $E$35>=69.5%, $E$37>=69.5%, $E$38>=69.5%)), D32*G32, 0), IF(AND($E$30>=69.5%, $E$31>=69.5%, $E$32>=69.5%, $E$33>=69.5%, $E$33>=69.5%, $E$35>=69.5%, $E$35>=69.5%, $E$37>=69.5%, $E$38>=69.5%), D32*G32, 0) ) -> 0 | J32: =H32+I32 -> 1.764 | K32: =SUMIFS(REALIZADO[META_SMARTPHONE],REALIZADO[PDV],'CENTRO VIX'!$M$7) -> 69000 | L32: =SUMIFS(REALIZADO[AT_SMARTPHONE],REALIZADO[PDV],'CENTRO VIX'!$M$7) -> 5227 | M32: =IFERROR(L32/K32,0) -> 0.075753623 | N32: =IF($M$32>=FATORES!$B$28,FATORES!$D$28,0) -> 0 | O32: =IF(E32>=100%, IF($P$7="ARIEL", IF(AND($E$30>=69.5%,$E$32>=69.5%,$E$33>=69.5%,$E$35>=69.5%,$E$37>=69.5%,$E$38>=69.5%), D32*N32, 0), IF(AND($E$30>=69.5%,$E$31>=69.5%,$E$32>=69.5%,$E$33>=69.5%,$E$35>=69.5%,$E$37>=69.5%,$E$38>=69.5%), D32*N32, 0) ),0) -> 0 | P32: =J32+O32 -> 1.764 | Q32: =IF($D$8=2,P32*0.05,0) -> 0 | R32: =IF($D$8=3,P32*0.15,0) -> 0
B33: ELETRONICOS - A | C33: =_xlfn.XLOOKUP($J$7,REALIZADO[CONSULTOR],REALIZADO[META_ACESSORIO]) -> 2966.6667 | D33: =_xlfn.XLOOKUP($J$7,REALIZADO[CONSULTOR],REALIZADO[AT_ACESSORIOS_A]) -> 209 | E33: =IFERROR((D33+D34)/C33,0) -> 0.34617977 | F33: =VLOOKUP($E$33,FATORES!$B$16:$E$18,3) -> 0.001 | G33: =IFERROR(VLOOKUP($E$33,FATORES!$B$19:$E$20,3),0) -> 0 | H33: =D33*F33 -> 0.209 | I33: =IF($P$7="ARIEL", IF(AND($E$30>=69.5%, AND($E$32>=69.5%, $E$33>=69.5%, $E$33>=69.5%, $E$35>=69.5%, $E$35>=69.5%, $E$37>=69.5%, $E$38>=69.5%)), D33*G33, 0), IF(AND($E$30>=69.5%, $E$31>=69.5%, $E$32>=69.5%, $E$33>=69.5%, $E$33>=69.5%, $E$35>=69.5%, $E$35>=69.5%, $E$37>=69.5%, $E$38>=69.5%), D33*G33, 0) ) -> 0 | J33: =H33+I33 -> 0.209 | K33: =SUMIFS(REALIZADO[META_ACESSORIO],REALIZADO[PDV],'CENTRO VIX'!$M$7) -> 8900.0001 | L33: =SUMIFS(REALIZADO[AT_ACESSORIOS_A],REALIZADO[PDV],'CENTRO VIX'!$M$7) -> 209 | M33: =IFERROR((L33+L34)/K33,0) -> 0.11539326 | N33: =IF($M$33>=FATORES!$B$21,FATORES!$D$21,0) -> 0 | O33: =IF(E33>=100%, IF($P$7="ARIEL", IF(AND($E$30>=69.5%,$E$32>=69.5%,$E$33>=69.5%,$E$35>=69.5%,$E$37>=69.5%,$E$38>=69.5%), D33*N33, 0), IF(AND($E$30>=69.5%,$E$31>=69.5%,$E$32>=69.5%,$E$33>=69.5%,$E$35>=69.5%,$E$37>=69.5%,$E$38>=69.5%), D33*N33, 0) ),0) -> 0 | P33: =J33+O33 -> 0.209 | Q33: =IF($E$8=2,P33*0.05,0) -> 0 | R33: =IF($E$8=3,P33*0.15,0) -> 0
