Workbook

Sheet FATORES
A2: VENDEDOR
A3: ESSENCIAIS | G3: MÓVEL | M3: SEGURO
D4: A | E4: B | G4: COMISSÃO | I4: 0 | J4: 0.79 | K4: 0.01 | M4: COMISSÃO | O4: 0 | P4: 0.79 | Q4: 0.01
D5: <50 | E5: <50 | I5: 0.8 | J5: 0.89 | K5: 0.05 | O5: 0.8 | P5: 0.89 | Q5: 0.03
A6: COMISSÃO | B6: 0 | C6: 0.7999 | D6: 0.005 | E6: 0.002 | I6: 0.9 | J6: 1000 | K6: 0.08 | O6: 0.9 | P6: 1000 | Q6: 0.05
B7: 0.8 | C7: 0.8999 | D7: 0.01 | E7: 0.004 | G7: PREMIAÇÃO ALTO DESEMPENHO | H7: INDIVIDUAL | I7: 1 | J7: 1.49 | K7: 0.15 | M7: PREMIAÇÃO ALTO DESEMPENHO | N7: INDIVIDUAL | O7: 1 | P7: 1.49 | Q7: 0.2
B8: 0.9 | C8: 10000 | D8: 0.015 | E8: 0.01 | I8: 1.5 | J8: 1000 | K8: 0.2 | O8: 1.5 | P8: 1000 | Q8: 0.25
A9: PREMIO ALTA PERFORMANCE | B9: 1 | C9: 1.4999 | D9: 0.04 | E9: 0.015 | H9: LOJA | I9: 1 | J9: 1000 | K9: 0.1 | N9: LOJA | O9: 1 | P9: 1000 | Q9: 0.1
B10: 1.5 | C10: 10 | D10: 0.05 | E10: 0.02
A11: PREMIO LOJA | B11: 1 | C11: 10 | D11: 0.015 | E11: 0.01 | G11: FIXA | M11: SVA
G12: COMISSÃO | I12: 0 | J12: 0.79 | K12: 0.01 | M12: COMISSÃO | O12: VENDEU GANHOU | Q12: 0.01
A13: ELETRONICOS | I13: 0.8 | J13: 0.89 | K13: 0.05
D14: A | E14: B | I14: 0.9 | J14: 1000 | K14: 0.08
D15: >15 | E15: <15 | G15: PREMIAÇÃO ALTO DESEMPENHO | H15: INDIVIDUAL | I15: 1 | J15: 1.49 | K15: 0.15 | M15: PREMIAÇÃO ALTO DESEMPENHO | N15: INDIVIDUAL | O15: 1 | P15: 100000 | Q15: 0.01
A16: COMISSÃO | B16: 0 | C16: 0.7999 | D16: 0.001 | E16: 0.0005 | I16: 1.5 | J16: 1000 | K16: 0.2
B17: 0.8 | C17: 0.8999 | D17: 0.002 | E17: 0.001 | H17: LOJA | I17: 1 | J17: 1000 | K17: 0.15 | N17: LOJA | O17: 1 | P17: 100000 | Q17: 0.01
B18: 0.9 | C18: 10000 | D18: 0.003 | E18: 0.0015
A19: PREMIO ALTA PERFORMANCE | B19: 1 | C19: 1.4999 | D19: 0.012 | E19: 0.006
B20: 1.5 | C20: 10 | D20: 0.014 | E20: 0.007
A21: PREMIO LOJA | B21: 1 | C21: 10 | D21: 0.005 | E21: 0.0025
A23: Smartphone
A25: COMISSÃO | B25: 0 | C25: 0.8999 | D25: 0.0005
B26: 0.9 | C26: 10000 | D26: 0.0015
A27: PREMIO ALTA PERFORMANCE | B27: 1 | C27: 10000 | D27: 0.002
A28: PREMIO LOJA | B28: 1 | C28: 10 | D28: 0.0025
A30: GERENTE
A31: ESSENCIAIS | G31: MÓVEL | M31: SEGURO
D32: A | E32: B | G32: COMISSÃO | I32: 0 | J32: 0.79 | K32: 0.005 | M32: COMISSÃO | O32: 0 | P32: 0.79 | Q32: 0.005
D33: <50 | E33: <50 | I33: 0.8 | J33: 0.89 | K33: 0.02 | O33: 0.8 | P33: 0.89 | Q33: 0.02
A34: COMISSÃO | B34: 0 | C34: 0.7999 | D34: 0.0005 | E34: 0.00025 | I34: 0.9 | J34: 1000 | K34: 0.04 | O34: 0.9 | P34: 1000 | Q34: 0.04
B35: 0.8 | C35: 0.8999 | D35: 0.001 | E35: 0.0005 | G35: PREMIAÇÃO ALTO DESEMPENHO | H35: INDIVIDUAL | I35: 1 | J35: 1.49 | K35: 0.08 | M35: PREMIAÇÃO ALTO DESEMPENHO | N35: INDIVIDUAL | O35: 1 | P35: 1.49 | Q35: 0.1
B36: 0.9 | C36: 10000 | D36: 0.0015 | E36: 0.00075 | I36: 1.5 | J36: 1000 | K36: 0.13 | O36: 1.5 | P36: 1000 | Q36: 0.15
A37: PREMIO ALTA PERFORMANCE | B37: 1 | C37: 1.4999 | D37: 0.006 | E37: 0.003 | H37: CARTEIRA | I37: 1 | J37: 1000 | K37: 0.03 | N37: CARTEIRA | O37: 1 | P37: 1000 | Q37: 0.03
B38: 1.5 | C38: 10 | D38: 0.025 | E38: 0.01
A39: PREMIO CARTEIRA | B39: 1 | C39: 10 | D39: 0.008 | E39: 0.004 | G39: FIXA | M39: SVA
G40: COMISSÃO | I40: 0 | J40: 0.79 | K40: 0.005 | M40: COMISSÃO | O40: VENDEU GANHOU | Q40: 0.005
A41: ELETRONICOS | I41: 0.8 | J41: 0.89 | K41: 0.02
D42: A | E42: B | I42: 0.9 | J42: 1000 | K42: 0.04
D43: >15 | E43: <15 | G43: PREMIAÇÃO ALTO DESEMPENHO | H43: INDIVIDUAL | I43: 1 | J43: 1.49 | K43: 0.1 | M43: PREMIAÇÃO ALTO DESEMPENHO | N43: INDIVIDUAL | O43: 1 | P43: 100000 | Q43: 0.005
A44: COMISSÃO | B44: 0 | C44: 0.7999 | D44: =D16/2 -> 0.0005 | E44: =E16/2 -> 0.00025 | I44: 1.5 | J44: 1000 | K44: 0.15
...

Sheet REALIZADO
A1: CONSULTOR | B1: PDV | C1: AT_MOVEL | D1: META_MOVEL | E1: F_M_MOVEL | F1: AT_FIXA | G1: META_FIXA | H1: F_M_FIXA | I1: AT_SMARTPHONE | J1: META_SMARTPHONE | K1: F_M_SMARTPHONE | L1: AT_ACESSORIOS_A | M1: AT_ACESSORIOS_B | N1: META_ACESSORIO | O1: F_M_ACESSORIOS | P1: AT_ESSENCIAIS_A | Q1: AT_ESSENCIAIS_B | R1: META_ESSENCIAIS | S1: F_M_ESSENCIAIS | T1: AT_SEGUROS | U1: META_SEGUROS | V1: F_M_SEGUROS | W1: AT_SVA | X1: META_SVA | Y1: F_M_SVA | Z1: COORDENAÇÃO
A2: GABRIEL PINHEIRO BORGES | B2: ANCHIETA | C2: 1835 | D2: 2346.6667 | E2: 511.6667 | F2: 45 | G2: 0 | H2: -45 | I2: 35412 | J2: 35000 | K2: -412 | L2: 0 | M2: 6853 | N2: 4166.6667 | O2: -2686.3333 | P2: 812 | Q2: 1470 | R2: 2166.6667 | S2: -115.3333 | T2: 206.1 | U2: 293.3333 | V2: 87.2333 | W2: 309.78 | X2: 293.3333 | Y2: -16.4467 | Z2: =_xlfn.XLOOKUP(REALIZADO[[#This Row],[PDV]],PROJEÇÃO[PDV],PROJEÇÃO[COORDENAÇÃO]) -> ARIEL
A3: NOEMI BATISTA DOS SANTOS | B3: ANCHIETA | C3: 1784 | D3: 2346.6667 | E3: 562.6667 | F3: 0 | G3: 0 | H3: 0 | I3: 43943 | J3: 35000 | K3: -8943 | L3: 449 | M3: 3494 | N3: 4166.6667 | O3: 223.6667 | P3: 950 | Q3: 1308 | R3: 2166.6667 | S3: -91.3333 | T3: 197.3 | U3: 293.3333 | V3: 96.0333 | W3: 281.08 | X3: 293.3333 | Y3: 12.2533 | Z3: =_xlfn.XLOOKUP(REALIZADO[[#This Row],[PDV]],PROJEÇÃO[PDV],PROJEÇÃO[COORDENAÇÃO]) -> ARIEL
A4: EVELYN MAVYE SILVEIRA | B4: ANCHIETA | C4: 2015 | D4: 2346.6667 | E4: 331.6667 | F4: 0 | G4: 0 | H4: 0 | I4: 33406 | J4: 35000 | K4: 1594 | L4: 0 | M4: 2586 | N4: 4166.6667 | O4: 1580.6667 | P4: 761 | Q4: 237 | R4: 2166.6667 | S4: 1168.6667 | T4: 233.2 | U4: 293.3333 | V4: 60.1333 | W4: 311.4 | X4: 293.3333 | Y4: -18.0667 | Z4: =_xlfn.XLOOKUP(REALIZADO[[#This Row],[PDV]],PROJEÇÃO[PDV],PROJEÇÃO[COORDENAÇÃO]) -> ARIEL
A5: SHIRLEY SILVA MOREIRA | B5: BOM JESUS DO ITABAPOANA | C5: 4279.24 | D5: 7452.5 | E5: 3173.26 | F5: 0 | G5: 0 | H5: 0 | I5: 32304 | J5: 44500 | K5: 12196 | L5: 0 | M5: 4402 | N5: 5000 | O5: 598 | P5: 1702 | Q5: 2726 | R5: 4275 | S5: -153 | T5: 361.4 | U5: 530.75 | V5: 169.35 | W5: 314.58 | X5: 440 | Y5: 125.42 | Z5: =_xlfn.XLOOKUP(REALIZADO[[#This Row],[PDV]],PROJEÇÃO[PDV],PROJEÇÃO[COORDENAÇÃO]) -> ARIEL
A6: GIAN BATISTA BRANCO | B6: BOM JESUS DO ITABAPOANA | C6: 4385.39 | D6: 7452.5 | E6: 3067.11 | F6: 0 | G6: 0 | H6: 0 | I6: 45229 | J6: 44500 | K6: -729 | L6: 199 | M6: 3163 | N6: 5000 | O6: 1638 | P6: 1218 | Q6: 1484 | R6: 4275 | S6: 1573 | T6: 297.5 | U6: 530.75 | V6: 233.25 | W6: 332.48 | X6: 440 | Y6: 107.52 | Z6: =_xlfn.XLOOKUP(REALIZADO[[#This Row],[PDV]],PROJEÇÃO[PDV],PROJEÇÃO[COORDENAÇÃO]) -> ARIEL
A7: REBECA SENA DOS SANTOS | B7: CENTRO VILA VELHA | C7: 1236.96 | D7: 2695 | E7: 1458.04 | F7: 1210 | G7: 1595 | H7: 385 | I7: 20494 | J7: 34500 | K7: 14006 | L7: 0 | M7: 6817 | N7: 5000 | O7: -1817 | P7: 207 | Q7: 228 | R7: 1600 | S7: 1165 | T7: 229.7 | U7: 220 | V7: -9.7 | W7: 161.7 | X7: 220 | Y7: 58.3 | Z7: =_xlfn.XLOOKUP(REALIZADO[[#This Row],[PDV]],PROJEÇÃO[PDV],PROJEÇÃO[COORDENAÇÃO]) -> LUIZ
A8: TAHINA PAHINS COELHO | B8: CENTRO VILA VELHA | C8: 338 | D8: 2695 | E8: 2357 | F8: 599.98 | G8: 1595 | H8: 995.02 | I8: 0 | J8: 34500 | K8: 34500 | L8: 0 | M8: 5298 | N8: 5000 | O8: -298 | P8: 0 | Q8: 59 | R8: 1600 | S8: 1541 | T8: 139.8 | U8: 220 | V8: 80.2 | W8: 0 | X8: 220 | Y8: 220 | Z8: =_xlfn.XLOOKUP(REALIZADO[[#This Row],[PDV]],PROJEÇÃO[PDV],PROJEÇÃO[COORDENAÇÃO]) -> LUIZ
A9: RODRIGO ARAUJO BRAU | B9: CENTRO VIX | C9: 2626 | D9: 3465 | E9: 839 | F9: 940.01 | G9: 2310 | H9: 1369.99 | I9: 9704 | J9: 39500 | K9: 29796 | L9: 0 | M9: 3388 | N9: 5000 | O9: 1612 | P9: 377 | Q9: 711 | R9: 2650 | S9: 1562 | T9: 106.6 | U9: 396 | V9: 289.4 | W9: 234.7 | X9: 330 | Y9: 95.3 | Z9: =_xlfn.XLOOKUP(REALIZADO[[#This Row],[PDV]],PROJEÇÃO[PDV],PROJEÇÃO[COORDENAÇÃO]) -> LUIZ
A10: ROQUELLEM HERMES RAMOS | B10: CENTRO VIX | C10: 2070.97 | D10: 3465 | E10: 1394.03 | F10: 465 | G10: 2310 | H10: 1845 | I10: 17742 | J10: 39500 | K10: 21758 | L10: 0 | M10: 1078 | N10: 5000 | O10: 3922 | P10: 516 | Q10: 1437 | R10: 2650 | S10: 697 | T10: 101.8 | U10: 396 | V10: 294.2 | W10: 234.89 | X10: 330 | Y10: 95.11 | Z10: =_xlfn.XLOOKUP(REALIZADO[[#This Row],[PDV]],PROJEÇÃO[PDV],PROJEÇÃO[COORDENAÇÃO]) -> LUIZ
A11: GYSELLA MOURA COSTA | B11: GLÓRIA | C11: 2495 | D11: 3043.3333 | E11: 548.3333 | F11: 1209.99 | G11: 1650 | H11: 440.01 | I11: 27420 | J11: 33333.333 | K11: 5913.3333 | L11: 117 | M11: 3691 | N11: 4166.6667 | O11: 358.6667 | P11: 267 | Q11: 1253 | R11: 1533.3333 | S11: 13.3333 | T11: 191 | U11: 256.6667 | V11: 65.6667 | W11: 330.19 | X11: 165 | Y11: -165.19 | Z11: =_xlfn.XLOOKUP(REALIZADO[[#This Row],[PDV]],PROJEÇÃO[PDV],PROJEÇÃO[COORDENAÇÃO]) -> LUIZ
A12: HERIK LUCAS SOUZA SOARES | B12: GLÓRIA | C12: 2003 | D12: 3043.3333 | E12: 1040.3333 | F12: 740 | G12: 1650 | H12: 910 | I12: 37067 | J12: 33333.333 | K12: -3733.6667 | L12: 39 | M12: 3314 | N12: 4166.6667 | O12: 813.6667 | P12: 0 | Q12: 1097 | R12: 1533.3333 | S12: 436.3333 | T12: 153.4 | U12: 256.6667 | V12: 103.2667 | W12: 200.9 | X12: 165 | Y12: -35.9 | Z12: =_xlfn.XLOOKUP(REALIZADO[[#This Row],[PDV]],PROJEÇÃO[PDV],PROJEÇÃO[COORDENAÇÃO]) -> LUIZ
A13: KLEYDSON NASCIMENTO DE JESUS | B13: GLÓRIA | C13: 2461 | D13: 3043.3333 | E13: 582.3333 | F13: 755 | G13: 1650 | H13: 895 | I13: 34661 | J13: 33333.333 | K13: -1327.6667 | L13: 0 | M13: 2074 | N13: 4166.6667 | O13: 2092.6667 | P13: 565 | Q13: 763 | R13: 1533.3333 | S13: 205.3333 | T13: 314.4 | U13: 256.6667 | V13: -57.7333 | W13: 155.5 | X13: 165 | Y13: 9.5 | Z13: =_xlfn.XLOOKUP(REALIZADO[[#This Row],[PDV]],PROJEÇÃO[PDV],PROJEÇÃO[COORDENAÇÃO]) -> LUIZ
... A102: CARLOS EDUARDO DOS REIS SILVA | B102: SERRA SEDE | C102: 0 | D102: 0 | E102: 0 | F102: 0 | G102: 0 | H102: 0 | I102: 0 | J102: 0 | K102: 0 | L102: 0 | M102: 0 | N102: 0 | O102: 0 | P102: 0 | Q102: 0 | R102: 0 | S102: 0 | T102: 29.9 | U102: 0 | V102: -29.9 | W102: 0 | X102: 0 | Y102: 0 | Z102: =_xlfn.XLOOKUP(REALIZADO[[#This Row],[PDV]],PROJEÇÃO[PDV],PROJEÇÃO[COORDENAÇÃO]) -> THAYANDRA

Sheet PROJEÇÃO
A1: CONSULTOR | B1: PDV | C1: PROJ_MOVEL | D1: PROJ_FIXA | E1: PROJ_BL | F1: PROJ_APARELHO | G1: PROJ_ESSENCIAIS | H1: PROJ_ACESSORIOS | I1: PROJ_SEGURO | J1: PROJ_SVA | K1: PROJ_PÓS | L1: PROJ_CONTROLE | M1: PROJ_MOVEL_B2B | N1: PROJ_FIXA_B2B | O1: PROJ_ELETRO_A | P1: PROJ_ELETRO_B | Q1: PROJ_ESSEN_A | R1: PROJ_ESSEN_B | S1: PROJ_BL% | T1: COORDENAÇÃO
A2: EVELYN MAVYE SILVEIRA | B2: ANCHIETA | C2: 1484.6871 | D2: 0 | E2: 3 | F2: 21974.857 | G2: 2014 | H2: 4473.1429 | I2: 203.0286 | J2: 565.8743 | K2: 0 | L2: 0 | M2: 0 | N2: 0 | O2: 0 | P2: 4473.1429 | Q2: 1207.8571 | R2: 806.1429 | S2: 0 | T2: ARIEL
A3: GABRIEL PINHEIRO BORGES | B3: ANCHIETA | C3: 1202.3471 | D3: 0 | E3: 0 | F3: 25118 | G3: 2662.7143 | H3: 947.2857 | I3: 140.6 | J3: 56.7286 | K3: 0 | L3: 0 | M3: 0 | N3: 0 | O3: 0 | P3: 947.2857 | Q3: 857.7143 | R3: 1805 | S3: 0 | T3: ARIEL
A4: MILENA SILVA MARTINS | B4: ANCHIETA | C4: 1063.9729 | D4: 0 | E4: 0 | F4: 17493.571 | G4: 2605.7143 | H4: 1864.7143 | I4: 183.4857 | J4: 224.2 | K4: 0 | L4: 0 | M4: 0 | N4: 0 | O4: 0 | P4: 1864.7143 | Q4: 1449.4286 | R4: 1156.2857 | S4: 0 | T4: ARIEL
A5: ALISSON PAULO SILVA | B5: BOM JESUS DO ITABAPOANA | C5: 6264.4629 | D5: 0 | E5: 0 | F5: 37036.429 | G5: 5862.8571 | H5: 16380.714 | I5: 473.9143 | J5: 460.8586 | K5: 0 | L5: 0 | M5: 0 | N5: 0 | O5: 0 | P5: 16380.714 | Q5: 3333.1429 | R5: 2529.7143 | S5: 0 | T5: ARIEL
A6: GIAN BATISTA BRANCO | B6: BOM JESUS DO ITABAPOANA | C6: 3908.5171 | D6: 0 | E6: 0 | F6: 17227.571 | G6: 2309.8571 | H6: 10216.571 | I6: 183.4857 | J6: 181.2871 | K6: 0 | L6: 0 | M6: 0 | N6: 0 | O6: 540.1429 | P6: 9676.4286 | Q6: 1207.8571 | R6: 1102 | S6: 0 | T6: ARIEL
A7: SHIRLEY SILVA MOREIRA | B7: BOM JESUS DO ITABAPOANA | C7: 3599.1429 | D7: 0 | E7: 0 | F7: 30123.143 | G7: 2904.2857 | H7: 9847.4286 | I7: 83.6 | J7: 54.2586 | K7: 0 | L7: 0 | M7: 0 | N7: 0 | O7: 0 | P7: 9847.4286 | Q7: 806.1429 | R7: 2098.1429 | S7: 0 | T7: ARIEL
A8: ALICE COSTALONGA COLLI | B8: CENTRO VILA VELHA | C8: 3273.4014 | D8: 1425 | E8: 11 | F8: 49660.571 | G8: 483.1429 | H8: 6356.8571 | I8: 45.8714 | J8: 732.3143 | K8: 0 | L8: 0 | M8: 0 | N8: 0 | O8: 211.7143 | P8: 6145.1429 | Q8: 483.1429 | R8: 0 | S8: 0.73333333 | T8: LUIZ
A9: TAHINA PAHINS COELHO | B9: CENTRO VILA VELHA | C9: 1848.4014 | D9: 1194.2857 | E9: 6 | F9: 0 | G9: 2315.2857 | H9: 781.7143 | I9: 189.7286 | J9: 298.0286 | K9: 0 | L9: 0 | M9: 0 | N9: 0 | O9: 0 | P9: 781.7143 | Q9: 887.5714 | R9: 1427.7143 | S9: 0.4 | T9: LUIZ
A10: BARBARA BORGES OLIVEIRA | B10: CENTRO VIX | C10: 2337 | D10: 447.8571 | E10: 6 | F10: 28977.714 | G10: 1639.4286 | H10: 3544.8571 | I10: 45.8714 | J10: 273.3286 | K10: 0 | L10: 0 | M10: 0 | N10: 0 | O10: 567.2857 | P10: 2977.5714 | Q10: 561.8571 | R10: 1077.5714 | S10: 0.4 | T10: LUIZ
A11: SAFYRA GOMES QUINTILIANO | B11: CENTRO VIX | C11: 746.4557 | D11: 787.1429 | E11: 9 | F11: 4204.4286 | G11: 187.2857 | H11: 0 | I11: 189.7286 | J11: 56.7286 | K11: 0 | L11: 0 | M11: 0 | N11: 0 | O11: 0 | P11: 0 | Q11: 187.2857 | R11: 0 | S11: 0.6 | T11: LUIZ
A12: RODRIGO ARAUJO BRAU | B12: CENTRO VIX | C12: 2147 | D12: 1872.83 | E12: 17 | F12: 46674.857 | G12: 3745.7143 | H12: 0 | I12: 189.7286 | J12: 219.3143 | K12: 0 | L12: 0 | M12: 0 | N12: 0 | O12: 0 | P12: 0 | Q12: 1346.2857 | R12: 2399.4286 | S12: 1.1333333 | T12: LUIZ
A13: BIANCA SALES SILVA | B13: GLÓRIA | C13: 2450.3214 | D13: 298.5714 | E13: 3 | F13: 6916 | G13: 574.2071 | H13: 703 | I13: 94.7286 | J13: 137.8857 | K13: 0 | L13: 0 | M13: 0 | N13: 0 | O13: 0 | P13: 703 | Q13: 574.2071 | R13: 0 | S13: 0.15789474 | T13: LUIZ
... A106: CARLOS EDUARDO DOS REIS SILVA | B106: SERRA SEDE | C106: 640.5714 | D106: 624.2857 | E106: 3 | F106: 0 | G106: 0 | H106: 0 | I106: 0 | J106: 162.5857 | K106: 0 | L106: 0 | M106: 0 | N106: 0 | O106: 0 | P106: 0 | Q106: 0 | R106: 0 | S106: 0 | T106: THAYANDRA

Sheet CAPA
B2: SELECIONE A LOJA
B6: ANCHIETA | E6: CENTRO VV | H6: ITACIBA
B8: ICONHA | E8: CENTRO VIX | H8: JACARAIPE
B10: PIUMA | E10: GLÓRIA | H10: LARANJEIRAS
B12: BOM JESUS | E12: JARDIM CAMBURI | H12: MARCILIO DE NORONHA
B14: MIRACEMA | E14: MASTERPLACE | H14: MONTSERRAT
B16: QUISSAMA | E16: NORTE SUL | H16: PORTO CANOA
B18: SAO FIDELIS | H18: SERRA SEDE
B20: ST PADUA

Sheet ARIEL
B2: SIMULADOR COORDENADOR
B6: HUNTER | J6: COORDENADOR | N6: 0 | O6: 2 | P6: 3
B7: MOVEL | C7: FIXA | D7: SMARTPHONE | E7: ELETRONICOS | F7: ESSESCIAIS | G7: SEGUROS | H7: SVA | J7: ARIEL
B8: 0 | C8: 0 | D8: 0 | E8: 0 | F8: 0 | G8: 0 | H8: 0
B11: PROJEÇÃO
B12: INDIVIDUAL
B13: PILAR | C13: PROJ PDV | F13: % - COMISSÃO | G13: R$ - COMISSÃO | H13: HUNTER 2 | I13: HUNTER 3 | J13: 6/7 PPILARES | K13: GANHO TOTAL COORDENADOR | L13: GANHO TOTAL SNIPER
C14: META | D14: ATINGIMENTO
B15: MÓVEL | C15: =SUMIFS(REALIZADO[META_MOVEL],REALIZADO[COORDENAÇÃO],$J$7) -> 65329 | D15: =SUMIFS(PROJEÇÃO[PROJ_MOVEL],PROJEÇÃO[COORDENAÇÃO],J7) -> 53812.804 | E15: =IFERROR(D15/C15,0) -> 0.82372 | F15: =VLOOKUP(E15,FATORES!$I$61:$K$65,3) -> 0.015 | G15: =D15*F15 -> 807.19206 | H15: =IF($B$8=2,G15*0.05,0) -> 0 | I15: =IF($B$8=3,G15*0.05,0) -> 0 | J15: 0.1 | K15: =SUM(G24:J24) -> 2479.4768 | L15: =K15*0.75 -> 1859.6076
B16: FIXA | C16: =SUMIFS(REALIZADO[META_FIXA],REALIZADO[COORDENAÇÃO],$J$7) -> 0 | D16: =SUMIFS(PROJEÇÃO[PROJ_FIXA],PROJEÇÃO[COORDENAÇÃO],J7) -> 0 | E16: =IFERROR(D16/C16,0) -> 0 | F16: =VLOOKUP(E16,FATORES!$I$68:$K$72,3) -> 0.005 | G16: =D16*F16 -> 0 | H16: =IF($C$8=2,G16*0.05,0) -> 0 | I16: =IF($C$8=3,G16*0.05,0) -> 0
B17: SMARTPHONES | C17: =SUMIFS(REALIZADO[META_SMARTPHONE],REALIZADO[COORDENAÇÃO],$J$7) -> 726000 | D17: =SUMIFS(PROJEÇÃO[PROJ_APARELHO],PROJEÇÃO[COORDENAÇÃO],J7) -> 670558.86 | E17: =IFERROR(D17/C17,0) -> 0.92363479 | F17: =VLOOKUP(E17,FATORES!$B$80:$D$83,3) -> 0.0015 | G17: =D17*F17 -> 1005.8383 | H17: =IF($D$8=2,G17*0.05,0) -> 0 | I17: =IF($D$8=3,G17*0.05,0) -> 0
B18: ELETRONICOS - A | C18: =SUMIFS(REALIZADO[META_ACESSORIO],REALIZADO[COORDENAÇÃO],$J$7) -> 77500 | D18: =SUMIFS(PROJEÇÃO[PROJ_ELETRO_A],PROJEÇÃO[COORDENAÇÃO],J7) -> 2646.4287 | E18: =IFERROR((D18+D19)/C18,0) -> 1.42873 | F18: =VLOOKUP(E18,FATORES!$B$72:$E$76,3) -> 0.003 | G18: =D18*F18 -> 7.9392861 | H18: =IF($E$8=2,G18*0.05,0) -> 0 | I18: =IF($E$8=3,G18*0.05,0) -> 0
B19: ELETRONICOS - B | D19: =SUMIFS(PROJEÇÃO[PROJ_ELETRO_B],PROJEÇÃO[COORDENAÇÃO],J7) -> 108080.14 | F19: =VLOOKUP(E18,FATORES!$B$72:$E$76,4) -> 0.0025 | G19: =D19*F19 -> 270.20036 | H19: =IF($E$8=2,G19*0.05,0) -> 0 | I19: =IF($E$8=3,G19*0.05,0) -> 0
B20: ESSENCIAIS - A | C20: =SUMIFS(REALIZADO[META_ESSENCIAIS],REALIZADO[COORDENAÇÃO],$J$7) -> 58100 | D20: =SUMIFS(PROJEÇÃO[PROJ_ESSEN_A],PROJEÇÃO[COORDENAÇÃO],J7) -> 30850.572 | E20: =IFERROR((D20+D21)/C20,0) -> 1.1747111 | F20: =VLOOKUP(E20,FATORES!$B$63:$E$67,3) -> 0.01 | G20: =D20*F20 -> 308.50572 | H20: =IF($F$8=2,G20*0.05,0) -> 0 | I20: =IF($F$8=3,G20*0.05,0) -> 0
B21: ESSENCIAIS - B | D21: =SUMIFS(PROJEÇÃO[PROJ_ESSEN_B],PROJEÇÃO[COORDENAÇÃO],J7) -> 37400.143 | F21: =VLOOKUP(E20,FATORES!$B$63:$E$67,4) -> 0.0012 | G21: =D21*F21 -> 44.880172 | H21: =IF($F$8=2,G21*0.05,0) -> 0 | I21: =IF($F$8=3,G21*0.05,0) -> 0
B22: SEGUROS | C22: =SUMIFS(REALIZADO[META_SEGUROS],REALIZADO[COORDENAÇÃO],$J$7) -> 6187.5 | D22: =SUMIFS(PROJEÇÃO[PROJ_SEGURO],PROJEÇÃO[COORDENAÇÃO],J7) -> 4375.9715 | E22: =IFERROR(D22/C22,0) -> 0.70722772 | F22: =VLOOKUP(E22,FATORES!$O$61:$Q$65,3) -> 0.005 | G22: =D22*F22 -> 21.879857 | H22: =IF($G$8=2,G22*0.05,0) -> 0 | I22: =IF($G$8=3,G22*0.05,0) -> 0
B23: SVA | C23: =SUMIFS(REALIZADO[META_SVA],REALIZADO[COORDENAÇÃO],$J$7) -> 5774.9999 | D23: =SUMIFS(PROJEÇÃO[PROJ_SVA],PROJEÇÃO[COORDENAÇÃO],J7) -> 5216.4229 | E23: =IFERROR(D23/C23,0) -> 0.90327671 | F23: =IF(E23>=0,FATORES!$Q$68) -> 0.0025 | G23: =D23*F23 -> 13.041057 | H23: =IF($H$8=2,G23*0.05,0) -> 0 | I23: =IF($H$8=3,G23*0.05,0) -> 0
G24: =SUM(G15:G23) -> 2479.4768 | H24: =SUM(H15:H23) -> 0 | I24: =SUM(I15:I23) -> 0 | J24: =IF($J$7="ARIEL",IF(MIN(E15,E17,E18,E19,E20,E22,E23)>=100%,G24*J15,""),IF(MIN(E15:E23)>=100%,G24*J15,""))
B26: REALIZADO
B27: INDIVIDUAL
B28: PILAR | C28: REAL PDV | F28: % - COMISSÃO | G28: R$ - COMISSÃO | H28: HUNTER 2 | I28: HUNTER 3 | J28: 6/7 PPILARES | K28: GANHO TOTAL COORDENADOR | L28: GANHO TOTAL SNIPER
C29: META | D29: ATINGIMENTO
B30: MÓVEL | C30: =SUMIFS(REALIZADO[META_MOVEL],REALIZADO[COORDENAÇÃO],$J$7) -> 65329 | D30: =SUMIFS(REALIZADO[AT_MOVEL],REALIZADO[COORDENAÇÃO],$J$7) -> 42429.64 | E30: =IFERROR(D30/C30,0) -> 0.64947634 | F30: =VLOOKUP($E$30,FATORES!$I$61:$K$65,3) -> 0.005 | G30: =D30*F30 -> 212.1482 | H30: =IF($B$8=2,G30*0.05,0) -> 0 | I30: =IF($B$8=3,G30*0.05,0) -> 0 | J30: 0.1 | K30: =SUM(G39:K39) -> 1267.142 | L30: =K30*0.75 -> 950.35652
B31: FIXA | C31: =SUMIFS(REALIZADO[META_FIXA],REALIZADO[COORDENAÇÃO],$J$7) -> 0 | D31: =SUMIFS(REALIZADO[AT_FIXA],REALIZADO[COORDENAÇÃO],J7) -> 60 | E31: =IFERROR(D31/C31,0) -> 0 | F31: =VLOOKUP($E$31,FATORES!$I$68:$K$72,3) -> 0.005 | G31: =D31*F31 -> 0.3 | H31: =IF($C$8=2,G31*0.05,0) -> 0 | I31: =IF($C$8=3,G31*0.05,0) -> 0
B32: SMARTPHONES | C32: =SUMIFS(REALIZADO[META_SMARTPHONE],REALIZADO[COORDENAÇÃO],$J$7) -> 726000 | D32: =SUMIFS(REALIZADO[AT_SMARTPHONE],REALIZADO[COORDENAÇÃO],J7) -> 656208 | E32: =IFERROR(D32/C32,0) -> 0.90386777 | F32: =VLOOKUP($E$32,FATORES!$B$80:$D$83,3) -> 0.0015 | G32: =D32*F32 -> 984.312 | H32: =IF($D$8=2,G32*0.05,0) -> 0 | I32: =IF($D$8=3,G32*0.05,0) -> 0
B33: ELETRONICOS - A | C33: =SUMIFS(REALIZADO[META_ACESSORIO],REALIZADO[COORDENAÇÃO],$J$7) -> 77500 | D33: =SUMIFS(REALIZADO[AT_ACESSORIOS_A],REALIZADO[COORDENAÇÃO],J7) -> 966 | E33: =IFERROR((D33+D34)/C33,0) -> 0.89779355 | F33: =IFERROR(VLOOKUP($E$33,FATORES!$B$72:$E$76,3),0) -> 0.0005 | G33: =D33*F33 -> 0.483 | H33: =IF($E$8=2,G33*0.05,0) -> 0 | I33: =IF($E$8=3,G33*0.05,0) -> 0
B34: ELETRONICOS - B | D34: =SUMIFS(REALIZADO[AT_ACESSORIOS_B],REALIZADO[COORDENAÇÃO],J7) -> 68613 | F34: =IFERROR(VLOOKUP($E$33,FATORES!$B$72:$E$76,4),0) -> 0.0004 | G34: =D34*F34 -> 27.4452 | H34: =IF($E$8=2,G34*0.05,0) -> 0 | I34: =IF($E$8=3,G34*0.05,0) -> 0
B35: ESSENCIAIS - A | C35: =SUMIFS(REALIZADO[META_ESSENCIAIS],REALIZADO[COORDENAÇÃO],$J$7) -> 58100 | D35: =SUMIFS(REALIZADO[AT_ESSENCIAIS_A],REALIZADO[COORDENAÇÃO],J7) -> 22540 | E35: =IFERROR((D35+D36)/C35,0) -> 0.82444062 | F35: =IFERROR(VLOOKUP($E$35,FATORES!$B$63:$E$67,3),0) -> 0.0004 | G35: =D35*F35 -> 9.016 | H35: =IF($F$8=2,G35*0.05,0) -> 0 | I35: =IF($F$8=3,G35*0.05,0) -> 0
B36: ESSENCIAIS - B | D36: =SUMIFS(REALIZADO[AT_ESSENCIAIS_B],REALIZADO[COORDENAÇÃO],J7) -> 25360 | F36: =IFERROR(VLOOKUP($E$35,FATORES!$B$63:$E$67,4),0) -> 0.0002 | G36: =D36*F36 -> 5.072 | H36: =IF($F$8=2,G36*0.05,0) -> 0 | I36: =IF($F$8=3,G36*0.05,0) -> 0
B37: SEGUROS | C37: =SUMIFS(REALIZADO[META_SEGUROS],REALIZADO[COORDENAÇÃO],$J$7) -> 6187.5 | D37: =SUMIFS(REALIZADO[AT_SEGUROS],REALIZADO[COORDENAÇÃO],J7) -> 3400.7 | E37: =IFERROR(D37/C37,0) -> 0.54960808 | F37: =VLOOKUP($E$37,FATORES!$O$61:$Q$65,3) -> 0.005 | G37: =D37*F37 -> 17.0035 | H37: =IF($G$8=2,G37*0.05,0) -> 0 | I37: =IF($G$8=3,G37*0.05,0) -> 0
B38: SVA | C38: =SUMIFS(REALIZADO[META_SVA],REALIZADO[COORDENAÇÃO],$J$7) -> 5774.9999 | D38: =SUMIFS(REALIZADO[AT_SVA],REALIZADO[COORDENAÇÃO],J7) -> 4544.85 | E38: =IFERROR(D38/C38,0) -> 0.78698703 | F38: =IF($E$38>=0,FATORES!$Q$68) -> 0.0025 | G38: =D38*F38 -> 11.362125 | H38: =IF($H$8=2,G38*0.05,0) -> 0 | I38: =IF($H$8=3,G38*0.05,0) -> 0
G39: =SUM(G30:G38) -> 1267.142 | H39: =SUM(H30:H38) -> 0 | I39: =SUM(I30:I38) -> 0 | J39: =IF($J$7="ARIEL",IF(MIN(E30,E32,E33,E34,E35,E37,E38)>=100%,G39*J30,""),IF(MIN(E30:E38)>=100%,G39*J30,""))
B41: SIMULADOR
B42: INDIVIDUAL
B43: PILAR | C43: REAL PDV | F43: % - COMISSÃO | G43: R$ - COMISSÃO | H43: HUNTER 2 | I43: HUNTER 3 | J43: 6/7 PPILARES | K43: GANHO TOTAL COORDENADOR | L43: GANHO TOTAL SNIPER
C44: META | D44: ATINGIMENTO
B45: MÓVEL | C45: =SUMIFS(REALIZADO[META_MOVEL],REALIZADO[COORDENAÇÃO],$J$7) -> 65329 | D45: =SUMIFS(REALIZADO[META_MOVEL],REALIZADO[COORDENAÇÃO],$J$7) -> 65329 | E45: =IFERROR(D45/C45,0) -> 1 | F45: =VLOOKUP(E45,FATORES!$I$61:$K$65,3) -> 0.045 | G45: =D45*F45 -> 2939.805 | H45: =IF($B$8=2,G45*0.05,0) -> 0 | I45: =IF($B$8=3,G45*0.05,0) -> 0 | J45: 0.1 | K45: =SUM(G54:J54) -> 5297.9025 | L45: =K45*0.75 -> 3973.4269
B46: FIXA | C46: =SUMIFS(REALIZADO[META_FIXA],REALIZADO[COORDENAÇÃO],$J$7) -> 0 | D46: =SUMIFS(REALIZADO[META_FIXA],REALIZADO[COORDENAÇÃO],$J$7) -> 0 | E46: =IFERROR(D46/C46,0) -> 0 | F46: =VLOOKUP(E46,FATORES!$I$68:$K$72,3) -> 0.005 | G46: =D46*F46 -> 0 | H46: =IF($C$8=2,G46*0.05,0) -> 0 | I46: =IF($C$8=3,G46*0.05,0) -> 0
B47: SMARTPHONES | C47: 548000 | D47: =SUMIFS(REALIZADO[META_SMARTPHONE],REALIZADO[COORDENAÇÃO],$J$7) -> 726000 | E47: =IFERROR(D47/C47,0) -> 1.3248175 | F47: =VLOOKUP(E47,FATORES!$B$80:$D$83,3) -> 0.002 | G47: =D47*F47 -> 1452 | H47: =IF($D$8=2,G47*0.05,0) -> 0 | I47: =IF($D$8=3,G47*0.05,0) -> 0
B48: ELETRONICOS - A | C48: =SUMIFS(REALIZADO[META_ACESSORIO],REALIZADO[COORDENAÇÃO],$J$7) -> 77500 | D48: =SUMIFS(REALIZADO[META_ACESSORIO],REALIZADO[COORDENAÇÃO],$J$7) -> 77500 | E48: =IFERROR((D48+D49)/C48,0) -> 1 | F48: =IFERROR(VLOOKUP(E48,FATORES!$B$72:$E$76,3),0) -> 0 | G48: =D48*F48 -> 0 | H48: =IF($E$8=2,G48*0.05,0) -> 0 | I48: =IF($E$8=3,G48*0.05,0) -> 0
...

Sheet LUIZ
B2: SIMULADOR COORDENADOR
B6: HUNTER | J6: COORDENADOR | N6: 0 | O6: 2 | P6: 3
B7: MOVEL | C7: FIXA | D7: SMARTPHONE | E7: ELETRONICOS | F7: ESSESCIAIS | G7: SEGUROS | H7: SVA | J7: LUIZ
B8: 0 | C8: 0 | D8: 0 | E8: 0 | F8: 0 | G8: 0 | H8: 0
B11: PROJEÇÃO
B12: INDIVIDUAL
B13: PILAR | C13: PROJ PDV | F13: % - COMISSÃO | G13: R$ - COMISSÃO | H13: HUNTER 2 | I13: HUNTER 3 | J13: 6/7 PILARES | K13: GANHO TOTAL COORDENADOR | L13: GANHO TOTAL SNIPER
C14: META | D14: ATINGIMENTO
B15: MÓVEL | C15: =SUMIFS(REALIZADO[META_MOVEL],REALIZADO[COORDENAÇÃO],$J$7) -> 59895 | D15: =SUMIFS(PROJEÇÃO[PROJ_MOVEL],PROJEÇÃO[COORDENAÇÃO],J7) -> 47060.231 | E15: =IFERROR(D15/C15,0) -> 0.78571219 | F15: =VLOOKUP(E15,FATORES!$I$61:$K$65,3) -> 0.005 | G15: =D15*F15 -> 235.30116 | H15: =IF($B$8=2,G15*0.05,0) -> 0 | I15: =IF($B$8=3,G15*0.05,0) -> 0 | J15: 0.1 | K15: =SUM(G24:J24) -> 1177.7278 | L15: =K15*0.75 -> 883.29582
B16: FIXA | C16: =SUMIFS(REALIZADO[META_FIXA],REALIZADO[COORDENAÇÃO],$J$7) -> 34210 | D16: =SUMIFS(PROJEÇÃO[PROJ_FIXA],PROJEÇÃO[COORDENAÇÃO],J7) -> 28133.49 | E16: =IFERROR(D16/C16,0) -> 0.8223762 | F16: =VLOOKUP(E16,FATORES!$I$68:$K$72,3) -> 0.015 | G16: =D16*F16 -> 422.00235 | H16: =IF($C$8=2,G16*0.05,0) -> 0 | I16: =IF($C$8=3,G16*0.05,0) -> 0
B17: SMARTPHONES | C17: =SUMIFS(REALIZADO[META_SMARTPHONE],REALIZADO[COORDENAÇÃO],$J$7) -> 727000 | D17: =SUMIFS(PROJEÇÃO[PROJ_APARELHO],PROJEÇÃO[COORDENAÇÃO],J7) -> 569991.99 | E17: =IFERROR(D17/C17,0) -> 0.784033 | F17: =VLOOKUP(E17,FATORES!$B$80:$D$83,3) -> 0.0005 | G17: =D17*F17 -> 284.996 | H17: =IF($D$8=2,G17*0.05,0) -> 0 | I17: =IF($D$8=3,G17*0.05,0) -> 0
B18: ELETRONICOS - A | C18: =SUMIFS(REALIZADO[META_ACESSORIO],REALIZADO[COORDENAÇÃO],$J$7) -> 82700 | D18: =SUMIFS(PROJEÇÃO[PROJ_ELETRO_A],PROJEÇÃO[COORDENAÇÃO],J7) -> 8859.4286 | E18: =IFERROR((D18+D19)/C18,0) -> 1.2111885 | F18: =VLOOKUP(E18,FATORES!$B$72:$E$76,3) -> 0 | G18: =D18*F18 -> 0 | H18: =IF($E$8=2,G18*0.05,0) -> 0 | I18: =IF($E$8=3,G18*0.05,0) -> 0
B19: ELETRONICOS - B | D19: =SUMIFS(PROJEÇÃO[PROJ_ELETRO_B],PROJEÇÃO[COORDENAÇÃO],J7) -> 91305.857 | F19: =VLOOKUP(E18,FATORES!$B$72:$E$76,4) -> 0.002 | G19: =D19*F19 -> 182.61171 | H19: =IF($E$8=2,G19*0.05,0) -> 0 | I19: =IF($E$8=3,G19*0.05,0) -> 0
B20: ESSENCIAIS - A | C20: =SUMIFS(REALIZADO[META_ESSENCIAIS],REALIZADO[COORDENAÇÃO],$J$7) -> 40700 | D20: =SUMIFS(PROJEÇÃO[PROJ_ESSEN_A],PROJEÇÃO[COORDENAÇÃO],J7) -> 16991.021 | E20: =IFERROR((D20+D21)/C20,0) -> 0.96408161 | F20: =VLOOKUP(E20,FATORES!$B$63:$E$67,3) -> 0.0006 | G20: =D20*F20 -> 10.194613 | H20: =IF($F$8=2,G20*0.05,0) -> 0 | I20: =IF($F$8=3,G20*0.05,0) -> 0
B21: ESSENCIAIS - B | D21: =SUMIFS(PROJEÇÃO[PROJ_ESSEN_B],PROJEÇÃO[COORDENAÇÃO],J7) -> 22247.1 | F21: =VLOOKUP(E20,FATORES!$B$63:$E$67,4) -> 0.0003 | G21: =D21*F21 -> 6.67413 | H21: =IF($F$8=2,G21*0.05,0) -> 0 | I21: =IF($F$8=3,G21*0.05,0) -> 0
B22: SEGUROS | C22: =SUMIFS(REALIZADO[META_SEGUROS],REALIZADO[COORDENAÇÃO],$J$7) -> 5555.0004 | D22: =SUMIFS(PROJEÇÃO[PROJ_SEGURO],PROJEÇÃO[COORDENAÇÃO],J7) -> 4193.3004 | E22: =IFERROR(D22/C22,0) -> 0.7548695 | F22: =VLOOKUP(E22,FATORES!$O$61:$Q$65,3) -> 0.005 | G22: =D22*F22 -> 20.966502 | H22: =IF($G$8=2,G22*0.05,0) -> 0 | I22: =IF($G$8=3,G22*0.05,0) -> 0
B23: SVA | C23: =SUMIFS(REALIZADO[META_SVA],REALIZADO[COORDENAÇÃO],$J$7) -> 4784.9998 | D23: =SUMIFS(PROJEÇÃO[PROJ_SVA],PROJEÇÃO[COORDENAÇÃO],J7) -> 5992.5187 | E23: =IFERROR(D23/C23,0) -> 1.2523551 | F23: =IF(E23>=0,FATORES!$Q$68) -> 0.0025 | G23: =D23*F23 -> 14.981297 | H23: =IF($H$8=2,G23*0.05,0) -> 0 | I23: =IF($H$8=3,G23*0.05,0) -> 0
G24: =SUM(G15:G23) -> 1177.7278 | H24: =SUM(H15:H23) -> 0 | I24: =SUM(I15:I23) -> 0 | J24: =IF($J$7="ARIEL",IF(MIN(E15,E17,E18,E19,E20,E22,E23)>=100%,G24*J15,""),IF(MIN(E15:E23)>=100%,G24*J15,""))
B26: REALIZADO
B27: INDIVIDUAL
B28: PILAR | C28: REAL PDV | F28: % - COMISSÃO | G28: R$ - COMISSÃO | H28: HUNTER 2 | I28: HUNTER 3 | J28: 6/7 PPILARES | K28: GANHO TOTAL COORDENADOR | L28: GANHO TOTAL SNIPER
C29: META | D29: ATINGIMENTO
B30: MÓVEL | C30: =SUMIFS(REALIZADO[META_MOVEL],REALIZADO[COORDENAÇÃO],$J$7) -> 59895 | D30: =SUMIFS(REALIZADO[AT_MOVEL],REALIZADO[COORDENAÇÃO],$J$7) -> 36584.13 | E30: =IFERROR(D30/C30,0) -> 0.61080441 | F30: =VLOOKUP($E$30,FATORES!$I$61:$K$65,3) -> 0.005 | G30: =D30*F30 -> 182.92065 | H30: =IF($B$8=2,G30*0.05,0) -> 0 | I30: =IF($B$8=3,G30*0.05,0) -> 0 | J30: 0.1 | K30: =SUM(G39:K39) -> 588.0638 | L30: =K30*0.75 -> 441.04785
B31: FIXA | C31: =SUMIFS(REALIZADO[META_FIXA],REALIZADO[COORDENAÇÃO],$J$7) -> 34210 | D31: =SUMIFS(REALIZADO[AT_FIXA],REALIZADO[COORDENAÇÃO],J7) -> 15581.84 | E31: =IFERROR(D31/C31,0) -> 0.45547618 | F31: =VLOOKUP($E$31,FATORES!$I$68:$K$72,3) -> 0.005 | G31: =D31*F31 -> 77.9092 | H31: =IF($C$8=2,G31*0.05,0) -> 0 | I31: =IF($C$8=3,G31*0.05,0) -> 0
B32: SMARTPHONES | C32: =SUMIFS(REALIZADO[META_SMARTPHONE],REALIZADO[COORDENAÇÃO],$J$7) -> 727000 | D32: =SUMIFS(REALIZADO[AT_SMARTPHONE],REALIZADO[COORDENAÇÃO],J7) -> 543786 | E32: =IFERROR(D32/C32,0) -> 0.74798625 | F32: =VLOOKUP($E$32,FATORES!$B$80:$D$83,3) -> 0.0005 | G32: =D32*F32 -> 271.893 | H32: =IF($D$8=2,G32*0.05,0) -> 0 | I32: =IF($D$8=3,G32*0.05,0) -> 0
B33: ELETRONICOS - A | C33: =SUMIFS(REALIZADO[META_ACESSORIO],REALIZADO[COORDENAÇÃO],$J$7) -> 82700 | D33: =SUMIFS(REALIZADO[AT_ACESSORIOS_A],REALIZADO[COORDENAÇÃO],J7) -> 156 | E33: =IFERROR((D33+D34)/C33,0) -> 0.80564692 | F33: =IFERROR(VLOOKUP($E$33,FATORES!$B$72:$E$76,3),0) -> 0.0005 | G33: =D33*F33 -> 0.078 | H33: =IF($E$8=2,G33*0.05,0) -> 0 | I33: =IF($E$8=3,G33*0.05,0) -> 0
B34: ELETRONICOS - B | D34: =SUMIFS(REALIZADO[AT_ACESSORIOS_B],REALIZADO[COORDENAÇÃO],J7) -> 66471 | F34: =IFERROR(VLOOKUP($E$33,FATORES!$B$72:$E$76,4),0) -> 0.0004 | G34: =D34*F34 -> 26.5884 | H34: =IF($E$8=2,G34*0.05,0) -> 0 | I34: =IF($E$8=3,G34*0.05,0) -> 0
B35: ESSENCIAIS - A | C35: =SUMIFS(REALIZADO[META_ESSENCIAIS],REALIZADO[COORDENAÇÃO],$J$7) -> 40700 | D35: =SUMIFS(REALIZADO[AT_ESSENCIAIS_A],REALIZADO[COORDENAÇÃO],J7) -> 11880 | E35: =IFERROR((D35+D36)/C35,0) -> 0.69918944 | F35: =IFERROR(VLOOKUP($E$35,FATORES!$B$63:$E$67,3),0) -> 0 | G35: =D35*F35 -> 0 | H35: =IF($F$8=2,G35*0.05,0) -> 0 | I35: =IF($F$8=3,G35*0.05,0) -> 0
B36: ESSENCIAIS - B | D36: =SUMIFS(REALIZADO[AT_ESSENCIAIS_B],REALIZADO[COORDENAÇÃO],J7) -> 16577.01 | F36: =IFERROR(VLOOKUP($E$35,FATORES!$B$63:$E$67,4),0) -> 0 | G36: =D36*F36 -> 0 | H36: =IF($F$8=2,G36*0.05,0) -> 0 | I36: =IF($F$8=3,G36*0.05,0) -> 0
B37: SEGUROS | C37: =SUMIFS(REALIZADO[META_SEGUROS],REALIZADO[COORDENAÇÃO],$J$7) -> 5555.0004 | D37: =SUMIFS(REALIZADO[AT_SEGUROS],REALIZADO[COORDENAÇÃO],J7) -> 3689.3 | E37: =IFERROR(D37/C37,0) -> 0.66414037 | F37: =VLOOKUP($E$37,FATORES!$O$61:$Q$65,3) -> 0.005 | G37: =D37*F37 -> 18.4465 | H37: =IF($G$8=2,G37*0.05,0) -> 0 | I37: =IF($G$8=3,G37*0.05,0) -> 0
B38: SVA | C38: =SUMIFS(REALIZADO[META_SVA],REALIZADO[COORDENAÇÃO],$J$7) -> 4784.9998 | D38: =SUMIFS(REALIZADO[AT_SVA],REALIZADO[COORDENAÇÃO],J7) -> 4091.22 | E38: =IFERROR(D38/C38,0) -> 0.85500944 | F38: =IF($E$38>=0,FATORES!$Q$68) -> 0.0025 | G38: =D38*F38 -> 10.22805 | H38: =IF($H$8=2,G38*0.05,0) -> 0 | I38: =IF($H$8=3,G38*0.05,0) -> 0
G39: =SUM(G30:G38) -> 588.0638 | H39: =SUM(H30:H38) -> 0 | I39: =SUM(I30:I38) -> 0 | J39: =IF($J$7="ARIEL",IF(MIN(E30,E32,E33,E34,E35,E37,E38)>=100%,G39*J30,""),IF(MIN(E30:E38)>=100%,G39*J30,""))
B41: SIMULADOR
B42: INDIVIDUAL
B43: PILAR | C43: REAL PDV | F43: % - COMISSÃO | G43: R$ - COMISSÃO | H43: HUNTER 2 | I43: HUNTER 3 | J43: 6/7 PPILARES | K43: GANHO TOTAL COORDENADOR | L43: GANHO TOTAL SNIPER
C44: META | D44: ATINGIMENTO
B45: MÓVEL | C45: 80130.5 | D45: 83457.04 | E45: =IFERROR(D45/C45,0) -> 1.041514 | F45: =VLOOKUP(E45,FATORES!$I$61:$K$65,3) -> 0.045 | G45: =D45*F45 -> 3755.5668 | H45: =IF($B$8=2,G45*0.05,0) -> 0 | I45: =IF($B$8=3,G45*0.05,0) -> 0 | J45: 0.1 | K45: =SUM(G54:J54) -> 7710.7468 | L45: =K45*0.75 -> 5783.0601
B46: FIXA | C46: 29151.73 | D46: 25331.79 | E46: =IFERROR(D46/C46,0) -> 0.86896352 | F46: =VLOOKUP(E46,FATORES!$I$68:$K$72,3) -> 0.015 | G46: =D46*F46 -> 379.97685 | H46: =IF($C$8=2,G46*0.05,0) -> 0 | I46: =IF($C$8=3,G46*0.05,0) -> 0
B47: SMARTPHONES | C47: 1176070 | D47: 1339366 | E47: =IFERROR(D47/C47,0) -> 1.1388489 | F47: =VLOOKUP(E47,FATORES!$B$80:$D$83,3) -> 0.002 | G47: =D47*F47 -> 2678.732 | H47: =IF($D$8=2,G47*0.05,0) -> 0 | I47: =IF($D$8=3,G47*0.05,0) -> 0
B48: ELETRONICOS - A | C48: 130145.66 | D48: 1 | E48: =IFERROR((D48+D49)/C48,0) -> 1.0934364 | F48: =IFERROR(VLOOKUP(E48,FATORES!$B$72:$E$76,3),0) -> 0 | G48: =D48*F48 -> 0 | H48: =IF($E$8=2,G48*0.05,0) -> 0 | I48: =IF($E$8=3,G48*0.05,0) -> 0
...

Sheet THAYANDRA
B2: SIMULADOR COORDENADOR
B6: HUNTER | J6: COORDENADOR | N6: 0 | O6: 2 | P6: 3
B7: MOVEL | C7: FIXA | D7: SMARTPHONE | E7: ELETRONICOS | F7: ESSESCIAIS | G7: SEGUROS | H7: SVA | J7: THAYANDRA
B8: 0 | C8: 0 | D8: 3 | E8: 3 | F8: 3 | G8: 0 | H8: 0
B11: PROJEÇÃO
B12: INDIVIDUAL
B13: PILAR | C13: PROJ PDV | F13: % - COMISSÃO | G13: R$ - COMISSÃO | H13: HUNTER 2 | I13: HUNTER 3 | J13: 6/7 PPILARES | K13: GANHO TOTAL COORDENADOR | L13: GANHO TOTAL SNIPER
C14: META | D14: ATINGIMENTO
B15: MÓVEL | C15: =SUMIFS(REALIZADO[META_MOVEL],REALIZADO[COORDENAÇÃO],$J$7) -> 92664 | D15: =SUMIFS(PROJEÇÃO[PROJ_MOVEL],PROJEÇÃO[COORDENAÇÃO],J7) -> 75957.06 | E15: =IFERROR(D15/C15,0) -> 0.81970409 | F15: =VLOOKUP(E15,FATORES!$I$61:$K$65,3) -> 0.015 | G15: =D15*F15 -> 1139.3559 | H15: =IF($B$8=2,G15*0.05,0) -> 0 | I15: =IF($B$8=3,G15*0.05,0) -> 0 | J15: 0.1 | K15: =SUM(G24:J24) -> 6187.9953 | L15: =K15*0.75 -> 4640.9964
B16: FIXA | C16: =SUMIFS(REALIZADO[META_FIXA],REALIZADO[COORDENAÇÃO],$J$7) -> 40920 | D16: =SUMIFS(PROJEÇÃO[PROJ_FIXA],PROJEÇÃO[COORDENAÇÃO],J7) -> 40097.98 | E16: =IFERROR(D16/C16,0) -> 0.97991153 | F16: =VLOOKUP(E16,FATORES!$I$68:$K$72,3) -> 0.025 | G16: =D16*F16 -> 1002.4495 | H16: =IF($C$8=2,G16*0.05,0) -> 0 | I16: =IF($C$8=3,G16*0.05,0) -> 0
B17: SMARTPHONES | C17: =SUMIFS(REALIZADO[META_SMARTPHONE],REALIZADO[COORDENAÇÃO],$J$7) -> 1248000 | D17: =SUMIFS(PROJEÇÃO[PROJ_APARELHO],PROJEÇÃO[COORDENAÇÃO],J7) -> 1379609.3 | E17: =IFERROR(D17/C17,0) -> 1.1054561 | F17: =VLOOKUP(E17,FATORES!$B$80:$D$83,3) -> 0.002 | G17: =D17*F17 -> 2759.2185 | H17: =IF($D$8=2,G17*0.05,0) -> 0 | I17: =IF($D$8=3,G17*0.05,0) -> 137.96093
B18: ELETRONICOS - A | C18: =SUMIFS(REALIZADO[META_ACESSORIO],REALIZADO[COORDENAÇÃO],$J$7) -> 136000 | D18: =SUMIFS(PROJEÇÃO[PROJ_ELETRO_A],PROJEÇÃO[COORDENAÇÃO],J7) -> 3121.4286 | E18: =IFERROR((D18+D19)/C18,0) -> 1.3399989 | F18: =VLOOKUP(E18,FATORES!$B$72:$E$76,3) -> 0.003 | G18: =D18*F18 -> 9.3642858 | H18: =IF($E$8=2,G18*0.05,0) -> 0 | I18: =IF($E$8=3,G18*0.05,0) -> 0.46821429
B19: ELETRONICOS - B | D19: =SUMIFS(PROJEÇÃO[PROJ_ELETRO_B],PROJEÇÃO[COORDENAÇÃO],J7) -> 179118.43 | F19: =VLOOKUP(E18,FATORES!$B$72:$E$76,4) -> 0.0025 | G19: =D19*F19 -> 447.79607 | H19: =IF($E$8=2,G19*0.05,0) -> 0 | I19: =IF($E$8=3,G19*0.05,0) -> 22.389804
B20: ESSENCIAIS - A | C20: =SUMIFS(REALIZADO[META_ESSENCIAIS],REALIZADO[COORDENAÇÃO],$J$7) -> 78900 | D20: =SUMIFS(PROJEÇÃO[PROJ_ESSEN_A],PROJEÇÃO[COORDENAÇÃO],J7) -> 34485.814 | E20: =IFERROR((D20+D21)/C20,0) -> 1.0532887 | F20: =VLOOKUP(E20,FATORES!$B$63:$E$67,3) -> 0.01 | G20: =D20*F20 -> 344.85814 | H20: =IF($F$8=2,G20*0.05,0) -> 0 | I20: =IF($F$8=3,G20*0.05,0) -> 17.242907
B21: ESSENCIAIS - B | D21: =SUMIFS(PROJEÇÃO[PROJ_ESSEN_B],PROJEÇÃO[COORDENAÇÃO],J7) -> 48618.666 | F21: =VLOOKUP(E20,FATORES!$B$63:$E$67,4) -> 0.0012 | G21: =D21*F21 -> 58.342399 | H21: =IF($F$8=2,G21*0.05,0) -> 0 | I21: =IF($F$8=3,G21*0.05,0) -> 2.9171199
B22: SEGUROS | C22: =SUMIFS(REALIZADO[META_SEGUROS],REALIZADO[COORDENAÇÃO],$J$7) -> 9135.5 | D22: =SUMIFS(PROJEÇÃO[PROJ_SEGURO],PROJEÇÃO[COORDENAÇÃO],J7) -> 8704.1715 | E22: =IFERROR(D22/C22,0) -> 0.95278545 | F22: =VLOOKUP(E22,FATORES!$O$61:$Q$65,3) -> 0.025 | G22: =D22*F22 -> 217.60429 | H22: =IF($G$8=2,G22*0.05,0) -> 0 | I22: =IF($G$8=3,G22*0.05,0) -> 0
B23: SVA | C23: =SUMIFS(REALIZADO[META_SVA],REALIZADO[COORDENAÇÃO],$J$7) -> 7974.9999 | D23: =SUMIFS(PROJEÇÃO[PROJ_SVA],PROJEÇÃO[COORDENAÇÃO],J7) -> 11210.869 | E23: =IFERROR(D23/C23,0) -> 1.4057516 | F23: =IF(E23>=0,FATORES!$Q$68) -> 0.0025 | G23: =D23*F23 -> 28.027172 | H23: =IF($H$8=2,G23*0.05,0) -> 0 | I23: =IF($H$8=3,G23*0.05,0) -> 0
G24: =SUM(G15:G23) -> 6007.0163 | H24: =SUM(H15:H23) -> 0 | I24: =SUM(I15:I23) -> 180.97897 | J24: =IF($J$7="ARIEL",IF(MIN(E15,E17,E18,E19,E20,E22,E23)>=100%,G24*J15,""),IF(MIN(E15:E23)>=100%,G24*J15,""))
B26: REALIZADO
B27: INDIVIDUAL
B28: PILAR | C28: REAL PDV | F28: % - COMISSÃO | G28: R$ - COMISSÃO | H28: HUNTER 2 | I28: HUNTER 3 | J28: 6/7 PPILARES | K28: GANHO TOTAL COORDENADOR | L28: GANHO TOTAL SNIPER
C29: META | D29: ATINGIMENTO
B30: MÓVEL | C30: =SUMIFS(REALIZADO[META_MOVEL],REALIZADO[COORDENAÇÃO],$J$7) -> 92664 | D30: =SUMIFS(REALIZADO[AT_MOVEL],REALIZADO[COORDENAÇÃO],$J$7) -> 63104.82 | E30: =IFERROR(D30/C30,0) -> 0.68100686 | F30: =VLOOKUP($E$30,FATORES!$I$61:$K$65,3) -> 0.005 | G30: =D30*F30 -> 315.5241 | H30: =IF($B$8=2,G30*0.05,0) -> 0 | I30: =IF($B$8=3,G30*0.05,0) -> 0 | J30: 0.1 | K30: =SUM(G39:K39) -> 1009.902 | L30: =K30*0.75 -> 757.42646
B31: FIXA | C31: =SUMIFS(REALIZADO[META_FIXA],REALIZADO[COORDENAÇÃO],$J$7) -> 40920 | D31: =SUMIFS(REALIZADO[AT_FIXA],REALIZADO[COORDENAÇÃO],J7) -> 25910.67 | E31: =IFERROR(D31/C31,0) -> 0.63320308 | F31: =VLOOKUP($E$31,FATORES!$I$68:$K$72,3) -> 0.005 | G31: =D31*F31 -> 129.55335 | H31: =IF($C$8=2,G31*0.05,0) -> 0 | I31: =IF($C$8=3,G31*0.05,0) -> 0
B32: SMARTPHONES | C32: =SUMIFS(REALIZADO[META_SMARTPHONE],REALIZADO[COORDENAÇÃO],$J$7) -> 1248000 | D32: =SUMIFS(REALIZADO[AT_SMARTPHONE],REALIZADO[COORDENAÇÃO],J7) -> 979341.05 | E32: =IFERROR(D32/C32,0) -> 0.78472841 | F32: =VLOOKUP($E$32,FATORES!$B$80:$D$83,3) -> 0.0005 | G32: =D32*F32 -> 489.67053 | H32: =IF($D$8=2,G32*0.05,0) -> 0 | I32: =IF($D$8=3,G32*0.05,0) -> 24.483526
B33: ELETRONICOS - A | C33: =SUMIFS(REALIZADO[META_ACESSORIO],REALIZADO[COORDENAÇÃO],$J$7) -> 136000 | D33: =SUMIFS(REALIZADO[AT_ACESSORIOS_A],REALIZADO[COORDENAÇÃO],J7) -> 6036 | E33: =IFERROR((D33+D34)/C33,0) -> 0.75191948 | F33: =IFERROR(VLOOKUP($E$33,FATORES!$B$72:$E$76,3),0) -> 0 | G33: =D33*F33 -> 0 | H33: =IF($E$8=2,G33*0.05,0) -> 0 | I33: =IF($E$8=3,G33*0.05,0) -> 0
B34: ELETRONICOS - B | D34: =SUMIFS(REALIZADO[AT_ACESSORIOS_B],REALIZADO[COORDENAÇÃO],J7) -> 96225.05 | F34: =IFERROR(VLOOKUP($E$33,FATORES!$B$72:$E$76,4),0) -> 0 | G34: =D34*F34 -> 0 | H34: =IF($E$8=2,G34*0.05,0) -> 0 | I34: =IF($E$8=3,G34*0.05,0) -> 0
B35: ESSENCIAIS - A | C35: =SUMIFS(REALIZADO[META_ESSENCIAIS],REALIZADO[COORDENAÇÃO],$J$7) -> 78900 | D35: =SUMIFS(REALIZADO[AT_ESSENCIAIS_A],REALIZADO[COORDENAÇÃO],J7) -> 25227 | E35: =IFERROR((D35+D36)/C35,0) -> 0.75070976 | F35: =IFERROR(VLOOKUP($E$35,FATORES!$B$63:$E$67,3),0) -> 0 | G35: =D35*F35 -> 0 | H35: =IF($F$8=2,G35*0.05,0) -> 0 | I35: =IF($F$8=3,G35*0.05,0) -> 0
B36: ESSENCIAIS - B | D36: =SUMIFS(REALIZADO[AT_ESSENCIAIS_B],REALIZADO[COORDENAÇÃO],J7) -> 34004 | F36: =IFERROR(VLOOKUP($E$35,FATORES!$B$63:$E$67,4),0) -> 0 | G36: =D36*F36 -> 0 | H36: =IF($F$8=2,G36*0.05,0) -> 0 | I36: =IF($F$8=3,G36*0.05,0) -> 0
B37: SEGUROS | C37: =SUMIFS(REALIZADO[META_SEGUROS],REALIZADO[COORDENAÇÃO],$J$7) -> 9135.5 | D37: =SUMIFS(REALIZADO[AT_SEGUROS],REALIZADO[COORDENAÇÃO],J7) -> 6645.7 | E37: =IFERROR(D37/C37,0) -> 0.72745881 | F37: =VLOOKUP($E$37,FATORES!$O$61:$Q$65,3) -> 0.005 | G37: =D37*F37 -> 33.2285 | H37: =IF($G$8=2,G37*0.05,0) -> 0 | I37: =IF($G$8=3,G37*0.05,0) -> 0
B38: SVA | C38: =SUMIFS(REALIZADO[META_SVA],REALIZADO[COORDENAÇÃO],$J$7) -> 7974.9999 | D38: =SUMIFS(REALIZADO[AT_SVA],REALIZADO[COORDENAÇÃO],J7) -> 6976.78 | E38: =IFERROR(D38/C38,0) -> 0.87483136 | F38: =IF($E$38>=0,FATORES!$Q$68) -> 0.0025 | G38: =D38*F38 -> 17.44195 | H38: =IF($H$8=2,G38*0.05,0) -> 0 | I38: =IF($H$8=3,G38*0.05,0) -> 0
G39: =SUM(G30:G38) -> 985.41843 | H39: =SUM(H30:H38) -> 0 | I39: =SUM(I30:I38) -> 24.483526 | J39: =IF($J$7="ARIEL",IF(MIN(E30,E32,E33,E34,E35,E37,E38)>=100%,G39*J30,""),IF(MIN(E30:E38)>=100%,G39*J30,""))
B41: SIMULADOR
B42: INDIVIDUAL
B43: PILAR | C43: REAL PDV | F43: % - COMISSÃO | G43: R$ - COMISSÃO | H43: HUNTER 2 | I43: HUNTER 3 | J43: 6/7 PPILARES | K43: GANHO TOTAL COORDENADOR | L43: GANHO TOTAL SNIPER
C44: META | D44: ATINGIMENTO
B45: MÓVEL | C45: 55000 | D45: 55000 | E45: =IFERROR(D45/C45,0) -> 1 | F45: =VLOOKUP(E45,FATORES!$I$61:$K$65,3) -> 0.045 | G45: =D45*F45 -> 2475 | H45: =IF($B$8=2,G45*0.05,0) -> 0 | I45: =IF($B$8=3,G45*0.05,0) -> 0 | J45: 0.1 | K45: =SUM(G54:J54) -> 5980.5821 | L45: =K45*0.75 -> 4485.4366
B46: FIXA | C46: 29000 | D46: 29000 | E46: =IFERROR(D46/C46,0) -> 1 | F46: =VLOOKUP(E46,FATORES!$I$68:$K$72,3) -> 0.055 | G46: =D46*F46 -> 1595 | H46: =IF($C$8=2,G46*0.05,0) -> 0 | I46: =IF($C$8=3,G46*0.05,0) -> 0
B47: SMARTPHONES | C47: 800000 | D47: 800001 | E47: =IFERROR(D47/C47,0) -> 1.0000012 | F47: =VLOOKUP(E47,FATORES!$B$80:$D$83,3) -> 0.002 | G47: =D47*F47 -> 1600.002 | H47: =IF($D$8=2,G47*0.05,0) -> 0 | I47: =IF($D$8=3,G47*0.05,0) -> 80.0001
B48: ELETRONICOS - A | C48: 83000 | E48: =IFERROR((D48+D49)/C48,0) -> 1.0120482 | F48: =IFERROR(VLOOKUP(E48,FATORES!$B$72:$E$76,3),0) -> 0 | G48: =D48*F48 -> 0 | H48: =IF($E$8=2,G48*0.05,0) -> 0 | I48: =IF($E$8=3,G48*0.05,0) -> 0
...
