Workbook

Sheet FATORES
A2: VENDEDOR
A3: ESSENCIAIS | G3: MÓVEL | M3: SEGURO
D4: A | E4: B | G4: COMISSÃO | I4: 0 | J4: 0.79 | K4: 0.01 | M4: COMISSÃO | O4: 0 | P4: 0.79 | Q4: 0.01
D5: <50 | E5: <50 | I5: 0.8 | J5: 0.89 | K5: 0.05 | O5: 0.8 | P5: 0.89 | Q5: 0.03
A6: COMISSÃO | B6: 0 | C6: 0.7999 | D6: 0.005 | E6: 0.002 | I6: 0.9 | J6: 1000 | K6: 0.08 | O6: 0.9 | P6: 1000 | Q6: 0.05
B7: 0.8 | C7: 0.8999 | D7: 0.01 | E7: 0.004 | G7: PREMIAÇÃO ALTO DESEMPENHO | H7: INDIVIDUAL | I7: 1 | J7: 1.49 | K7: 0.15 | M7: PREMIAÇÃO ALTO DESEMPENHO | N7: INDIVIDUAL | O7: 1 | P7: 1.49 | Q7: 0.2
B8: 0.9 | C8: 10000 | D8: 0.015 | E8: 0.01 | I8: 1.5 | J8: 1000 | K8: 0.2 | O8: 1.5 | P8: 1000 | Q8: 0.25
A9: PREMIO ALTA PERFORMANCE | B9: 1 | C9: 1.49 | D9: 0.04 | E9: 0.015 | H9: LOJA | I9: 1 | J9: 1000 | K9: 0.1 | N9: LOJA | O9: 1 | P9: 1000 | Q9: 0.1
B10: 1.5 | C10: 10 | D10: 0.05 | E10: 0.02
A11: PREMIO LOJA | B11: 1 | C11: 10 | D11: 0.015 | E11: 0.01 | G11: FIXA | M11: SVA
G12: COMISSÃO | I12: 0 | J12: 0.79 | K12: 0.01 | M12: COMISSÃO | O12: VENDEU GANHOU | Q12: 0.01
A13: ELETRONICOS | I13: 0.8 | J13: 0.89 | K13: 0.05
D14: A | E14: B | I14: 0.9 | J14: 1000 | K14: 0.08
D15: >15 | E15: <15 | G15: PREMIAÇÃO ALTO DESEMPENHO | H15: INDIVIDUAL | I15: 1 | J15: 1.49 | K15: 0.15 | M15: PREMIAÇÃO ALTO DESEMPENHO | N15: INDIVIDUAL | O15: 1 | P15: 100000 | Q15: 0.01
A16: COMISSÃO | B16: 0 | C16: 0.7999 | D16: 0.001 | E16: 0.0005 | I16: 1.5 | J16: 1000 | K16: 0.2
B17: 0.8 | C17: 0.8999 | D17: 0.002 | E17: 0.001 | H17: LOJA | I17: 1 | J17: 1000 | K17: 0.15 | N17: LOJA | O17: 1 | P17: 100000 | Q17: 0.01
B18: 0.9 | C18: 10000 | D18: 0.003 | E18: 0.0015
A19: PREMIO ALTA PERFORMANCE | B19: 1 | C19: 1.49 | D19: 0.012 | E19: 0.006
B20: 1.5 | C20: 10 | D20: 0.014 | E20: 0.007
A21: PREMIO LOJA | B21: 1 | C21: 10 | D21: 0.005 | E21: 0.0025
A23: Smartphone
A25: COMISSÃO | B25: 0 | C25: 0.8999 | D25: 0.0005
B26: 0.9 | C26: 10000 | D26: 0.0015
A27: PREMIO ALTA PERFORMANCE | B27: 1 | C27: 10000 | D27: 0.002
A28: PREMIO LOJA | B28: 1 | C28: 10 | D28: 0.0025
A30: GERENTE
A31: ESSENCIAIS | G31: MÓVEL | M31: SEGURO
D32: A | E32: B | G32: COMISSÃO | I32: 0 | J32: 0.79 | K32: 0.005 | M32: COMISSÃO | O32: 0 | P32: 0.79 | Q32: 0.005
D33: <50 | E33: <50 | I33: 0.8 | J33: 0.89 | K33: 0.02 | O33: 0.8 | P33: 0.89 | Q33: 0.02
A34: COMISSÃO | B34: 0 | C34: 0.7999 | D34: 0.0005 | E34: 0.00025 | I34: 0.9 | J34: 1000 | K34: 0.04 | O34: 0.9 | P34: 1000 | Q34: 0.04
B35: 0.8 | C35: 0.8999 | D35: 0.001 | E35: 0.0005 | G35: PREMIAÇÃO ALTO DESEMPENHO | H35: INDIVIDUAL | I35: 1 | J35: 1.19 | K35: 0.08 | M35: PREMIAÇÃO ALTO DESEMPENHO | N35: INDIVIDUAL | O35: 1 | P35: 1.19 | Q35: 0.1
B36: 0.9 | C36: 10000 | D36: 0.0015 | E36: 0.00075 | I36: 1.2 | J36: 1000 | K36: 0.13 | O36: 1.2 | P36: 1000 | Q36: 0.15
A37: PREMIO ALTA PERFORMANCE | B37: 1 | C37: 1.49 | D37: 0.006 | E37: 0.003 | H37: CARTEIRA | I37: 1 | J37: 1000 | K37: 0.03 | N37: CARTEIRA | O37: 1 | P37: 1000 | Q37: 0.03
B38: 1.5 | C38: 10 | D38: 0.025 | E38: 0.01
A39: PREMIO CARTEIRA | B39: 1 | C39: 10 | D39: 0.008 | E39: 0.004 | G39: FIXA | M39: SVA
G40: COMISSÃO | I40: 0 | J40: 0.79 | K40: 0.005 | M40: COMISSÃO | O40: VENDEU GANHOU | Q40: 0.005
A41: ELETRONICOS | I41: 0.8 | J41: 0.89 | K41: 0.02
D42: A | E42: B | I42: 0.9 | J42: 1000 | K42: 0.04
D43: >15 | E43: <15 | G43: PREMIAÇÃO ALTO DESEMPENHO | H43: INDIVIDUAL | I43: 1 | J43: 1.19 | K43: 0.1 | M43: PREMIAÇÃO ALTO DESEMPENHO | N43: INDIVIDUAL | O43: 1 | P43: 100000 | Q43: 0.005
A44: COMISSÃO | B44: 0 | C44: 0.7999 | D44: =D16/2 -> 0.0005 | E44: =E16/2 -> 0.00025 | I44: 1.2 | J44: 1000 | K44: 0.15
...

Sheet REALIZADO
A1: CONSULTOR | B1: PDV | C1: AT_MOVEL | D1: META_MOVEL | E1: F_M_MOVEL | F1: AT_FIXA | G1: META_FIXA | H1: F_M_FIXA | I1: AT_SMARTPHONE | J1: META_SMARTPHONE | K1: F_M_SMARTPHONE | L1: AT_ACESSORIOS_A | M1: AT_ACESSORIOS_B | N1: META_ACESSORIO | O1: F_M_ACESSORIOS | P1: AT_ESSENCIAIS_A | Q1: AT_ESSENCIAIS_B | R1: META_ESSENCIAIS | S1: F_M_ESSENCIAIS | T1: AT_SEGUROS | U1: META_SEGUROS | V1: F_M_SEGUROS | W1: AT_SVA | X1: META_SVA | Y1: F_M_SVA | Z1: COORDENAÇÃO
A2: EVELYN MAVYE SILVEIRA | B2: ANCHIETA | C2: 44 | D2: 2200 | E2: 2156 | F2: 0 | G2: 0 | H2: 0 | I2: 2999 | J2: 38666.667 | K2: 35667.667 | L2: 0 | M2: 0 | N2: 4650 | O2: 4650 | P2: 129 | Q2: 79 | R2: 2283.3333 | S2: 2075.3333 | T2: 0 | U2: 275 | V2: 275 | W2: 20.9 | X2: 283.3333 | Y2: 262.4333 | Z2: =_xlfn.XLOOKUP(REALIZADO[[#This Row],[PDV]],PROJEÇÃO[PDV],PROJEÇÃO[COORDENAÇÃO]) -> ARIEL
A3: GABRIEL PINHEIRO BORGES | B3: ANCHIETA | C3: 118 | D3: 2200 | E3: 2082 | F3: 0 | G3: 0 | H3: 0 | I3: 3098 | J3: 38666.667 | K3: 35568.667 | L3: 0 | M3: 0 | N3: 4650 | O3: 4650 | P3: 158 | Q3: 99 | R3: 2283.3333 | S3: 2026.3333 | T3: 0 | U3: 275 | V3: 275 | W3: 20.9 | X3: 283.3333 | Y3: 262.4333 | Z3: =_xlfn.XLOOKUP(REALIZADO[[#This Row],[PDV]],PROJEÇÃO[PDV],PROJEÇÃO[COORDENAÇÃO]) -> ARIEL
A4: MILENA SILVA MARTINS | B4: ANCHIETA | C4: 315.01 | D4: 2200 | E4: 1884.99 | F4: 0 | G4: 0 | H4: 0 | I4: 2747 | J4: 38666.667 | K4: 35919.667 | L4: 0 | M4: 199 | N4: 4650 | O4: 4451 | P4: 356 | Q4: 198 | R4: 2283.3333 | S4: 1729.3333 | T4: 33.8 | U4: 275 | V4: 241.2 | W4: 77.6 | X4: 283.3333 | Y4: 205.7333 | Z4: =_xlfn.XLOOKUP(REALIZADO[[#This Row],[PDV]],PROJEÇÃO[PDV],PROJEÇÃO[COORDENAÇÃO]) -> ARIEL
A5: ALISSON PAULO SILVA | B5: BOM JESUS DO ITABAPOANA | C5: 480 | D5: 4333.3333 | E5: 3853.3333 | F5: 0 | G5: 0 | H5: 0 | I5: 7297 | J5: 30000 | K5: 22703 | L5: 0 | M5: 4137 | N5: 3566.6667 | O5: -570.3333 | P5: 802 | Q5: 455 | R5: 2850 | S5: 1593 | T5: 51.8 | U5: 333.3333 | V5: 281.5333 | W5: 45 | X5: 283.3333 | Y5: 238.3333 | Z5: =_xlfn.XLOOKUP(REALIZADO[[#This Row],[PDV]],PROJEÇÃO[PDV],PROJEÇÃO[COORDENAÇÃO]) -> ARIEL
A6: GIAN BATISTA BRANCO | B6: BOM JESUS DO ITABAPOANA | C6: 444.99 | D6: 4333.3333 | E6: 3888.3433 | F6: 0 | G6: 0 | H6: 0 | I6: 5048 | J6: 30000 | K6: 24952 | L6: 0 | M6: 1738 | N6: 3566.6667 | O6: 1828.6667 | P6: 178 | Q6: 208 | R6: 2850 | S6: 2464 | T6: 33.8 | U6: 333.3333 | V6: 299.5333 | W6: 25.9 | X6: 283.3333 | Y6: 257.4333 | Z6: =_xlfn.XLOOKUP(REALIZADO[[#This Row],[PDV]],PROJEÇÃO[PDV],PROJEÇÃO[COORDENAÇÃO]) -> ARIEL
A7: SHIRLEY SILVA MOREIRA | B7: BOM JESUS DO ITABAPOANA | C7: 445 | D7: 4333.3333 | E7: 3888.3333 | F7: 0 | G7: 0 | H7: 0 | I7: 11098 | J7: 30000 | K7: 18902 | L7: 0 | M7: 0 | N7: 3566.6667 | O7: 3566.6667 | P7: 89 | Q7: 505 | R7: 2850 | S7: 2256 | T7: 0 | U7: 333.3333 | V7: 333.3333 | W7: 0 | X7: 283.3333 | Y7: 283.3333 | Z7: =_xlfn.XLOOKUP(REALIZADO[[#This Row],[PDV]],PROJEÇÃO[PDV],PROJEÇÃO[COORDENAÇÃO]) -> ARIEL
A8: ALICE COSTALONGA COLLI | B8: CENTRO VILA VELHA | C8: 418.99 | D8: 2200 | E8: 1781.01 | F8: 20.01 | G8: 1275 | H8: 1254.99 | I8: 0 | J8: 33750 | K8: 33750 | L8: 0 | M8: 0 | N8: 4450 | O8: 4450 | P8: 0 | Q8: 0 | R8: 1700 | S8: 1700 | T8: 0 | U8: 195 | V8: 195 | W8: 137.7 | X8: 200 | Y8: 62.3 | Z8: =_xlfn.XLOOKUP(REALIZADO[[#This Row],[PDV]],PROJEÇÃO[PDV],PROJEÇÃO[COORDENAÇÃO]) -> LUIZ
A9: TAHINA PAHINS COELHO | B9: CENTRO VILA VELHA | C9: 187.99 | D9: 2200 | E9: 2012.01 | F9: 0 | G9: 1275 | H9: 1275 | I9: 0 | J9: 33750 | K9: 33750 | L9: 0 | M9: 0 | N9: 4450 | O9: 4450 | P9: 0 | Q9: 0 | R9: 1700 | S9: 1700 | T9: 69.9 | U9: 195 | V9: 125.1 | W9: 0 | X9: 200 | Y9: 200 | Z9: =_xlfn.XLOOKUP(REALIZADO[[#This Row],[PDV]],PROJEÇÃO[PDV],PROJEÇÃO[COORDENAÇÃO]) -> LUIZ
A10: BARBARA BORGES OLIVEIRA | B10: CENTRO VIX | C10: 309 | D10: 2066.6667 | E10: 1757.6667 | F10: 0 | G10: 1266.6667 | H10: 1266.6667 | I10: 3528 | J10: 23000 | K10: 19472 | L10: 209 | M10: 818 | N10: 2966.6667 | O10: 1939.6667 | P10: 138 | Q10: 0 | R10: 1666.6667 | S10: 1528.6667 | T10: 0 | U10: 230 | V10: 230 | W10: 0 | X10: 200 | Y10: 200 | Z10: =_xlfn.XLOOKUP(REALIZADO[[#This Row],[PDV]],PROJEÇÃO[PDV],PROJEÇÃO[COORDENAÇÃO]) -> LUIZ
A11: SAFYRA GOMES QUINTILIANO | B11: CENTRO VIX | C11: 0 | D11: 2066.6667 | E11: 2066.6667 | F11: 0 | G11: 1266.6667 | H11: 1266.6667 | I11: 0 | J11: 23000 | K11: 23000 | L11: 0 | M11: 0 | N11: 2966.6667 | O11: 2966.6667 | P11: 0 | Q11: 0 | R11: 1666.6667 | S11: 1666.6667 | T11: 0 | U11: 230 | V11: 230 | W11: 0 | X11: 200 | Y11: 200 | Z11: =_xlfn.XLOOKUP(REALIZADO[[#This Row],[PDV]],PROJEÇÃO[PDV],PROJEÇÃO[COORDENAÇÃO]) -> LUIZ
A12: RODRIGO ARAUJO BRAU | B12: CENTRO VIX | C12: 218 | D12: 2066.6667 | E12: 1848.6667 | F12: 85 | G12: 1266.6667 | H12: 1181.6667 | I12: 1699 | J12: 23000 | K12: 21301 | L12: 0 | M12: 0 | N12: 2966.6667 | O12: 2966.6667 | P12: 119 | Q12: 79 | R12: 1666.6667 | S12: 1468.6667 | T12: 0 | U12: 230 | V12: 230 | W12: 0 | X12: 200 | Y12: 200 | Z12: =_xlfn.XLOOKUP(REALIZADO[[#This Row],[PDV]],PROJEÇÃO[PDV],PROJEÇÃO[COORDENAÇÃO]) -> LUIZ
A13: BIANCA SALES SILVA | B13: GLÓRIA | C13: 353.99 | D13: 2530.303 | E13: 2176.313 | F13: 0 | G13: 1378.7879 | H13: 1378.7879 | I13: 0 | J13: 30303.03 | K13: 30303.03 | L13: 0 | M13: 0 | N13: 3863.6364 | O13: 3863.6364 | P13: 122.55 | Q13: 0 | R13: 1500 | S13: 1377.45 | T13: 0 | U13: 227.2727 | V13: 227.2727 | W13: 9.9 | X13: 151.5152 | Y13: 141.6152 | Z13: =_xlfn.XLOOKUP(REALIZADO[[#This Row],[PDV]],PROJEÇÃO[PDV],PROJEÇÃO[COORDENAÇÃO]) -> LUIZ
... A106: CARLOS EDUARDO DOS REIS SILVA | B106: SERRA SEDE | C106: 126 | D106: 0 | E106: -126 | F106: 0 | G106: 0 | H106: 0 | I106: 0 | J106: 0 | K106: 0 | L106: 0 | M106: 0 | N106: 0 | O106: 0 | P106: 0 | Q106: 0 | R106: 0 | S106: 0 | T106: 0 | U106: 0 | V106: 0 | W106: 0 | X106: 0 | Y106: 0 | Z106: =_xlfn.XLOOKUP(REALIZADO[[#This Row],[PDV]],PROJEÇÃO[PDV],PROJEÇÃO[COORDENAÇÃO]) -> THAYANDRA

Sheet PROJEÇÃO
A1: CONSULTOR | B1: PDV | C1: PROJ_MOVEL | D1: PROJ_FIXA | E1: PROJ_BL | F1: PROJ_APARELHO | G1: PROJ_ESSENCIAIS | H1: PROJ_ACESSORIOS | I1: PROJ_SEGURO | J1: PROJ_SVA | K1: PROJ_PÓS | L1: PROJ_CONTROLE | M1: PROJ_MOVEL_B2B | N1: PROJ_FIXA_B2B | O1: PROJ_ELETRO_A | P1: PROJ_ELETRO_B | Q1: PROJ_ESSEN_A | R1: PROJ_ESSEN_B | S1: PROJ_BL% | T1: COORDENAÇÃO
A2: EVELYN MAVYE SILVEIRA | B2: ANCHIETA | C2: 2030.8256 | D2: 0 | E2: 3 | F2: 24985 | G2: 1838.7778 | H2: 3479.1111 | I2: 187.2556 | J2: 532.5911 | K2: 0 | L2: 0 | M2: 0 | N2: 0 | O2: 0 | P2: 3479.1111 | Q2: 1211.7778 | R2: 627 | S2: 0 | T2: ARIEL
A3: GABRIEL PINHEIRO BORGES | B3: ANCHIETA | C3: 1218.0478 | D3: 0 | E3: 0 | F3: 19536.222 | G3: 2322.2222 | H3: 1220.2222 | I3: 193.5889 | J3: 54.6778 | K3: 0 | L3: 0 | M3: 0 | N3: 0 | O3: 0 | P3: 1220.2222 | Q3: 667.1111 | R3: 1655.1111 | S3: 0 | T3: ARIEL
A4: MILENA SILVA MARTINS | B4: ANCHIETA | C4: 1422.8678 | D4: 0 | E4: 0 | F4: 13606.111 | G4: 2402.4444 | H4: 1450.3333 | I4: 172.0556 | J4: 397.5222 | K4: 0 | L4: 0 | M4: 0 | N4: 0 | O4: 0 | P4: 1450.3333 | Q4: 1503.1111 | R4: 899.3333 | S4: 0 | T4: ARIEL
A5: ALISSON PAULO SILVA | B5: BOM JESUS DO ITABAPOANA | C5: 5607.0056 | D5: 0 | E5: 0 | F5: 35029.667 | G5: 6483.2222 | H5: 16538.444 | I5: 516.1667 | J5: 516.1456 | K5: 0 | L5: 0 | M5: 0 | N5: 0 | O5: 0 | P5: 16538.444 | Q5: 3783.1111 | R5: 2700.1111 | S5: 0 | T5: ARIEL
A6: GIAN BATISTA BRANCO | B6: BOM JESUS DO ITABAPOANA | C6: 3662.6933 | D6: 0 | E6: 0 | F6: 15824.889 | G6: 2778.2222 | H6: 7946.2222 | I6: 214.0667 | J6: 235.5789 | K6: 0 | L6: 0 | M6: 0 | N6: 0 | O6: 420.1111 | P6: 7526.1111 | Q6: 1503.1111 | R6: 1275.1111 | S6: 0 | T6: ARIEL
A7: SHIRLEY SILVA MOREIRA | B7: BOM JESUS DO ITABAPOANA | C7: 3192 | D7: 0 | E7: 0 | F7: 29547.111 | G7: 2968.2222 | H7: 7659.1111 | I7: 100.7 | J7: 84.4022 | K7: 0 | L7: 0 | M7: 0 | N7: 0 | O7: 0 | P7: 7659.1111 | Q7: 1002.7778 | R7: 1965.4444 | S7: 0 | T7: ARIEL
A8: ALICE COSTALONGA COLLI | B8: CENTRO VILA VELHA | C8: 3075.8678 | D8: 1129.4444 | E8: 9 | F8: 49176.222 | G8: 2368.6667 | H8: 4944.2222 | I8: 183.2444 | J8: 569.5778 | K8: 0 | L8: 0 | M8: 0 | N8: 0 | O8: 164.6667 | P8: 4779.5556 | Q8: 939.4444 | R8: 1429.2222 | S8: 0.6 | T8: LUIZ
A9: TAHINA PAHINS COELHO | B9: CENTRO VILA VELHA | C9: 2296.8678 | D9: 1709.9789 | E9: 13 | F9: 3903.4444 | G9: 1800.7778 | H9: 1506.4889 | I9: 147.5667 | J9: 358.2556 | K9: 0 | L9: 0 | M9: 0 | N9: 0 | O9: 0 | P9: 1506.4889 | Q9: 690.3333 | R9: 1110.4444 | S9: 0.86666667 | T9: LUIZ
A10: BARBARA BORGES OLIVEIRA | B10: CENTRO VIX | C10: 2007.6667 | D10: 939.4444 | E10: 9 | F10: 30347.222 | G10: 1275.1111 | H10: 3303.8889 | I10: 35.6778 | J10: 265.1556 | K10: 0 | L10: 0 | M10: 0 | N10: 0 | O10: 441.2222 | P10: 2862.6667 | Q10: 437 | R10: 838.1111 | S10: 0.6 | T10: LUIZ
A11: SAFYRA GOMES QUINTILIANO | B11: CENTRO VIX | C11: 798.0211 | D11: 612.2222 | E11: 7 | F11: 3270.1111 | G11: 145.6667 | H11: 0 | I11: 221.2444 | J11: 86.1333 | K11: 0 | L11: 0 | M11: 0 | N11: 0 | O11: 0 | P11: 0 | Q11: 145.6667 | R11: 0 | S11: 0.46666667 | T11: LUIZ
A12: RODRIGO ARAUJO BRAU | B12: CENTRO VIX | C12: 2645.2222 | D12: 1942.2011 | E12: 17 | F12: 50656.111 | G12: 3458 | H12: 483.4444 | I12: 147.5667 | J12: 214.7 | K12: 0 | L12: 0 | M12: 0 | N12: 0 | O12: 0 | P12: 483.4444 | Q12: 1591.7778 | R12: 1866.2222 | S12: 1.1333333 | T12: LUIZ
A13: BIANCA SALES SILVA | B13: GLÓRIA | C13: 2036.6944 | D13: 411.6667 | E13: 5 | F13: 5379.1111 | G13: 446.6056 | H13: 546.7778 | I13: 147.3556 | J13: 107.2444 | K13: 0 | L13: 0 | M13: 0 | N13: 0 | O13: 0 | P13: 546.7778 | Q13: 446.6056 | R13: 0 | S13: 0.26315789 | T13: LUIZ
... A106: CARLOS EDUARDO DOS REIS SILVA | B106: SERRA SEDE | C106: 498.2222 | D106: 485.5556 | E106: 3 | F106: 0 | G106: 0 | H106: 0 | I106: 0 | J106: 126.4556 | K106: 0 | L106: 0 | M106: 0 | N106: 0 | O106: 0 | P106: 0 | Q106: 0 | R106: 0 | S106: 0 | T106: THAYANDRA

Sheet CAPA
B2: SELECIONE A LOJA
B6: ANCHIETA | E6: CENTRO VV | H6: ITACIBA
B8: ICONHA | E8: CENTRO VIX | H8: JACARAIPE
B10: PIUMA | E10: GLÓRIA | H10: LARANJEIRAS
B12: BOM JESUS | E12: JARDIM CAMBURI | H12: MARCILIO DE NORONHA
B14: MIRACEMA | E14: MASTERPLACE | H14: MONTSERRAT
B16: QUISSAMA | E16: NORTE SUL | H16: PORTO CANOA
B18: SAO FIDELIS | H18: SERRA SEDE
B20: ST PADUA

Sheet ANCHIETA
B2: SIMULADOR GERENTE
B6: HUNTER | M6: PDV | P6: COORDENADOR | V6: 0 | W6: 2 | X6: 3
B7: MOVEL | C7: FIXA | D7: SMARTPHONE | E7: ELETRONICOS | F7: ESSESCIAIS | G7: SEGUROS | H7: SVA | M7: ANCHIETA | P7: ARIEL
B8: 0 | C8: 0 | D8: 0 | E8: 0 | F8: 0 | G8: 0 | H8: 0
B11: PROJEÇÃO
B12: INDIVIDUAL | K12: PDV
B13: PILAR | C13: PROJ PDV | F13: % - COMISSÃO | G13: % - PREMIAÇÃO ALTO DESEMP. INDIV. | H13: R$ - COMISSÃO | I13: R$ - PREMIAÇÃO ALTO DESEMP. INDIV. | J13: R$ - COMISSÃO + PREMIAÇÃO INDIV. | K13: PROJ CARTEIRA | N13: % - PREMIAÇÃO ALTO DESEMPENHO PDV | O13: R$ - PREMIAÇÃO ALTO DESEMPENHO PDV | P13: R$ - COMISSÃO + PREMIAÇÕES | Q13: HUNTER 2 | R13: HUNTER 3 | S13: 6/7 PPILARES | T13: GANHO TOTAL
C14: META | D14: ATINGIMENTO | K14: META | L14: ATINGIMENTO
B15: MÓVEL | C15: =SUMIFS(REALIZADO[META_MOVEL],REALIZADO[PDV],ANCHIETA!$M$7) -> 6600 | D15: =SUMIFS(PROJEÇÃO[PROJ_MOVEL],PROJEÇÃO[PDV],ANCHIETA!$M$7) -> 4671.7412 | E15: =IFERROR(D15/C15,0) -> 0.70783958 | F15: =VLOOKUP($E$15,FATORES!$I$32:$K$34,3) -> 0.005 | G15: =IFERROR(VLOOKUP($E$15,FATORES!$I$35:$K$36,3),0) -> 0 | H15: =D15*F15 -> 23.358706 | I15: =IF($P$7="ARIEL", IF(AND($E$15>=69.5%, AND($E$17>=69.5%, $E$18>=69.5%, $E$18>=69.5%, $E$20>=69.5%, $E$20>=69.5%, $E$22>=69.5%, $E$23>=69.5%)), D15*G15, 0), IF(AND($E$15>=69.5%, $E$16>=69.5%, $E$17>=69.5%, $E$18>=69.5%, $E$18>=69.5%, $E$20>=69.5%, $E$20>=69.5%, $E$22>=69.5%, $E$23>=69.5%), D15*G15, 0) ) -> 0 | J15: =H15+I15 -> 23.358706 | K15: =SUMIFS(REALIZADO[META_MOVEL],REALIZADO[COORDENAÇÃO],$P$7) -> 59730 | L15: =SUMIFS(PROJEÇÃO[PROJ_MOVEL],PROJEÇÃO[COORDENAÇÃO],$P$7) -> 52523.22 | M15: =IFERROR(L15/K15,0) -> 0.87934405 | N15: =IF($M$15>=FATORES!$I$37,FATORES!$K$37,0) -> 0 | O15: =IF(E15>=100%, IF($P$7="ARIEL", IF(AND($E$15>=69.5%,$E$17>=69.5%,$E$18>=69.5%,$E$20>=69.5%,$E$22>=69.5%,$E$23>=69.5%), D15*N15, 0 ), IF(AND($E$15>=69.5%,$E$16>=69.5%,$E$17>=69.5%,$E$18>=69.5%,$E$20>=69.5%,$E$22>=69.5%,$E$23>=69.5%), D15*N15, 0 ) ), 0) -> 0 | P15: =J15+O15 -> 23.358706 | Q15: =IF($B$8=2,P15*0.05,0) -> 0 | R15: =IF($B$8=3,P15*0.15,0) -> 0 | S15: 0.1 | T15: =SUM(P24:S24) -> 51.669129
B16: FIXA | C16: =SUMIFS(REALIZADO[META_FIXA],REALIZADO[PDV],ANCHIETA!$M$7) -> 0 | D16: =SUMIFS(PROJEÇÃO[PROJ_FIXA],PROJEÇÃO[PDV],ANCHIETA!$M$7) -> 0 | E16: =IFERROR(D16/C16,0) -> 0 | F16: =VLOOKUP($E$16,FATORES!$I$40:$K$42,3) -> 0.005 | G16: =IFERROR(VLOOKUP($E$16,FATORES!$I$43:$K$44,3),0) -> 0 | H16: =D16*F16 -> 0 | I16: =IF($P$7="ARIEL", IF(AND($E$15>=69.5%, AND($E$17>=69.5%, $E$18>=69.5%, $E$18>=69.5%, $E$20>=69.5%, $E$20>=69.5%, $E$22>=69.5%, $E$23>=69.5%)), D16*G16, 0), IF(AND($E$15>=69.5%, $E$16>=69.5%, $E$17>=69.5%, $E$18>=69.5%, $E$18>=69.5%, $E$20>=69.5%, $E$20>=69.5%, $E$22>=69.5%, $E$23>=69.5%), D16*G16, 0) ) -> 0 | J16: =H16+I16 -> 0 | K16: =SUMIFS(REALIZADO[META_FIXA],REALIZADO[COORDENAÇÃO],$P$7) -> 0 | L16: =SUMIFS(PROJEÇÃO[PROJ_FIXA],PROJEÇÃO[COORDENAÇÃO],$P$7) -> 0 | M16: =IFERROR(L16/K16,0) -> 0 | N16: =IF($M$16>=FATORES!$I$45,FATORES!$K$45,0) -> 0 | O16: =IF(E16>=100%, IF($P$7="ARIEL", IF(AND($E$15>=69.5%,$E$17>=69.5%,$E$18>=69.5%,$E$20>=69.5%,$E$22>=69.5%,$E$23>=69.5%), D16*N16, 0 ), IF(AND($E$15>=69.5%,$E$16>=69.5%,$E$17>=69.5%,$E$18>=69.5%,$E$20>=69.5%,$E$22>=69.5%,$E$23>=69.5%), D16*N16, 0 ) ), 0) -> 0 | P16: =J16+O16 -> 0 | Q16: =IF($C$8=2,P16*0.05,0) -> 0 | R16: =IF($C$8=3,P16*0.15,0) -> 0
B17: SMARTPHONES | C17: =SUMIFS(REALIZADO[META_SMARTPHONE],REALIZADO[PDV],ANCHIETA!$M$7) -> 116000 | D17: =SUMIFS(PROJEÇÃO[PROJ_APARELHO],PROJEÇÃO[PDV],ANCHIETA!$M$7) -> 58127.333 | E17: =IFERROR(D17/C17,0) -> 0.5010977 | F17: =VLOOKUP($E$17,FATORES!$B$53:$D$54,3) -> 0.0002 | G17: =IFERROR(VLOOKUP($E$17,FATORES!$B$55:$D$55,3),0) -> 0 | H17: =D17*F17 -> 11.625467 | I17: =IF($P$7="ARIEL", IF(AND($E$15>=69.5%, AND($E$17>=69.5%, $E$18>=69.5%, $E$18>=69.5%, $E$20>=69.5%, $E$20>=69.5%, $E$22>=69.5%, $E$23>=69.5%)), D17*G17, 0), IF(AND($E$15>=69.5%, $E$16>=69.5%, $E$17>=69.5%, $E$18>=69.5%, $E$18>=69.5%, $E$20>=69.5%, $E$20>=69.5%, $E$22>=69.5%, $E$23>=69.5%), D17*G17, 0) ) -> 0 | J17: =H17+I17 -> 11.625467 | K17: =SUMIFS(REALIZADO[META_SMARTPHONE],REALIZADO[COORDENAÇÃO],$P$7) -> 741000 | L17: =SUMIFS(PROJEÇÃO[PROJ_APARELHO],PROJEÇÃO[COORDENAÇÃO],$P$7) -> 619809.56 | M17: =IFERROR(L17/K17,0) -> 0.83645014 | N17: =IF($M$17>=FATORES!$B$56,FATORES!$D$56,0) -> 0 | O17: =IF(E17>=100%, IF($P$7="ARIEL", IF(AND($E$15>=69.5%,$E$17>=69.5%,$E$18>=69.5%,$E$20>=69.5%,$E$22>=69.5%,$E$23>=69.5%), D17*N17, 0 ), IF(AND($E$15>=69.5%,$E$16>=69.5%,$E$17>=69.5%,$E$18>=69.5%,$E$20>=69.5%,$E$22>=69.5%,$E$23>=69.5%), D17*N17, 0 ) ), 0) -> 0 | P17: =J17+O17 -> 11.625467 | Q17: =IF($D$8=2,P17*0.05,0) -> 0 | R17: =IF($D$8=3,P17*0.15,0) -> 0
B18: ELETRONICOS - A | C18: =SUMIFS(REALIZADO[META_ACESSORIO],REALIZADO[PDV],ANCHIETA!$M$7) -> 13950 | D18: =SUMIFS(PROJEÇÃO[PROJ_ELETRO_A],PROJEÇÃO[PDV],ANCHIETA!$M$7) -> 0 | E18: =IFERROR((D18+D19)/C18,0) -> 0.44083632 | F18: =VLOOKUP($E$18,FATORES!$B$44:$E$46,3) -> 0.0005 | G18: =IFERROR(VLOOKUP($E$18,FATORES!$B$47:$E$48,3),0) -> 0 | H18: =D18*F18 -> 0 | I18: =IF($P$7="ARIEL", IF(AND($E$15>=69.5%, AND($E$17>=69.5%, $E$18>=69.5%, $E$18>=69.5%, $E$20>=69.5%, $E$20>=69.5%, $E$22>=69.5%, $E$23>=69.5%)), D18*G18, 0), IF(AND($E$15>=69.5%, $E$16>=69.5%, $E$17>=69.5%, $E$18>=69.5%, $E$18>=69.5%, $E$20>=69.5%, $E$20>=69.5%, $E$22>=69.5%, $E$23>=69.5%), D18*G18, 0) ) -> 0 | J18: =H18+I18 -> 0 | K18: =SUMIFS(REALIZADO[META_ACESSORIO],REALIZADO[COORDENAÇÃO],$P$7) -> 84200 | L18: =SUMIFS(PROJEÇÃO[PROJ_ELETRO_A],PROJEÇÃO[COORDENAÇÃO],$P$7) -> 2058.3333 | M18: =IFERROR((L18+L19)/K18,0) -> 1.2364041 | N18: =IF($M$18>=FATORES!$B$49,FATORES!$D$49,0) -> 0.0025 | O18: =IF(E18>=100%, IF($P$7="ARIEL", IF(AND($E$15>=69.5%,$E$17>=69.5%,$E$18>=69.5%,$E$20>=69.5%,$E$22>=69.5%,$E$23>=69.5%), D18*N18, 0 ), IF(AND($E$15>=69.5%,$E$16>=69.5%,$E$17>=69.5%,$E$18>=69.5%,$E$20>=69.5%,$E$22>=69.5%,$E$23>=69.5%), D18*N18, 0 ) ), 0) -> 0 | P18: =J18+O18 -> 0 | Q18: =IF($E$8=2,P18*0.05,0) -> 0 | R18: =IF($E$8=3,P18*0.15,0) -> 0
B19: ELETRONICOS - B | D19: =SUMIFS(PROJEÇÃO[PROJ_ELETRO_B],PROJEÇÃO[PDV],ANCHIETA!$M$7) -> 6149.6666 | F19: =VLOOKUP($E$18,FATORES!$B$44:$E$46,4) -> 0.00025 | G19: =IFERROR(VLOOKUP($E$18,FATORES!$B$47:$E$48,4),0) -> 0 | H19: =D19*F19 -> 1.5374167 | I19: =IF($P$7="ARIEL", IF(AND($E$15>=69.5%, AND($E$17>=69.5%, $E$18>=69.5%, $E$18>=69.5%, $E$20>=69.5%, $E$20>=69.5%, $E$22>=69.5%, $E$23>=69.5%)), D19*G19, 0), IF(AND($E$15>=69.5%, $E$16>=69.5%, $E$17>=69.5%, $E$18>=69.5%, $E$18>=69.5%, $E$20>=69.5%, $E$20>=69.5%, $E$22>=69.5%, $E$23>=69.5%), D19*G19, 0) ) -> 0 | J19: =H19+I19 -> 1.5374167 | L19: =SUMIFS(PROJEÇÃO[PROJ_ELETRO_B],PROJEÇÃO[COORDENAÇÃO],$P$7) -> 102046.89 | N19: =IF($M$18>=FATORES!$B$49,FATORES!$E$49,0) -> 0.00125 | O19: =IF(E19>=100%, IF($P$7="ARIEL", IF(AND($E$15>=69.5%,$E$17>=69.5%,$E$18>=69.5%,$E$20>=69.5%,$E$22>=69.5%,$E$23>=69.5%), D19*N19, 0 ), IF(AND($E$15>=69.5%,$E$16>=69.5%,$E$17>=69.5%,$E$18>=69.5%,$E$20>=69.5%,$E$22>=69.5%,$E$23>=69.5%), D19*N19, 0 ) ), 0) -> 0 | P19: =J19+O19 -> 1.5374167 | Q19: =IF($E$8=2,P19*0.05,0) -> 0 | R19: =IF($E$8=3,P19*0.15,0) -> 0
B20: ESSENCIAIS - A | C20: =SUMIFS(REALIZADO[META_ESSENCIAIS],REALIZADO[PDV],ANCHIETA!$M$7) -> 6849.9999 | D20: =SUMIFS(PROJEÇÃO[PROJ_ESSEN_A],PROJEÇÃO[PDV],ANCHIETA!$M$7) -> 3382 | E20: =IFERROR((D20+D21)/C20,0) -> 0.95816708 | F20: =VLOOKUP($E$20,FATORES!$B$34:$E$36,3) -> 0.0015 | G20: =IFERROR(VLOOKUP($E$20,FATORES!$B$37:$E$38,3),0) -> 0 | H20: =D20*F20 -> 5.073 | I20: =IF($P$7="ARIEL", IF(AND($E$15>=69.5%, AND($E$17>=69.5%, $E$18>=69.5%, $E$18>=69.5%, $E$20>=69.5%, $E$20>=69.5%, $E$22>=69.5%, $E$23>=69.5%)), D20*G20, 0), IF(AND($E$15>=69.5%, $E$16>=69.5%, $E$17>=69.5%, $E$18>=69.5%, $E$18>=69.5%, $E$20>=69.5%, $E$20>=69.5%, $E$22>=69.5%, $E$23>=69.5%), D20*G20, 0) ) -> 0 | J20: =H20+I20 -> 5.073 | K20: =SUMIFS(REALIZADO[META_ESSENCIAIS],REALIZADO[COORDENAÇÃO],$P$7) -> 58600 | L20: =SUMIFS(PROJEÇÃO[PROJ_ESSEN_A],PROJEÇÃO[COORDENAÇÃO],$P$7) -> 30216.333 | M20: =IFERROR((L20+L21)/K20,0) -> 1.0940311 | N20: =IF($M$20>=FATORES!$B$39,FATORES!$D$39,0) -> 0.008 | O20: =IF(E20>=100%, IF($P$7="ARIEL", IF(AND($E$15>=69.5%,$E$17>=69.5%,$E$18>=69.5%,$E$20>=69.5%,$E$22>=69.5%,$E$23>=69.5%), D20*N20, 0 ), IF(AND($E$15>=69.5%,$E$16>=69.5%,$E$17>=69.5%,$E$18>=69.5%,$E$20>=69.5%,$E$22>=69.5%,$E$23>=69.5%), D20*N20, 0 ) ), 0) -> 0 | P20: =J20+O20 -> 5.073 | Q20: =IF($F$8=2,P20*0.05,0) -> 0 | R20: =IF($F$8=3,P20*0.15,0) -> 0
B21: ESSENCIAIS - B | D21: =SUMIFS(PROJEÇÃO[PROJ_ESSEN_B],PROJEÇÃO[PDV],ANCHIETA!$M$7) -> 3181.4444 | F21: =VLOOKUP($E$20,FATORES!$B$34:$E$36,4) -> 0.00075 | G21: =IFERROR(VLOOKUP($E$20,FATORES!$B$37:$E$38,4),0) -> 0 | H21: =D21*F21 -> 2.3860833 | I21: =IF($P$7="ARIEL", IF(AND($E$15>=69.5%, AND($E$17>=69.5%, $E$18>=69.5%, $E$18>=69.5%, $E$20>=69.5%, $E$20>=69.5%, $E$22>=69.5%, $E$23>=69.5%)), D21*G21, 0), IF(AND($E$15>=69.5%, $E$16>=69.5%, $E$17>=69.5%, $E$18>=69.5%, $E$18>=69.5%, $E$20>=69.5%, $E$20>=69.5%, $E$22>=69.5%, $E$23>=69.5%), D21*G21, 0) ) -> 0 | J21: =H21+I21 -> 2.3860833 | L21: =SUMIFS(PROJEÇÃO[PROJ_ESSEN_B],PROJEÇÃO[COORDENAÇÃO],$P$7) -> 33893.889 | N21: =IF($M$20>=FATORES!$B$39,FATORES!$E$39,0) -> 0.004 | O21: =IF(E21>=100%, IF($P$7="ARIEL", IF(AND($E$15>=69.5%,$E$17>=69.5%,$E$18>=69.5%,$E$20>=69.5%,$E$22>=69.5%,$E$23>=69.5%), D21*N21, 0 ), IF(AND($E$15>=69.5%,$E$16>=69.5%,$E$17>=69.5%,$E$18>=69.5%,$E$20>=69.5%,$E$22>=69.5%,$E$23>=69.5%), D21*N21, 0 ) ), 0) -> 0 | P21: =J21+O21 -> 2.3860833 | Q21: =IF($F$8=2,P21*0.05,0) -> 0 | R21: =IF($F$8=3,P21*0.15,0) -> 0
B22: SEGUROS | C22: =SUMIFS(REALIZADO[META_SEGUROS],REALIZADO[PDV],ANCHIETA!$M$7) -> 825 | D22: =SUMIFS(PROJEÇÃO[PROJ_SEGURO],PROJEÇÃO[PDV],ANCHIETA!$M$7) -> 552.9001 | E22: =IFERROR(D22/C22,0) -> 0.67018194 | F22: =VLOOKUP($E$22,FATORES!$O$32:$Q$34,3) -> 0.005 | G22: =IFERROR(VLOOKUP($E$22,FATORES!$O$35:$Q$36,3),0) -> 0 | H22: =D22*F22 -> 2.7645005 | I22: =IF($P$7="ARIEL", IF(AND($E$15>=69.5%, AND($E$17>=69.5%, $E$18>=69.5%, $E$18>=69.5%, $E$20>=69.5%, $E$20>=69.5%, $E$22>=69.5%, $E$23>=69.5%)), D22*G22, 0), IF(AND($E$15>=69.5%, $E$16>=69.5%, $E$17>=69.5%, $E$18>=69.5%, $E$18>=69.5%, $E$20>=69.5%, $E$20>=69.5%, $E$22>=69.5%, $E$23>=69.5%), D22*G22, 0) ) -> 0 | J22: =H22+I22 -> 2.7645005 | K22: =SUMIFS(REALIZADO[META_SEGUROS],REALIZADO[COORDENAÇÃO],$P$7) -> 5665 | L22: =SUMIFS(PROJEÇÃO[PROJ_SEGURO],PROJEÇÃO[COORDENAÇÃO],$P$7) -> 5467.5669 | M22: =IFERROR(L22/K22,0) -> 0.96514861 | N22: =IF($M$22>=FATORES!$O$37,FATORES!$Q$37,0) -> 0 | O22: =IF(E22>=100%, IF($P$7="ARIEL", IF(AND($E$15>=69.5%,$E$17>=69.5%,$E$18>=69.5%,$E$20>=69.5%,$E$22>=69.5%,$E$23>=69.5%), D22*N22, 0 ), IF(AND($E$15>=69.5%,$E$16>=69.5%,$E$17>=69.5%,$E$18>=69.5%,$E$20>=69.5%,$E$22>=69.5%,$E$23>=69.5%), D22*N22, 0 ) ), 0) -> 0 | P22: =J22+O22 -> 2.7645005 | Q22: =IF($G$8=2,P22*0.05,0) -> 0 | R22: =IF($G$8=3,P22*0.15,0) -> 0
B23: SVA | C23: =SUMIFS(REALIZADO[META_SVA],REALIZADO[PDV],ANCHIETA!$M$7) -> 849.9999 | D23: =SUMIFS(PROJEÇÃO[PROJ_SVA],PROJEÇÃO[PDV],ANCHIETA!$M$7) -> 984.7911 | E23: =IFERROR(D23/C23,0) -> 1.1585779 | F23: =IF($E$23>=0,FATORES!$Q$40) -> 0.005 | G23: =IFERROR(VLOOKUP($E$23,FATORES!$O$43:$Q$44,3),0) -> 0.005 | H23: =D23*F23 -> 4.9239555 | I23: =IF($P$7="ARIEL", IF(AND($E$15>=69.5%, AND($E$17>=69.5%, $E$18>=69.5%, $E$18>=69.5%, $E$20>=69.5%, $E$20>=69.5%, $E$22>=69.5%, $E$23>=69.5%)), D23*G23, 0), IF(AND($E$15>=69.5%, $E$16>=69.5%, $E$17>=69.5%, $E$18>=69.5%, $E$18>=69.5%, $E$20>=69.5%, $E$20>=69.5%, $E$22>=69.5%, $E$23>=69.5%), D23*G23, 0) ) -> 0 | J23: =H23+I23 -> 4.9239555 | K23: =SUMIFS(REALIZADO[META_SVA],REALIZADO[COORDENAÇÃO],$P$7) -> 5384.9998 | L23: =SUMIFS(PROJEÇÃO[PROJ_SVA],PROJEÇÃO[COORDENAÇÃO],$P$7) -> 5513.6099 | M23: =IFERROR(L23/K23,0) -> 1.023883 | N23: =IF($M$23>=FATORES!$O$45,FATORES!$Q$45,0) -> 0.005 | O23: =IF(E23>=100%, IF($P$7="ARIEL", IF(AND($E$15>=69.5%,$E$17>=69.5%,$E$18>=69.5%,$E$20>=69.5%,$E$22>=69.5%,$E$23>=69.5%), D23*N23, 0 ), IF(AND($E$15>=69.5%,$E$16>=69.5%,$E$17>=69.5%,$E$18>=69.5%,$E$20>=69.5%,$E$22>=69.5%,$E$23>=69.5%), D23*N23, 0 ) ), 0) -> 0 | P23: =J23+O23 -> 4.9239555 | Q23: =IF($H$8=2,P23*0.05,0) -> 0 | R23: =IF($H$8=3,P23*0.15,0) -> 0
P24: =SUM(P15:P23) -> 51.669129 | Q24: =SUM(Q15:Q23) -> 0 | R24: =SUM(R15:R23) -> 0 | S24: =IF($P$7="ARIEL",IF(MIN(E15,E17,E18,E19,E20,E22,E23)>=100%,SUM(P24:R24)*S15,""),IF(MIN(E15:E23)>=100%,SUM(P24:R24)*S15,""))
B26: REALIZADO
B27: INDIVIDUAL | K27: PDV
B28: PILAR | C28: REAL PDV | F28: % - COMISSÃO | G28: % - PREMIAÇÃO ALTO DESEMP. INDIV. | H28: R$ - COMISSÃO | I28: R$ - PREMIAÇÃO ALTO DESEMP. INDIV. | J28: R$ - COMISSÃO + PREMIAÇÃO INDIV. | K28: REAL CARTEIRA | N28: % - PREMIAÇÃO ALTO DESEMPENHO PDV | O28: R$ - PREMIAÇÃO ALTO DESEMPENHO PDV | P28: R$ - COMISSÃO + PREMIAÇÕES | Q28: HUNTER 2 | R28: HUNTER 3 | S28: 6/7 PPILARES | T28: GANHO TOTAL
C29: META | D29: ATINGIMENTO | K29: META | L29: ATINGIMENTO
B30: MÓVEL | C30: =SUMIFS(REALIZADO[META_MOVEL],REALIZADO[PDV],ANCHIETA!$M$7) -> 6600 | D30: =SUMIFS(REALIZADO[AT_MOVEL],REALIZADO[PDV],ANCHIETA!$M$7) -> 477.01 | E30: =IFERROR(D30/C30,0) -> 0.072274242 | F30: =VLOOKUP($E$30,FATORES!$I$32:$K$34,3) -> 0.005 | G30: =IFERROR(VLOOKUP($E$30,FATORES!$I$35:$K$36,3),0) -> 0 | H30: =D30*F30 -> 2.38505 | I30: =IF($P$7="ARIEL", IF(AND($E$30>=69.5%, AND($E$32>=69.5%, $E$33>=69.5%, $E$33>=69.5%, $E$35>=69.5%, $E$35>=69.5%, $E$37>=69.5%, $E$38>=69.5%)), D30*G30, 0), IF(AND($E$30>=69.5%, $E$31>=69.5%, $E$32>=69.5%, $E$33>=69.5%, $E$33>=69.5%, $E$35>=69.5%, $E$35>=69.5%, $E$37>=69.5%, $E$38>=69.5%), D30*G30, 0) ) -> 0 | J30: =H30+I30 -> 2.38505 | K30: =SUMIFS(REALIZADO[META_MOVEL],REALIZADO[COORDENAÇÃO],$P$7) -> 59730 | L30: =SUMIFS(REALIZADO[AT_MOVEL],REALIZADO[COORDENAÇÃO],$P$7) -> 5335.72 | M30: =IFERROR(L30/K30,0) -> 0.089330655 | N30: =IF($M$30>=FATORES!$I$37,FATORES!$K$37,0) -> 0 | O30: =IF(E30>=100%, IF($P$7="ARIEL", IF(AND($E$30>=69.5%,$E$32>=69.5%,$E$33>=69.5%,$E$35>=69.5%,$E$37>=69.5%,$E$38>=69.5%), D30*N30, 0), IF(AND($E$30>=69.5%,$E$31>=69.5%,$E$32>=69.5%,$E$33>=69.5%,$E$35>=69.5%,$E$37>=69.5%,$E$38>=69.5%), D30*N30, 0) ),0) -> 0 | P30: =J30+O30 -> 2.38505 | Q30: =IF($B$8=2,P30*0.05,0) -> 0 | R30: =IF($B$8=3,P30*0.15,0) -> 0 | S30: 0.1 | T30: =SUM(P39:S39) -> 5.3851
B31: FIXA | C31: =SUMIFS(REALIZADO[META_FIXA],REALIZADO[PDV],ANCHIETA!$M$7) -> 0 | D31: =SUMIFS(REALIZADO[AT_FIXA],REALIZADO[PDV],ANCHIETA!$M$7) -> 0 | E31: =IFERROR(D31/C31,0) -> 0 | F31: =VLOOKUP($E$31,FATORES!$I$40:$K$42,3) -> 0.005 | G31: =IFERROR(VLOOKUP($E$31,FATORES!$I$43:$K$44,3),0) -> 0 | H31: =D31*F31 -> 0 | I31: =IF($P$7="ARIEL", IF(AND($E$30>=69.5%, AND($E$32>=69.5%, $E$33>=69.5%, $E$33>=69.5%, $E$35>=69.5%, $E$35>=69.5%, $E$37>=69.5%, $E$38>=69.5%)), D31*G31, 0), IF(AND($E$30>=69.5%, $E$31>=69.5%, $E$32>=69.5%, $E$33>=69.5%, $E$33>=69.5%, $E$35>=69.5%, $E$35>=69.5%, $E$37>=69.5%, $E$38>=69.5%), D31*G31, 0) ) -> 0 | J31: =H31+I31 -> 0 | K31: =SUMIFS(REALIZADO[META_FIXA],REALIZADO[COORDENAÇÃO],$P$7) -> 0 | L31: =SUMIFS(REALIZADO[AT_FIXA],REALIZADO[COORDENAÇÃO],$P$7) -> 0 | M31: =IFERROR(L31/K31,0) -> 0 | N31: =IF($M$31>=FATORES!$I$45,FATORES!$K$45,0) -> 0 | O31: =IF(E31>=100%, IF($P$7="ARIEL", IF(AND($E$30>=69.5%,$E$32>=69.5%,$E$33>=69.5%,$E$35>=69.5%,$E$37>=69.5%,$E$38>=69.5%), D31*N31, 0), IF(AND($E$30>=69.5%,$E$31>=69.5%,$E$32>=69.5%,$E$33>=69.5%,$E$35>=69.5%,$E$37>=69.5%,$E$38>=69.5%), D31*N31, 0) ),0) -> 0 | P31: =J31+O31 -> 0 | Q31: =IF($C$8=2,P31*0.05,0) -> 0 | R31: =IF($C$8=3,P31*0.15,0) -> 0
B32: SMARTPHONES | C32: =SUMIFS(REALIZADO[META_SMARTPHONE],REALIZADO[PDV],ANCHIETA!$M$7) -> 116000 | D32: =SUMIFS(REALIZADO[AT_SMARTPHONE],REALIZADO[PDV],ANCHIETA!$M$7) -> 8844 | E32: =IFERROR(D32/C32,0) -> 0.076241379 | F32: =VLOOKUP($E$32,FATORES!$B$53:$D$54,3) -> 0.0002 | G32: =IFERROR(VLOOKUP($E$32,FATORES!$B$55:$D$55,3),0) -> 0 | H32: =D32*F32 -> 1.7688 | I32: =IF($P$7="ARIEL", IF(AND($E$30>=69.5%, AND($E$32>=69.5%, $E$33>=69.5%, $E$33>=69.5%, $E$35>=69.5%, $E$35>=69.5%, $E$37>=69.5%, $E$38>=69.5%)), D32*G32, 0), IF(AND($E$30>=69.5%, $E$31>=69.5%, $E$32>=69.5%, $E$33>=69.5%, $E$33>=69.5%, $E$35>=69.5%, $E$35>=69.5%, $E$37>=69.5%, $E$38>=69.5%), D32*G32, 0) ) -> 0 | J32: =H32+I32 -> 1.7688 | K32: =SUMIFS(REALIZADO[META_SMARTPHONE],REALIZADO[COORDENAÇÃO],$P$7) -> 741000 | L32: =SUMIFS(REALIZADO[AT_SMARTPHONE],REALIZADO[COORDENAÇÃO],$P$7) -> 81442 | M32: =IFERROR(L32/K32,0) -> 0.10990823 | N32: =IF($M$32>=FATORES!$B$56,FATORES!$D$56,0) -> 0 | O32: =IF(E32>=100%, IF($P$7="ARIEL", IF(AND($E$30>=69.5%,$E$32>=69.5%,$E$33>=69.5%,$E$35>=69.5%,$E$37>=69.5%,$E$38>=69.5%), D32*N32, 0), IF(AND($E$30>=69.5%,$E$31>=69.5%,$E$32>=69.5%,$E$33>=69.5%,$E$35>=69.5%,$E$37>=69.5%,$E$38>=69.5%), D32*N32, 0) ),0) -> 0 | P32: =J32+O32 -> 1.7688 | Q32: =IF($D$8=2,P32*0.05,0) -> 0 | R32: =IF($D$8=3,P32*0.15,0) -> 0
B33: ELETRONICOS - A | C33: =SUMIFS(REALIZADO[META_ACESSORIO],REALIZADO[PDV],ANCHIETA!$M$7) -> 13950 | D33: =SUMIFS(REALIZADO[AT_ACESSORIOS_A],REALIZADO[PDV],ANCHIETA!$M$7) -> 0 | E33: =IFERROR((D33+D34)/C33,0) -> 0.014265233 | F33: =VLOOKUP($E$33,FATORES!$B$44:$E$46,3) -> 0.0005 | G33: =IFERROR(VLOOKUP($E$33,FATORES!$B$47:$E$48,3),0) -> 0 | H33: =D33*F33 -> 0 | I33: =IF($P$7="ARIEL", IF(AND($E$30>=69.5%, AND($E$32>=69.5%, $E$33>=69.5%, $E$33>=69.5%, $E$35>=69.5%, $E$35>=69.5%, $E$37>=69.5%, $E$38>=69.5%)), D33*G33, 0), IF(AND($E$30>=69.5%, $E$31>=69.5%, $E$32>=69.5%, $E$33>=69.5%, $E$33>=69.5%, $E$35>=69.5%, $E$35>=69.5%, $E$37>=69.5%, $E$38>=69.5%), D33*G33, 0) ) -> 0 | J33: =H33+I33 -> 0 | K33: =SUMIFS(REALIZADO[META_ACESSORIO],REALIZADO[COORDENAÇÃO],$P$7) -> 84200 | L33: =SUMIFS(REALIZADO[AT_ACESSORIOS_A],REALIZADO[COORDENAÇÃO],$P$7) -> 0 | M33: =IFERROR((L33+L34)/K33,0) -> 0.13485748 | N33: =IF($M$33>=FATORES!$B$49,FATORES!$D$49,0) -> 0 | O33: =IF(E33>=100%, IF($P$7="ARIEL", IF(AND($E$30>=69.5%,$E$32>=69.5%,$E$33>=69.5%,$E$35>=69.5%,$E$37>=69.5%,$E$38>=69.5%), D33*N33, 0), IF(AND($E$30>=69.5%,$E$31>=69.5%,$E$32>=69.5%,$E$33>=69.5%,$E$35>=69.5%,$E$37>=69.5%,$E$38>=69.5%), D33*N33, 0) ),0) -> 0 | P33: =J33+O33 -> 0 | Q33: =IF($E$8=2,P33*0.05,0) -> 0 | R33: =IF($E$8=3,P33*0.15,0) -> 0
B34: ELETRONICOS - B | D34: =SUMIFS(REALIZADO[AT_ACESSORIOS_B],REALIZADO[PDV],ANCHIETA!$M$7) -> 199 | F34: =VLOOKUP($E$33,FATORES!$B$44:$E$46,4) -> 0.00025 | G34: =IFERROR(VLOOKUP($E$33,FATORES!$B$47:$E$48,4),0) -> 0 | H34: =D34*F34 -> 0.04975 | I34: =IF($P$7="ARIEL", IF(AND($E$30>=69.5%, AND($E$32>=69.5%, $E$33>=69.5%, $E$33>=69.5%, $E$35>=69.5%, $E$35>=69.5%, $E$37>=69.5%, $E$38>=69.5%)), D34*G34, 0), IF(AND($E$30>=69.5%, $E$31>=69.5%, $E$32>=69.5%, $E$33>=69.5%, $E$33>=69.5%, $E$35>=69.5%, $E$35>=69.5%, $E$37>=69.5%, $E$38>=69.5%), D34*G34, 0) ) -> 0 | J34: =H34+I34 -> 0.04975 | L34: =SUMIFS(REALIZADO[AT_ACESSORIOS_B],REALIZADO[COORDENAÇÃO],$P$7) -> 11355 | N34: =IF($M$33>=FATORES!$B$49,FATORES!$E$49,0) -> 0 | O34: =IF(E34>=100%, IF($P$7="ARIEL", IF(AND($E$30>=69.5%,$E$32>=69.5%,$E$33>=69.5%,$E$35>=69.5%,$E$37>=69.5%,$E$38>=69.5%), D34*N34, 0), IF(AND($E$30>=69.5%,$E$31>=69.5%,$E$32>=69.5%,$E$33>=69.5%,$E$35>=69.5%,$E$37>=69.5%,$E$38>=69.5%), D34*N34, 0) ),0) -> 0 | P34: =J34+O34 -> 0.04975 | Q34: =IF($E$8=2,P34*0.05,0) -> 0 | R34: =IF($E$8=3,P34*0.15,0) -> 0
B35: ESSENCIAIS - A | C35: =SUMIFS(REALIZADO[META_ESSENCIAIS],REALIZADO[PDV],ANCHIETA!$M$7) -> 6849.9999 | D35: =SUMIFS(REALIZADO[AT_ESSENCIAIS_A],REALIZADO[PDV],ANCHIETA!$M$7) -> 643 | E35: =IFERROR((D35+D36)/C35,0) -> 0.14875913 | F35: =VLOOKUP($E$35,FATORES!$B$34:$E$36,3) -> 0.0005 | G35: =IFERROR(VLOOKUP($E$35,FATORES!$B$37:$E$38,3),0) -> 0 | H35: =D35*F35 -> 0.3215 | I35: =IF($P$7="ARIEL", IF(AND($E$30>=69.5%, AND($E$32>=69.5%, $E$33>=69.5%, $E$33>=69.5%, $E$35>=69.5%, $E$35>=69.5%, $E$37>=69.5%, $E$38>=69.5%)), D35*G35, 0), IF(AND($E$30>=69.5%, $E$31>=69.5%, $E$32>=69.5%, $E$33>=69.5%, $E$33>=69.5%, $E$35>=69.5%, $E$35>=69.5%, $E$37>=69.5%, $E$38>=69.5%), D35*G35, 0) ) -> 0 | J35: =H35+I35 -> 0.3215 | K35: =SUMIFS(REALIZADO[META_ESSENCIAIS],REALIZADO[COORDENAÇÃO],$P$7) -> 58600 | L35: =SUMIFS(REALIZADO[AT_ESSENCIAIS_A],REALIZADO[COORDENAÇÃO],$P$7) -> 4117 | M35: =IFERROR((L35+L36)/K35,0) -> 0.14191126 | N35: =IF($M$35>=FATORES!$B$39,FATORES!$D$39,0) -> 0 | O35: =IF(E35>=100%, IF($P$7="ARIEL", IF(AND($E$30>=69.5%,$E$32>=69.5%,$E$33>=69.5%,$E$35>=69.5%,$E$37>=69.5%,$E$38>=69.5%), D35*N35, 0), IF(AND($E$30>=69.5%,$E$31>=69.5%,$E$32>=69.5%,$E$33>=69.5%,$E$35>=69.5%,$E$37>=69.5%,$E$38>=69.5%), D35*N35, 0) ),0) -> 0 | P35: =J35+O35 -> 0.3215 | Q35: =IF($F$8=2,P35*0.05,0) -> 0 | R35: =IF($F$8=3,P35*0.15,0) -> 0
B36: ESSENCIAIS - B | D36: =SUMIFS(REALIZADO[AT_ESSENCIAIS_B],REALIZADO[PDV],ANCHIETA!$M$7) -> 376 | F36: =VLOOKUP($E$35,FATORES!$B$34:$E$36,4) -> 0.00025 | G36: =IFERROR(VLOOKUP($E$35,FATORES!$B$37:$E$38,4),0) -> 0 | H36: =D36*F36 -> 0.094 | I36: =IF($P$7="ARIEL", IF(AND($E$30>=69.5%, AND($E$32>=69.5%, $E$33>=69.5%, $E$33>=69.5%, $E$35>=69.5%, $E$35>=69.5%, $E$37>=69.5%, $E$38>=69.5%)), D36*G36, 0), IF(AND($E$30>=69.5%, $E$31>=69.5%, $E$32>=69.5%, $E$33>=69.5%, $E$33>=69.5%, $E$35>=69.5%, $E$35>=69.5%, $E$37>=69.5%, $E$38>=69.5%), D36*G36, 0) ) -> 0 | J36: =H36+I36 -> 0.094 | L36: =SUMIFS(REALIZADO[AT_ESSENCIAIS_B],REALIZADO[COORDENAÇÃO],$P$7) -> 4199 | N36: =IF($M$35>=FATORES!$B$39,FATORES!$E$39,0) -> 0 | O36: =IF(E36>=100%, IF($P$7="ARIEL", IF(AND($E$30>=69.5%,$E$32>=69.5%,$E$33>=69.5%,$E$35>=69.5%,$E$37>=69.5%,$E$38>=69.5%), D36*N36, 0), IF(AND($E$30>=69.5%,$E$31>=69.5%,$E$32>=69.5%,$E$33>=69.5%,$E$35>=69.5%,$E$37>=69.5%,$E$38>=69.5%), D36*N36, 0) ),0) -> 0 | P36: =J36+O36 -> 0.094 | Q36: =IF($F$8=2,P36*0.05,0) -> 0 | R36: =IF($F$8=3,P36*0.15,0) -> 0
B37: SEGUROS | C37: =SUMIFS(REALIZADO[META_SEGUROS],REALIZADO[PDV],ANCHIETA!$M$7) -> 825 | D37: =SUMIFS(REALIZADO[AT_SEGUROS],REALIZADO[PDV],ANCHIETA!$M$7) -> 33.8 | E37: =IFERROR(D37/C37,0) -> 0.040969697 | F37: =VLOOKUP($E$37,FATORES!$O$32:$Q$34,3) -> 0.005 | G37: =IFERROR(VLOOKUP($E$37,FATORES!$O$35:$Q$36,3),0) -> 0 | H37: =D37*F37 -> 0.169 | I37: =IF($P$7="ARIEL", IF(AND($E$30>=69.5%, AND($E$32>=69.5%, $E$33>=69.5%, $E$33>=69.5%, $E$35>=69.5%, $E$35>=69.5%, $E$37>=69.5%, $E$38>=69.5%)), D37*G37, 0), IF(AND($E$30>=69.5%, $E$31>=69.5%, $E$32>=69.5%, $E$33>=69.5%, $E$33>=69.5%, $E$35>=69.5%, $E$35>=69.5%, $E$37>=69.5%, $E$38>=69.5%), D37*G37, 0) ) -> 0 | J37: =H37+I37 -> 0.169 | K37: =SUMIFS(REALIZADO[META_SEGUROS],REALIZADO[COORDENAÇÃO],$P$7) -> 5665 | L37: =SUMIFS(REALIZADO[AT_SEGUROS],REALIZADO[COORDENAÇÃO],$P$7) -> 420.2 | M37: =IFERROR(L37/K37,0) -> 0.074174757 | N37: =IF($M$37>=FATORES!$O$37,FATORES!$Q$37,0) -> 0 | O37: =IF(E37>=100%, IF($P$7="ARIEL", IF(AND($E$30>=69.5%,$E$32>=69.5%,$E$33>=69.5%,$E$35>=69.5%,$E$37>=69.5%,$E$38>=69.5%), D37*N37, 0), IF(AND($E$30>=69.5%,$E$31>=69.5%,$E$32>=69.5%,$E$33>=69.5%,$E$35>=69.5%,$E$37>=69.5%,$E$38>=69.5%), D37*N37, 0) ),0) -> 0 | P37: =J37+O37 -> 0.169 | Q37: =IF($G$8=2,P37*0.05,0) -> 0 | R37: =IF($G$8=3,P37*0.15,0) -> 0
B38: SVA | C38: =SUMIFS(REALIZADO[META_SVA],REALIZADO[PDV],ANCHIETA!$M$7) -> 849.9999 | D38: =SUMIFS(REALIZADO[AT_SVA],REALIZADO[PDV],ANCHIETA!$M$7) -> 119.4 | E38: =IFERROR(D38/C38,0) -> 0.1404706 | F38: =IF($E$38>=0,FATORES!$Q$40) -> 0.005 | G38: =IFERROR(VLOOKUP($E$38,FATORES!$O$43:$Q$44,3),0) -> 0 | H38: =D38*F38 -> 0.597 | I38: =IF($P$7="ARIEL", IF(AND($E$30>=69.5%, AND($E$32>=69.5%, $E$33>=69.5%, $E$33>=69.5%, $E$35>=69.5%, $E$35>=69.5%, $E$37>=69.5%, $E$38>=69.5%)), D38*G38, 0), IF(AND($E$30>=69.5%, $E$31>=69.5%, $E$32>=69.5%, $E$33>=69.5%, $E$33>=69.5%, $E$35>=69.5%, $E$35>=69.5%, $E$37>=69.5%, $E$38>=69.5%), D38*G38, 0) ) -> 0 | J38: =H38+I38 -> 0.597 | K38: =SUMIFS(REALIZADO[META_SVA],REALIZADO[COORDENAÇÃO],$P$7) -> 5384.9998 | L38: =SUMIFS(REALIZADO[AT_SVA],REALIZADO[COORDENAÇÃO],$P$7) -> 461.55 | M38: =IFERROR(L38/K38,0) -> 0.08571031 | N38: =IF($M$38>=FATORES!$O$45,FATORES!$Q$45,0) -> 0 | O38: =IF(E38>=100%, IF($P$7="ARIEL", IF(AND($E$30>=69.5%,$E$32>=69.5%,$E$33>=69.5%,$E$35>=69.5%,$E$37>=69.5%,$E$38>=69.5%), D38*N38, 0), IF(AND($E$30>=69.5%,$E$31>=69.5%,$E$32>=69.5%,$E$33>=69.5%,$E$35>=69.5%,$E$37>=69.5%,$E$38>=69.5%), D38*N38, 0) ),0) -> 0 | P38: =J38+O38 -> 0.597 | Q38: =IF($H$8=2,P38*0.05,0) -> 0 | R38: =IF($H$8=3,P38*0.15,0) -> 0
P39: =SUM(P30:P38) -> 5.3851 | Q39: =SUM(Q30:Q38) -> 0 | R39: =SUM(R30:R38) -> 0 | S39: =IF($P$7="ARIEL",IF(MIN(E30,E32,E33,E34,E35,E37,E38)>=100%,SUM(P39:R39)*S30,""),IF(MIN(E30:E38)>=100%,SUM(P39:R39)*S30,""))
B41: SIMULADOR
B42: INDIVIDUAL | K42: PDV
B43: PILAR | C43: REAL PDV | F43: % - COMISSÃO | G43: % - PREMIAÇÃO ALTO DESEMP. INDIV. | H43: R$ - COMISSÃO | I43: R$ - PREMIAÇÃO ALTO DESEMP. INDIV. | J43: R$ - COMISSÃO + PREMIAÇÃO INDIV. | K43: REAL CARTEIRA | N43: % - PREMIAÇÃO ALTO DESEMPENHO PDV | O43: R$ - PREMIAÇÃO ALTO DESEMPENHO PDV | P43: R$ - COMISSÃO + PREMIAÇÕES | Q43: HUNTER 2 | R43: HUNTER 3 | S43: 6/7 PPILARES | T43: GANHO TOTAL
C44: META | D44: ATINGIMENTO | K44: META | L44: ATINGIMENTO
B45: MÓVEL | C45: =SUMIFS(REALIZADO[META_MOVEL],REALIZADO[PDV],ANCHIETA!$M$7) -> 6600 | D45: 7842.21 | E45: =IFERROR(D45/C45,0) -> 1.1882136 | F45: =VLOOKUP($E$45,FATORES!$I$32:$K$34,3) -> 0.04 | G45: =IFERROR(VLOOKUP(E45,FATORES!$I$35:$K$36,3),0) -> 0.08 | H45: =D45*F45 -> 313.6884 | I45: =IF($P$7="ARIEL", IF(AND($E$45>=69.5%, AND($E$47>=69.5%, $E$48>=69.5%, $E$48>=69.5%, $E$50>=69.5%, $E$50>=69.5%, $E$52>=69.5%, $E$53>=69.5%)), D45*G45, 0), IF(AND($E$45>=69.5%, $E$46>=69.5%, $E$47>=69.5%, $E$48>=69.5%, $E$48>=69.5%, $E$50>=69.5%, $E$50>=69.5%, $E$52>=69.5%, $E$53>=69.5%), D45*G45, 0) ) -> 627.3768 | J45: =H45+I45 -> 941.0652 | K45: =SUMIFS(REALIZADO[META_MOVEL],REALIZADO[PDV],ANCHIETA!$M$7) -> 6600 | L45: 7842.21 | M45: =IFERROR(L45/K45,0) -> 1.1882136 | N45: =IF($M$45>=FATORES!$I$37,FATORES!$K$37,0) -> 0.03 | O45: =IF(E45>=100%, IF($P$7="ARIEL", IF(AND($E$45>=69.5%, AND($E$47>=69.5%, $E$48>=69.5%, $E$48>=69.5%, $E$50>=69.5%, $E$50>=69.5%, $E$52>=69.5%, $E$53>=69.5%)), D45*N45, 0), IF(AND($E$45>=69.5%, $E$46>=69.5%, $E$47>=69.5%, $E$48>=69.5%, $E$48>=69.5%, $E$50>=69.5%, $E$50>=69.5%, $E$52>=69.5%, $E$53>=69.5%), D45*N45, 0) ),0) -> 235.2663 | P45: =J45+O45 -> 1176.3315 | Q45: =IF($B$8=2,P45*0.05,0) -> 0 | R45: =IF($B$8=3,P45*0.15,0) -> 0 | S45: 0.1 | T45: =SUM($P$54:$S$54) -> 2057.7616
B46: FIXA | C46: =SUMIFS(REALIZADO[META_FIXA],REALIZADO[PDV],ANCHIETA!$M$7) -> 0 | D46: 100 | E46: =IFERROR(D46/C46,0) -> 0 | F46: =VLOOKUP($E$46,FATORES!$I$40:$K$42,3) -> 0.005 | G46: =IFERROR(VLOOKUP(E46,FATORES!$I$43:$K$44,3),0) -> 0 | H46: =D46*F46 -> 0.5 | I46: =IF($P$7="ARIEL", IF(AND($E$45>=69.5%, AND($E$47>=69.5%, $E$48>=69.5%, $E$48>=69.5%, $E$50>=69.5%, $E$50>=69.5%, $E$52>=69.5%, $E$53>=69.5%)), D46*G46, 0), IF(AND($E$45>=69.5%, $E$46>=69.5%, $E$47>=69.5%, $E$48>=69.5%, $E$48>=69.5%, $E$50>=69.5%, $E$50>=69.5%, $E$52>=69.5%, $E$53>=69.5%), D46*G46, 0) ) -> 0 | J46: =H46+I46 -> 0.5 | K46: =SUMIFS(REALIZADO[META_FIXA],REALIZADO[PDV],ANCHIETA!$M$7) -> 0 | L46: 100 | M46: =IFERROR(L46/K46,0) -> 0 | N46: =IF($M$46>=FATORES!$I$45,FATORES!$K$45,0) -> 0 | O46: =IF(E46>=100%, IF($P$7="ARIEL", IF(AND($E$45>=69.5%, AND($E$47>=69.5%, $E$48>=69.5%, $E$48>=69.5%, $E$50>=69.5%, $E$50>=69.5%, $E$52>=69.5%, $E$53>=69.5%)), D46*N46, 0), IF(AND($E$45>=69.5%, $E$46>=69.5%, $E$47>=69.5%, $E$48>=69.5%, $E$48>=69.5%, $E$50>=69.5%, $E$50>=69.5%, $E$52>=69.5%, $E$53>=69.5%), D46*N46, 0) ),0) -> 0 | P46: =J46+O46 -> 0.5 | Q46: =IF($C$8=2,P46*0.05,0) -> 0 | R46: =IF($C$8=3,P46*0.15,0) -> 0
B47: SMARTPHONES | C47: =SUMIFS(REALIZADO[META_SMARTPHONE],REALIZADO[PDV],ANCHIETA!$M$7) -> 116000 | D47: 156456 | E47: =IFERROR(D47/C47,0) -> 1.3487586 | F47: =VLOOKUP($E$47,FATORES!$B$53:$D$54,3) -> 0.0005 | G47: =IFERROR(VLOOKUP(E47,FATORES!$B$55:$D$55,3),0) -> 0.001 | H47: =D47*F47 -> 78.228 | I47: =IF($P$7="ARIEL", IF(AND($E$45>=69.5%, AND($E$47>=69.5%, $E$48>=69.5%, $E$48>=69.5%, $E$50>=69.5%, $E$50>=69.5%, $E$52>=69.5%, $E$53>=69.5%)), D47*G47, 0), IF(AND($E$45>=69.5%, $E$46>=69.5%, $E$47>=69.5%, $E$48>=69.5%, $E$48>=69.5%, $E$50>=69.5%, $E$50>=69.5%, $E$52>=69.5%, $E$53>=69.5%), D47*G47, 0) ) -> 156.456 | J47: =H47+I47 -> 234.684 | K47: =SUMIFS(REALIZADO[META_SMARTPHONE],REALIZADO[PDV],ANCHIETA!$M$7) -> 116000 | L47: 156456 | M47: =IFERROR(L47/K47,0) -> 1.3487586 | N47: =IF($M$47>=FATORES!$B$56,FATORES!$D$56,0) -> 0.0005 | O47: =IF(E47>=100%, IF($P$7="ARIEL", IF(AND($E$45>=69.5%, AND($E$47>=69.5%, $E$48>=69.5%, $E$48>=69.5%, $E$50>=69.5%, $E$50>=69.5%, $E$52>=69.5%, $E$53>=69.5%)), D47*N47, 0), IF(AND($E$45>=69.5%, $E$46>=69.5%, $E$47>=69.5%, $E$48>=69.5%, $E$48>=69.5%, $E$50>=69.5%, $E$50>=69.5%, $E$52>=69.5%, $E$53>=69.5%), D47*N47, 0) ),0) -> 78.228 | P47: =J47+O47 -> 312.912 | Q47: =IF($D$8=2,P47*0.05,0) -> 0 | R47: =IF($D$8=3,P47*0.15,0) -> 0
B48: ELETRONICOS - A | C48: =SUMIFS(REALIZADO[META_ACESSORIO],REALIZADO[PDV],ANCHIETA!$M$7) -> 13950 | D48: =SUMIFS(REALIZADO[AT_ACESSORIOS_A],REALIZADO[PDV],ANCHIETA!$M$7) -> 0 | E48: =IFERROR((D48+D49)/C48,0) -> 1.295914 | F48: =VLOOKUP($E$48,FATORES!$B$44:$E$46,3) -> 0.0015 | G48: =IFERROR(VLOOKUP(E48,FATORES!$B$47:$E$48,3),0) -> 0.006 | H48: =D48*F48 -> 0 | I48: =IF($P$7="ARIEL", IF(AND($E$45>=69.5%, AND($E$47>=69.5%, $E$48>=69.5%, $E$48>=69.5%, $E$50>=69.5%, $E$50>=69.5%, $E$52>=69.5%, $E$53>=69.5%)), D48*G48, 0), IF(AND($E$45>=69.5%, $E$46>=69.5%, $E$47>=69.5%, $E$48>=69.5%, $E$48>=69.5%, $E$50>=69.5%, $E$50>=69.5%, $E$52>=69.5%, $E$53>=69.5%), D48*G48, 0) ) -> 0 | J48: =H48+I48 -> 0 | K48: =SUMIFS(REALIZADO[META_ACESSORIO],REALIZADO[PDV],ANCHIETA!$M$7) -> 13950 | L48: =SUMIFS(REALIZADO[AT_ACESSORIOS_A],REALIZADO[PDV],ANCHIETA!$M$7) -> 0 | M48: =IFERROR((L48+L49)/K48,0) -> 1.295914 | N48: =IF($M$48>=FATORES!$B$49,FATORES!$D$49,0) -> 0.0025 | O48: =IF(E48>=100%, IF($P$7="ARIEL", IF(AND($E$45>=69.5%, AND($E$47>=69.5%, $E$48>=69.5%, $E$48>=69.5%, $E$50>=69.5%, $E$50>=69.5%, $E$52>=69.5%, $E$53>=69.5%)), D48*N48, 0), IF(AND($E$45>=69.5%, $E$46>=69.5%, $E$47>=69.5%, $E$48>=69.5%, $E$48>=69.5%, $E$50>=69.5%, $E$50>=69.5%, $E$52>=69.5%, $E$53>=69.5%), D48*N48, 0) ),0) -> 0 | P48: =J48+O48 -> 0 | Q48: =IF($E$8=2,P48*0.05,0) -> 0 | R48: =IF($E$8=3,P48*0.15,0) -> 0
...

Sheet BOM JESUS
B2: SIMULADOR GERENTE
B6: HUNTER | M6: PDV | P6: COORDENADOR | V6: 0 | W6: 2 | X6: 3
B7: MOVEL | C7: FIXA | D7: SMARTPHONE | E7: ELETRONICOS | F7: ESSESCIAIS | G7: SEGUROS | H7: SVA | M7: BOM JESUS DO ITABAPOANA | P7: ARIEL
B8: 0 | C8: 0 | D8: 0 | E8: 0 | F8: 0 | G8: 0 | H8: 0
B11: PROJEÇÃO
B12: INDIVIDUAL | K12: PDV
B13: PILAR | C13: PROJ PDV | F13: % - COMISSÃO | G13: % - PREMIAÇÃO ALTO DESEMP. INDIV. | H13: R$ - COMISSÃO | I13: R$ - PREMIAÇÃO ALTO DESEMP. INDIV. | J13: R$ - COMISSÃO + PREMIAÇÃO INDIV. | K13: PROJ CARTEIRA | N13: % - PREMIAÇÃO ALTO DESEMPENHO PDV | O13: R$ - PREMIAÇÃO ALTO DESEMPENHO PDV | P13: R$ - COMISSÃO + PREMIAÇÕES | Q13: HUNTER 2 | R13: HUNTER 3 | S13: 6/7 PPILARES | T13: GANHO TOTAL
C14: META | D14: ATINGIMENTO | K14: META | L14: ATINGIMENTO
B15: MÓVEL | C15: =SUMIFS(REALIZADO[META_MOVEL],REALIZADO[PDV],'BOM JESUS'!$M$7) -> 13000 | D15: =SUMIFS(PROJEÇÃO[PROJ_MOVEL],PROJEÇÃO[PDV],'BOM JESUS'!$M$7) -> 12715.011 | E15: =IFERROR(D15/C15,0) -> 0.97807778 | F15: =VLOOKUP($E$15,FATORES!$I$32:$K$34,3) -> 0.04 | G15: =IFERROR(VLOOKUP($E$15,FATORES!$I$35:$K$36,3),0) -> 0 | H15: =D15*F15 -> 508.60044 | I15: =IF($P$7="ARIEL", IF(AND($E$15>=69.5%, AND($E$17>=69.5%, $E$18>=69.5%, $E$18>=69.5%, $E$20>=69.5%, $E$20>=69.5%, $E$22>=69.5%, $E$23>=69.5%)), D15*G15, 0), IF(AND($E$15>=69.5%, $E$16>=69.5%, $E$17>=69.5%, $E$18>=69.5%, $E$18>=69.5%, $E$20>=69.5%, $E$20>=69.5%, $E$22>=69.5%, $E$23>=69.5%), D15*G15, 0) ) -> 0 | J15: =H15+I15 -> 508.60044 | K15: =SUMIFS(REALIZADO[META_MOVEL],REALIZADO[COORDENAÇÃO],$P$7) -> 59730 | L15: =SUMIFS(PROJEÇÃO[PROJ_MOVEL],PROJEÇÃO[COORDENAÇÃO],$P$7) -> 52523.22 | M15: =IFERROR(L15/K15,0) -> 0.87934405 | N15: =IF($M$15>=FATORES!$I$37,FATORES!$K$37,0) -> 0 | O15: =IF(E15>=100%, IF($P$7="ARIEL", IF(AND($E$15>=69.5%,$E$17>=69.5%,$E$18>=69.5%,$E$20>=69.5%,$E$22>=69.5%,$E$23>=69.5%), D15*N15, 0 ), IF(AND($E$15>=69.5%,$E$16>=69.5%,$E$17>=69.5%,$E$18>=69.5%,$E$20>=69.5%,$E$22>=69.5%,$E$23>=69.5%), D15*N15, 0 ) ), 0) -> 0 | P15: =J15+O15 -> 508.60044 | Q15: =IF($B$8=2,P15*0.05,0) -> 0 | R15: =IF($B$8=3,P15*0.15,0) -> 0 | S15: 0.1 | T15: =SUM(P24:S24) -> 804.68388
B16: FIXA | C16: =SUMIFS(REALIZADO[META_FIXA],REALIZADO[PDV],'BOM JESUS'!$M$7) -> 0 | D16: =SUMIFS(PROJEÇÃO[PROJ_FIXA],PROJEÇÃO[PDV],'BOM JESUS'!$M$7) -> 0 | E16: =IFERROR(D16/C16,0) -> 0 | F16: =VLOOKUP($E$16,FATORES!$I$40:$K$42,3) -> 0.005 | G16: =IFERROR(VLOOKUP($E$16,FATORES!$I$43:$K$44,3),0) -> 0 | H16: =D16*F16 -> 0 | I16: =IF($P$7="ARIEL", IF(AND($E$15>=69.5%, AND($E$17>=69.5%, $E$18>=69.5%, $E$18>=69.5%, $E$20>=69.5%, $E$20>=69.5%, $E$22>=69.5%, $E$23>=69.5%)), D16*G16, 0), IF(AND($E$15>=69.5%, $E$16>=69.5%, $E$17>=69.5%, $E$18>=69.5%, $E$18>=69.5%, $E$20>=69.5%, $E$20>=69.5%, $E$22>=69.5%, $E$23>=69.5%), D16*G16, 0) ) -> 0 | J16: =H16+I16 -> 0 | K16: =SUMIFS(REALIZADO[META_FIXA],REALIZADO[COORDENAÇÃO],$P$7) -> 0 | L16: =SUMIFS(PROJEÇÃO[PROJ_FIXA],PROJEÇÃO[COORDENAÇÃO],$P$7) -> 0 | M16: =IFERROR(L16/K16,0) -> 0 | N16: =IF($M$16>=FATORES!$I$45,FATORES!$K$45,0) -> 0 | O16: =IF(E16>=100%, IF($P$7="ARIEL", IF(AND($E$15>=69.5%,$E$17>=69.5%,$E$18>=69.5%,$E$20>=69.5%,$E$22>=69.5%,$E$23>=69.5%), D16*N16, 0 ), IF(AND($E$15>=69.5%,$E$16>=69.5%,$E$17>=69.5%,$E$18>=69.5%,$E$20>=69.5%,$E$22>=69.5%,$E$23>=69.5%), D16*N16, 0 ) ), 0) -> 0 | P16: =J16+O16 -> 0 | Q16: =IF($C$8=2,P16*0.05,0) -> 0 | R16: =IF($C$8=3,P16*0.15,0) -> 0
B17: SMARTPHONES | C17: =SUMIFS(REALIZADO[META_SMARTPHONE],REALIZADO[PDV],'BOM JESUS'!$M$7) -> 90000 | D17: =SUMIFS(PROJEÇÃO[PROJ_APARELHO],PROJEÇÃO[PDV],'BOM JESUS'!$M$7) -> 80401.667 | E17: =IFERROR(D17/C17,0) -> 0.89335185 | F17: =VLOOKUP($E$17,FATORES!$B$53:$D$54,3) -> 0.0002 | G17: =IFERROR(VLOOKUP($E$17,FATORES!$B$55:$D$55,3),0) -> 0 | H17: =D17*F17 -> 16.080333 | I17: =IF($P$7="ARIEL", IF(AND($E$15>=69.5%, AND($E$17>=69.5%, $E$18>=69.5%, $E$18>=69.5%, $E$20>=69.5%, $E$20>=69.5%, $E$22>=69.5%, $E$23>=69.5%)), D17*G17, 0), IF(AND($E$15>=69.5%, $E$16>=69.5%, $E$17>=69.5%, $E$18>=69.5%, $E$18>=69.5%, $E$20>=69.5%, $E$20>=69.5%, $E$22>=69.5%, $E$23>=69.5%), D17*G17, 0) ) -> 0 | J17: =H17+I17 -> 16.080333 | K17: =SUMIFS(REALIZADO[META_SMARTPHONE],REALIZADO[COORDENAÇÃO],$P$7) -> 741000 | L17: =SUMIFS(PROJEÇÃO[PROJ_APARELHO],PROJEÇÃO[COORDENAÇÃO],$P$7) -> 619809.56 | M17: =IFERROR(L17/K17,0) -> 0.83645014 | N17: =IF($M$17>=FATORES!$B$56,FATORES!$D$56,0) -> 0 | O17: =IF(E17>=100%, IF($P$7="ARIEL", IF(AND($E$15>=69.5%,$E$17>=69.5%,$E$18>=69.5%,$E$20>=69.5%,$E$22>=69.5%,$E$23>=69.5%), D17*N17, 0 ), IF(AND($E$15>=69.5%,$E$16>=69.5%,$E$17>=69.5%,$E$18>=69.5%,$E$20>=69.5%,$E$22>=69.5%,$E$23>=69.5%), D17*N17, 0 ) ), 0) -> 0 | P17: =J17+O17 -> 16.080333 | Q17: =IF($D$8=2,P17*0.05,0) -> 0 | R17: =IF($D$8=3,P17*0.15,0) -> 0
B18: ELETRONICOS - A | C18: =SUMIFS(REALIZADO[META_ACESSORIO],REALIZADO[PDV],'BOM JESUS'!$M$7) -> 10700 | D18: =SUMIFS(PROJEÇÃO[PROJ_ELETRO_A],PROJEÇÃO[PDV],'BOM JESUS'!$M$7) -> 420.1111 | E18: =IFERROR((D18+D19)/C18,0) -> 3.0040913 | F18: =VLOOKUP($E$18,FATORES!$B$44:$E$46,3) -> 0.0015 | G18: =IFERROR(VLOOKUP($E$18,FATORES!$B$47:$E$48,3),0) -> 0.007 | H18: =D18*F18 -> 0.63016665 | I18: =IF($P$7="ARIEL", IF(AND($E$15>=69.5%, AND($E$17>=69.5%, $E$18>=69.5%, $E$18>=69.5%, $E$20>=69.5%, $E$20>=69.5%, $E$22>=69.5%, $E$23>=69.5%)), D18*G18, 0), IF(AND($E$15>=69.5%, $E$16>=69.5%, $E$17>=69.5%, $E$18>=69.5%, $E$18>=69.5%, $E$20>=69.5%, $E$20>=69.5%, $E$22>=69.5%, $E$23>=69.5%), D18*G18, 0) ) -> 2.9407777 | J18: =H18+I18 -> 3.5709444 | K18: =SUMIFS(REALIZADO[META_ACESSORIO],REALIZADO[COORDENAÇÃO],$P$7) -> 84200 | L18: =SUMIFS(PROJEÇÃO[PROJ_ELETRO_A],PROJEÇÃO[COORDENAÇÃO],$P$7) -> 2058.3333 | M18: =IFERROR((L18+L19)/K18,0) -> 1.2364041 | N18: =IF($M$18>=FATORES!$B$49,FATORES!$D$49,0) -> 0.0025 | O18: =IF(E18>=100%, IF($P$7="ARIEL", IF(AND($E$15>=69.5%,$E$17>=69.5%,$E$18>=69.5%,$E$20>=69.5%,$E$22>=69.5%,$E$23>=69.5%), D18*N18, 0 ), IF(AND($E$15>=69.5%,$E$16>=69.5%,$E$17>=69.5%,$E$18>=69.5%,$E$20>=69.5%,$E$22>=69.5%,$E$23>=69.5%), D18*N18, 0 ) ), 0) -> 1.0502778 | P18: =J18+O18 -> 4.6212221 | Q18: =IF($E$8=2,P18*0.05,0) -> 0 | R18: =IF($E$8=3,P18*0.15,0) -> 0
B19: ELETRONICOS - B | D19: =SUMIFS(PROJEÇÃO[PROJ_ELETRO_B],PROJEÇÃO[PDV],'BOM JESUS'!$M$7) -> 31723.667 | F19: =VLOOKUP($E$18,FATORES!$B$44:$E$46,4) -> 0.00075 | G19: =IFERROR(VLOOKUP($E$18,FATORES!$B$47:$E$48,4),0) -> 0.0035 | H19: =D19*F19 -> 23.79275 | I19: =IF($P$7="ARIEL", IF(AND($E$15>=69.5%, AND($E$17>=69.5%, $E$18>=69.5%, $E$18>=69.5%, $E$20>=69.5%, $E$20>=69.5%, $E$22>=69.5%, $E$23>=69.5%)), D19*G19, 0), IF(AND($E$15>=69.5%, $E$16>=69.5%, $E$17>=69.5%, $E$18>=69.5%, $E$18>=69.5%, $E$20>=69.5%, $E$20>=69.5%, $E$22>=69.5%, $E$23>=69.5%), D19*G19, 0) ) -> 111.03283 | J19: =H19+I19 -> 134.82558 | L19: =SUMIFS(PROJEÇÃO[PROJ_ELETRO_B],PROJEÇÃO[COORDENAÇÃO],$P$7) -> 102046.89 | N19: =IF($M$18>=FATORES!$B$49,FATORES!$E$49,0) -> 0.00125 | O19: =IF(E19>=100%, IF($P$7="ARIEL", IF(AND($E$15>=69.5%,$E$17>=69.5%,$E$18>=69.5%,$E$20>=69.5%,$E$22>=69.5%,$E$23>=69.5%), D19*N19, 0 ), IF(AND($E$15>=69.5%,$E$16>=69.5%,$E$17>=69.5%,$E$18>=69.5%,$E$20>=69.5%,$E$22>=69.5%,$E$23>=69.5%), D19*N19, 0 ) ), 0) -> 0 | P19: =J19+O19 -> 134.82558 | Q19: =IF($E$8=2,P19*0.05,0) -> 0 | R19: =IF($E$8=3,P19*0.15,0) -> 0
B20: ESSENCIAIS - A | C20: =SUMIFS(REALIZADO[META_ESSENCIAIS],REALIZADO[PDV],'BOM JESUS'!$M$7) -> 8550 | D20: =SUMIFS(PROJEÇÃO[PROJ_ESSEN_A],PROJEÇÃO[PDV],'BOM JESUS'!$M$7) -> 6289 | E20: =IFERROR((D20+D21)/C20,0) -> 1.4303704 | F20: =VLOOKUP($E$20,FATORES!$B$34:$E$36,3) -> 0.0015 | G20: =IFERROR(VLOOKUP($E$20,FATORES!$B$37:$E$38,3),0) -> 0.006 | H20: =D20*F20 -> 9.4335 | I20: =IF($P$7="ARIEL", IF(AND($E$15>=69.5%, AND($E$17>=69.5%, $E$18>=69.5%, $E$18>=69.5%, $E$20>=69.5%, $E$20>=69.5%, $E$22>=69.5%, $E$23>=69.5%)), D20*G20, 0), IF(AND($E$15>=69.5%, $E$16>=69.5%, $E$17>=69.5%, $E$18>=69.5%, $E$18>=69.5%, $E$20>=69.5%, $E$20>=69.5%, $E$22>=69.5%, $E$23>=69.5%), D20*G20, 0) ) -> 37.734 | J20: =H20+I20 -> 47.1675 | K20: =SUMIFS(REALIZADO[META_ESSENCIAIS],REALIZADO[COORDENAÇÃO],$P$7) -> 58600 | L20: =SUMIFS(PROJEÇÃO[PROJ_ESSEN_A],PROJEÇÃO[COORDENAÇÃO],$P$7) -> 30216.333 | M20: =IFERROR((L20+L21)/K20,0) -> 1.0940311 | N20: =IF($M$20>=FATORES!$B$39,FATORES!$D$39,0) -> 0.008 | O20: =IF(E20>=100%, IF($P$7="ARIEL", IF(AND($E$15>=69.5%,$E$17>=69.5%,$E$18>=69.5%,$E$20>=69.5%,$E$22>=69.5%,$E$23>=69.5%), D20*N20, 0 ), IF(AND($E$15>=69.5%,$E$16>=69.5%,$E$17>=69.5%,$E$18>=69.5%,$E$20>=69.5%,$E$22>=69.5%,$E$23>=69.5%), D20*N20, 0 ) ), 0) -> 50.312 | P20: =J20+O20 -> 97.4795 | Q20: =IF($F$8=2,P20*0.05,0) -> 0 | R20: =IF($F$8=3,P20*0.15,0) -> 0
B21: ESSENCIAIS - B | D21: =SUMIFS(PROJEÇÃO[PROJ_ESSEN_B],PROJEÇÃO[PDV],'BOM JESUS'!$M$7) -> 5940.6666 | F21: =VLOOKUP($E$20,FATORES!$B$34:$E$36,4) -> 0.00075 | G21: =IFERROR(VLOOKUP($E$20,FATORES!$B$37:$E$38,4),0) -> 0.003 | H21: =D21*F21 -> 4.4555 | I21: =IF($P$7="ARIEL", IF(AND($E$15>=69.5%, AND($E$17>=69.5%, $E$18>=69.5%, $E$18>=69.5%, $E$20>=69.5%, $E$20>=69.5%, $E$22>=69.5%, $E$23>=69.5%)), D21*G21, 0), IF(AND($E$15>=69.5%, $E$16>=69.5%, $E$17>=69.5%, $E$18>=69.5%, $E$18>=69.5%, $E$20>=69.5%, $E$20>=69.5%, $E$22>=69.5%, $E$23>=69.5%), D21*G21, 0) ) -> 17.822 | J21: =H21+I21 -> 22.2775 | L21: =SUMIFS(PROJEÇÃO[PROJ_ESSEN_B],PROJEÇÃO[COORDENAÇÃO],$P$7) -> 33893.889 | N21: =IF($M$20>=FATORES!$B$39,FATORES!$E$39,0) -> 0.004 | O21: =IF(E21>=100%, IF($P$7="ARIEL", IF(AND($E$15>=69.5%,$E$17>=69.5%,$E$18>=69.5%,$E$20>=69.5%,$E$22>=69.5%,$E$23>=69.5%), D21*N21, 0 ), IF(AND($E$15>=69.5%,$E$16>=69.5%,$E$17>=69.5%,$E$18>=69.5%,$E$20>=69.5%,$E$22>=69.5%,$E$23>=69.5%), D21*N21, 0 ) ), 0) -> 0 | P21: =J21+O21 -> 22.2775 | Q21: =IF($F$8=2,P21*0.05,0) -> 0 | R21: =IF($F$8=3,P21*0.15,0) -> 0
B22: SEGUROS | C22: =SUMIFS(REALIZADO[META_SEGUROS],REALIZADO[PDV],'BOM JESUS'!$M$7) -> 999.9999 | D22: =SUMIFS(PROJEÇÃO[PROJ_SEGURO],PROJEÇÃO[PDV],'BOM JESUS'!$M$7) -> 830.9334 | E22: =IFERROR(D22/C22,0) -> 0.83093348 | F22: =VLOOKUP($E$22,FATORES!$O$32:$Q$34,3) -> 0.02 | G22: =IFERROR(VLOOKUP($E$22,FATORES!$O$35:$Q$36,3),0) -> 0 | H22: =D22*F22 -> 16.618668 | I22: =IF($P$7="ARIEL", IF(AND($E$15>=69.5%, AND($E$17>=69.5%, $E$18>=69.5%, $E$18>=69.5%, $E$20>=69.5%, $E$20>=69.5%, $E$22>=69.5%, $E$23>=69.5%)), D22*G22, 0), IF(AND($E$15>=69.5%, $E$16>=69.5%, $E$17>=69.5%, $E$18>=69.5%, $E$18>=69.5%, $E$20>=69.5%, $E$20>=69.5%, $E$22>=69.5%, $E$23>=69.5%), D22*G22, 0) ) -> 0 | J22: =H22+I22 -> 16.618668 | K22: =SUMIFS(REALIZADO[META_SEGUROS],REALIZADO[COORDENAÇÃO],$P$7) -> 5665 | L22: =SUMIFS(PROJEÇÃO[PROJ_SEGURO],PROJEÇÃO[COORDENAÇÃO],$P$7) -> 5467.5669 | M22: =IFERROR(L22/K22,0) -> 0.96514861 | N22: =IF($M$22>=FATORES!$O$37,FATORES!$Q$37,0) -> 0 | O22: =IF(E22>=100%, IF($P$7="ARIEL", IF(AND($E$15>=69.5%,$E$17>=69.5%,$E$18>=69.5%,$E$20>=69.5%,$E$22>=69.5%,$E$23>=69.5%), D22*N22, 0 ), IF(AND($E$15>=69.5%,$E$16>=69.5%,$E$17>=69.5%,$E$18>=69.5%,$E$20>=69.5%,$E$22>=69.5%,$E$23>=69.5%), D22*N22, 0 ) ), 0) -> 0 | P22: =J22+O22 -> 16.618668 | Q22: =IF($G$8=2,P22*0.05,0) -> 0 | R22: =IF($G$8=3,P22*0.15,0) -> 0
B23: SVA | C23: =SUMIFS(REALIZADO[META_SVA],REALIZADO[PDV],'BOM JESUS'!$M$7) -> 849.9999 | D23: =SUMIFS(PROJEÇÃO[PROJ_SVA],PROJEÇÃO[PDV],'BOM JESUS'!$M$7) -> 836.1267 | E23: =IFERROR(D23/C23,0) -> 0.98367859 | F23: =IF($E$23>=0,FATORES!$Q$40) -> 0.005 | G23: =IFERROR(VLOOKUP($E$23,FATORES!$O$43:$Q$44,3),0) -> 0 | H23: =D23*F23 -> 4.1806335 | I23: =IF($P$7="ARIEL", IF(AND($E$15>=69.5%, AND($E$17>=69.5%, $E$18>=69.5%, $E$18>=69.5%, $E$20>=69.5%, $E$20>=69.5%, $E$22>=69.5%, $E$23>=69.5%)), D23*G23, 0), IF(AND($E$15>=69.5%, $E$16>=69.5%, $E$17>=69.5%, $E$18>=69.5%, $E$18>=69.5%, $E$20>=69.5%, $E$20>=69.5%, $E$22>=69.5%, $E$23>=69.5%), D23*G23, 0) ) -> 0 | J23: =H23+I23 -> 4.1806335 | K23: =SUMIFS(REALIZADO[META_SVA],REALIZADO[COORDENAÇÃO],$P$7) -> 5384.9998 | L23: =SUMIFS(PROJEÇÃO[PROJ_SVA],PROJEÇÃO[COORDENAÇÃO],$P$7) -> 5513.6099 | M23: =IFERROR(L23/K23,0) -> 1.023883 | N23: =IF($M$23>=FATORES!$O$45,FATORES!$Q$45,0) -> 0.005 | O23: =IF(E23>=100%, IF($P$7="ARIEL", IF(AND($E$15>=69.5%,$E$17>=69.5%,$E$18>=69.5%,$E$20>=69.5%,$E$22>=69.5%,$E$23>=69.5%), D23*N23, 0 ), IF(AND($E$15>=69.5%,$E$16>=69.5%,$E$17>=69.5%,$E$18>=69.5%,$E$20>=69.5%,$E$22>=69.5%,$E$23>=69.5%), D23*N23, 0 ) ), 0) -> 0 | P23: =J23+O23 -> 4.1806335 | Q23: =IF($H$8=2,P23*0.05,0) -> 0 | R23: =IF($H$8=3,P23*0.15,0) -> 0
P24: =SUM(P15:P23) -> 804.68388 | Q24: =SUM(Q15:Q23) -> 0 | R24: =SUM(R15:R23) -> 0 | S24: =IF($P$7="ARIEL",IF(MIN(E15,E17,E18,E19,E20,E22,E23)>=100%,SUM(P24:R24)*S15,""),IF(MIN(E15:E23)>=100%,SUM(P24:R24)*S15,""))
B26: REALIZADO
B27: INDIVIDUAL | K27: PDV
B28: PILAR | C28: REAL PDV | F28: % - COMISSÃO | G28: % - PREMIAÇÃO ALTO DESEMP. INDIV. | H28: R$ - COMISSÃO | I28: R$ - PREMIAÇÃO ALTO DESEMP. INDIV. | J28: R$ - COMISSÃO + PREMIAÇÃO INDIV. | K28: REAL CARTEIRA | N28: % - PREMIAÇÃO ALTO DESEMPENHO PDV | O28: R$ - PREMIAÇÃO ALTO DESEMPENHO PDV | P28: R$ - COMISSÃO + PREMIAÇÕES | Q28: HUNTER 2 | R28: HUNTER 3 | S28: 6/7 PPILARES | T28: GANHO TOTAL
C29: META | D29: ATINGIMENTO | K29: META | L29: ATINGIMENTO
B30: MÓVEL | C30: =SUMIFS(REALIZADO[META_MOVEL],REALIZADO[PDV],'BOM JESUS'!$M$7) -> 13000 | D30: =SUMIFS(REALIZADO[AT_MOVEL],REALIZADO[PDV],'BOM JESUS'!$M$7) -> 1369.99 | E30: =IFERROR(D30/C30,0) -> 0.10538385 | F30: =VLOOKUP($E$30,FATORES!$I$32:$K$34,3) -> 0.005 | G30: =IFERROR(VLOOKUP($E$30,FATORES!$I$35:$K$36,3),0) -> 0 | H30: =D30*F30 -> 6.84995 | I30: =IF($P$7="ARIEL", IF(AND($E$30>=69.5%, AND($E$32>=69.5%, $E$33>=69.5%, $E$33>=69.5%, $E$35>=69.5%, $E$35>=69.5%, $E$37>=69.5%, $E$38>=69.5%)), D30*G30, 0), IF(AND($E$30>=69.5%, $E$31>=69.5%, $E$32>=69.5%, $E$33>=69.5%, $E$33>=69.5%, $E$35>=69.5%, $E$35>=69.5%, $E$37>=69.5%, $E$38>=69.5%), D30*G30, 0) ) -> 0 | J30: =H30+I30 -> 6.84995 | K30: =SUMIFS(REALIZADO[META_MOVEL],REALIZADO[COORDENAÇÃO],$P$7) -> 59730 | L30: =SUMIFS(REALIZADO[AT_MOVEL],REALIZADO[COORDENAÇÃO],$P$7) -> 5335.72 | M30: =IFERROR(L30/K30,0) -> 0.089330655 | N30: =IF($M$30>=FATORES!$I$37,FATORES!$K$37,0) -> 0 | O30: =IF(E30>=100%, IF($P$7="ARIEL", IF(AND($E$30>=69.5%,$E$32>=69.5%,$E$33>=69.5%,$E$35>=69.5%,$E$37>=69.5%,$E$38>=69.5%), D30*N30, 0), IF(AND($E$30>=69.5%,$E$31>=69.5%,$E$32>=69.5%,$E$33>=69.5%,$E$35>=69.5%,$E$37>=69.5%,$E$38>=69.5%), D30*N30, 0) ),0) -> 0 | P30: =J30+O30 -> 6.84995 | Q30: =IF($B$8=2,P30*0.05,0) -> 0 | R30: =IF($B$8=3,P30*0.15,0) -> 0 | S30: 0.1 | T30: =SUM(P39:S39) -> 14.6163
B31: FIXA | C31: =SUMIFS(REALIZADO[META_FIXA],REALIZADO[PDV],'BOM JESUS'!$M$7) -> 0 | D31: =SUMIFS(REALIZADO[AT_FIXA],REALIZADO[PDV],'BOM JESUS'!$M$7) -> 0 | E31: =IFERROR(D31/C31,0) -> 0 | F31: =VLOOKUP($E$31,FATORES!$I$40:$K$42,3) -> 0.005 | G31: =IFERROR(VLOOKUP($E$31,FATORES!$I$43:$K$44,3),0) -> 0 | H31: =D31*F31 -> 0 | I31: =IF($P$7="ARIEL", IF(AND($E$30>=69.5%, AND($E$32>=69.5%, $E$33>=69.5%, $E$33>=69.5%, $E$35>=69.5%, $E$35>=69.5%, $E$37>=69.5%, $E$38>=69.5%)), D31*G31, 0), IF(AND($E$30>=69.5%, $E$31>=69.5%, $E$32>=69.5%, $E$33>=69.5%, $E$33>=69.5%, $E$35>=69.5%, $E$35>=69.5%, $E$37>=69.5%, $E$38>=69.5%), D31*G31, 0) ) -> 0 | J31: =H31+I31 -> 0 | K31: =SUMIFS(REALIZADO[META_FIXA],REALIZADO[COORDENAÇÃO],$P$7) -> 0 | L31: =SUMIFS(REALIZADO[AT_FIXA],REALIZADO[COORDENAÇÃO],$P$7) -> 0 | M31: =IFERROR(L31/K31,0) -> 0 | N31: =IF($M$31>=FATORES!$I$45,FATORES!$K$45,0) -> 0 | O31: =IF(E31>=100%, IF($P$7="ARIEL", IF(AND($E$30>=69.5%,$E$32>=69.5%,$E$33>=69.5%,$E$35>=69.5%,$E$37>=69.5%,$E$38>=69.5%), D31*N31, 0), IF(AND($E$30>=69.5%,$E$31>=69.5%,$E$32>=69.5%,$E$33>=69.5%,$E$35>=69.5%,$E$37>=69.5%,$E$38>=69.5%), D31*N31, 0) ),0) -> 0 | P31: =J31+O31 -> 0 | Q31: =IF($C$8=2,P31*0.05,0) -> 0 | R31: =IF($C$8=3,P31*0.15,0) -> 0
